Workbook

Sheet 1-4月+5-6月明细
A1: 2026年国际市场运营系统上半年预计签排发数量
A2: 报表日期： | C2: 2026-04-28
A3: 序号 | B3: 模块类型 | C3: 模块 | D3: 1-4月新签梯量 | I3: 1-4月新签金额 | N3: 1-4月排产台 | S3: 1-4月排产额 | X3: 1-4月发货台 | AC3: 1-4月发货额 | AH3: 预计上半年签单 | AS3: 预计上半年排产 | BE3: 预计上半年发货
D4: 指标 | E4: 完成 | F4: 完成比 | G4: 去年同期 | H4: 增长比 | I4: 指标 | J4: 完成 | K4: 完成比 | L4: 去年同期 | M4: 增长比 | N4: 指标 | O4: 完成 | P4: 完成比 | Q4: 去年同期 | R4: 增长比 | S4: 指标 | T4: 完成 | U4: 完成比 | V4: 去年同期 | W4: 增长比 | X4: 指标 | Y4: 完成 | Z4: 完成比 | AA4: 去年同期 | AB4: 增长比 | AC4: 指标 | AD4: 完成 | AE4: 完成比 | AF4: 去年同期 | AG4: 增长比 | AH4: 5-6月台数 | AI4: 上半年台数 | AJ4: 完成比 | AK4: 去年同期 | AL4: 增长额 | AM4: 增长比 | AN4: 5-6月合同额 | AO4: 上半年合同额合计 | AP4: 完成比 | AQ4: 去年同期 | AR4: 增长比 | AS4: 5-6月台数 | AT4: 上半年台数合计 | AU4: 完成比 | AV4: 去年同期 | AW4: 增长额 | AX4: 增长比 | AY4: 5-6月合同额 | AZ4: 上半年排产额合计 | BA4: 完成比 | BB4: 去年同期 | BC4: 增长额 | BD4: 增长比 | BE4: 5-6月台数 | BF4: 上半年台数合计 | BG4: 完成比 | BH4: 去年同期 | BI4: 增长比 | BJ4: 5-6月合同额 | BK4: 上半年合同额合计 | BL4: 完成比 | BM4: 去年同期 | BN4: 增长比
A5: 1 | B5: A | C5: 俄罗斯（中部） | D5: 1683 | E5: 429 | F5: 0.25490196 | G5: 448 | H5: -0.044289044 | I5: 35680 | J5: 8320.51 | K5: 0.23319815 | L5: 8425.6546 | M5: -0.012636798 | N5: 750 | O5: 291 | P5: 0.388 | Q5: 189 | R5: 0.35051546 | S5: 14500 | T5: 5446.15 | U5: 0.37559655 | V5: 3547.1566 | W5: 0.34868548 | X5: 750 | Y5: 166 | Z5: 0.22133333 | AA5: 134 | AB5: 0.19277108 | AC5: 14500 | AD5: 3443.34 | AE5: 0.23747172 | AF5: 2418.3666 | AG5: =(AD5-AF5)/AF5 -> 0.42382879 | AH5: 580 | AI5: =AH5+E5 -> 1009 | AJ5: =AI5/D5 -> 0.59952466 | AK5: =VLOOKUP(C5,[1]两年对比终版!$A:$C,3,0) -> 714 | AL5: =AI5-AK5 -> 295 | AM5: =(AI5-AK5)/AK5 -> 0.41316527 | AN5: 10460 | AO5: =AN5+J5 -> 18780.51 | AP5: =AO5/I5 -> 0.52635959 | AQ5: =VLOOKUP(C5,[1]两年对比终版!$A:$W,6,0) -> 12648.627 | AR5: =(AO5-AQ5)/AQ5 -> 0.48478641 | AS5: 129 | AT5: =AS5+O5 -> 420 | AU5: =AT5/N5 -> 0.56 | AV5: =VLOOKUP(C5,[1]两年对比终版!$A:$N,14,0) -> 371 | AW5: =AT5-AV5 -> 49 | AX5: =(AT5-AV5)/AV5 -> 0.13207547 | AY5: 1491 | AZ5: =AY5+T5 -> 6937.15 | BA5: =AZ5/S5 -> 0.47842414 | BB5: =VLOOKUP(C5,[1]两年对比终版!$A:$W,17,0) -> 6707.2804 | BC5: =AZ5-BB5 -> 229.86964 | BD5: =(AZ5-BB5)/BB5 -> 0.034271661 | BE5: 182 | BF5: =BE5+Y5 -> 348 | BG5: =BF5/X5 -> 0.464 | BH5: =VLOOKUP(C5,[1]两年对比终版!$A:$T,20,0) -> 223 | BI5: =(BF5-BH5)/BH5 -> 0.56053812 | BJ5: 4030 | BK5: =BJ5+AD5 -> 7473.34 | BL5: =BK5/AC5 -> 0.51540276 | BM5: =VLOOKUP(C5,[1]两年对比终版!$A:$W,23,0) -> 4120.0566 | BN5: =(BK5-BM5)/BM5 -> 0.81389256
A6: 2 | B6: A | C6: 俄罗斯（西部） | D6: 1683 | E6: 289 | F6: 0.17171717 | G6: 280 | H6: 0.031141869 | I6: 35680 | J6: 7186.16 | K6: 0.20140583 | L6: 5541.0212 | M6: 0.22893156 | N6: 750 | O6: 179 | P6: 0.23866667 | Q6: 117 | R6: 0.34636872 | S6: 14500 | T6: 2931.35 | U6: 0.20216207 | V6: 2772.4712 | W6: 0.054199874 | X6: 750 | Y6: 175 | Z6: 0.23333333 | AA6: 32 | AB6: 0.81714286 | AC6: 14500 | AD6: 3358.53 | AE6: 0.23162276 | AF6: 871.6712 | AG6: =(AD6-AF6)/AF6 -> 2.852978 | AH6: 0 | AI6: =AH6+E6 -> 289 | AJ6: =AI6/D6 -> 0.17171717 | AK6: =VLOOKUP(C6,[1]两年对比终版!$A:$C,3,0) -> 500 | AL6: =AI6-AK6 -> -211 | AM6: =(AI6-AK6)/AK6 -> -0.422 | AN6: 0 | AO6: =AN6+J6 -> 7186.16 | AP6: =AO6/I6 -> 0.20140583 | AQ6: =VLOOKUP(C6,[1]两年对比终版!$A:$W,6,0) -> 9367.9865 | AR6: =(AO6-AQ6)/AQ6 -> -0.2329024 | AS6: 0 | AT6: =AS6+O6 -> 179 | AU6: =AT6/N6 -> 0.23866667 | AV6: =VLOOKUP(C6,[1]两年对比终版!$A:$N,14,0) -> 207 | AW6: =AT6-AV6 -> -28 | AX6: =(AT6-AV6)/AV6 -> -0.1352657 | AY6: 0 | AZ6: =AY6+T6 -> 2931.35 | BA6: =AZ6/S6 -> 0.20216207 | BB6: =VLOOKUP(C6,[1]两年对比终版!$A:$W,17,0) -> 4230.2512 | BC6: =AZ6-BB6 -> -1298.9012 | BD6: =(AZ6-BB6)/BB6 -> -0.30705061 | BE6: 0 | BF6: =BE6+Y6 -> 175 | BG6: =BF6/X6 -> 0.23333333 | BH6: =VLOOKUP(C6,[1]两年对比终版!$A:$T,20,0) -> 121 | BI6: =(BF6-BH6)/BH6 -> 0.44628099 | BJ6: 0 | BK6: =BJ6+AD6 -> 3358.53 | BL6: =BK6/AC6 -> 0.23162276 | BM6: =VLOOKUP(C6,[1]两年对比终版!$A:$W,23,0) -> 2814.2512 | BN6: =(BK6-BM6)/BM6 -> 0.19340093
A7: 3 | B7: A | C7: 俄罗斯（东部） | D7: 400 | E7: 193 | F7: 0.4825 | G7: 207 | H7: -0.07253886 | I7: 6544 | J7: 3691.48 | K7: 0.56410147 | L7: 3066.3678 | M7: 0.16933918 | N7: 160 | O7: 75 | P7: 0.46875 | Q7: 92 | R7: -0.22666667 | S7: 2657 | T7: 978.14 | U7: 0.368137 | V7: 1337.86 | W7: -0.36775922 | X7: 160 | Y7: 49 | Z7: 0.30625 | AA7: 69 | AB7: -0.40816327 | AC7: 2657 | AD7: 637.85 | AE7: 0.24006398 | AF7: 997.73 | AG7: =(AD7-AF7)/AF7 -> -0.36069879 | AH7: 50 | AI7: =AH7+E7 -> 243 | AJ7: =AI7/D7 -> 0.6075 | AK7: =VLOOKUP(C7,[1]两年对比终版!$A:$C,3,0) -> 446 | AL7: =AI7-AK7 -> -203 | AM7: =(AI7-AK7)/AK7 -> -0.45515695 | AN7: 510.13 | AO7: =AN7+J7 -> 4201.61 | AP7: =AO7/I7 -> 0.64205532 | AQ7: =VLOOKUP(C7,[1]两年对比终版!$A:$W,6,0) -> 6485.9783 | AR7: =(AO7-AQ7)/AQ7 -> -0.35220104 | AS7: 50 | AT7: =AS7+O7 -> 125 | AU7: =AT7/N7 -> 0.78125 | AV7: =VLOOKUP(C7,[1]两年对比终版!$A:$N,14,0) -> 126 | AW7: =AT7-AV7 -> -1 | AX7: =(AT7-AV7)/AV7 -> -0.0079365079 | AY7: 510.13 | AZ7: =AY7+T7 -> 1488.27 | BA7: =AZ7/S7 -> 0.56013173 | BB7: =VLOOKUP(C7,[1]两年对比终版!$A:$W,17,0) -> 1887.3783 | BC7: =AZ7-BB7 -> -399.1083 | BD7: =(AZ7-BB7)/BB7 -> -0.21146174 | BE7: 49 | BF7: =BE7+Y7 -> 98 | BG7: =BF7/X7 -> 0.6125 | BH7: =VLOOKUP(C7,[1]两年对比终版!$A:$T,20,0) -> 125 | BI7: =(BF7-BH7)/BH7 -> -0.216 | BJ7: 755.56 | BK7: =BJ7+AD7 -> 1393.41 | BL7: =BK7/AC7 -> 0.52442981 | BM7: =VLOOKUP(C7,[1]两年对比终版!$A:$W,23,0) -> 1964.9378 | BN7: =(BK7-BM7)/BM7 -> -0.29086305
A8: 4 | B8: A | C8: 罗斯托夫 | D8: 270 | E8: 39 | F8: 0.14444444 | G8: 0 | H8: 1 | I8: 4428 | J8: 867.42 | K8: 0.19589431 | L8: 0 | M8: 1 | N8: 120 | O8: 10 | P8: 0.083333333 | Q8: 0 | R8: 1 | S8: 1800 | T8: 102.4 | U8: 0.056888889 | V8: 0 | W8: 1 | X8: 120 | Y8: 10 | Z8: 0.083333333 | AA8: 0 | AB8: 1 | AC8: 1800 | AD8: 102.4 | AE8: 0.056888889 | AF8: 0 | AG8: =(AD8-AF8)/AF8 -> #DIV/0! | AH8: 31 | AI8: =AH8+E8 -> 70 | AJ8: =AI8/D8 -> 0.25925926 | AK8: =VLOOKUP(C8,[1]两年对比终版!$A:$C,3,0) -> 0 | AL8: =AI8-AK8 -> 70 | AM8: =(AI8-AK8)/AK8 -> #DIV/0! | AN8: 341.67 | AO8: =AN8+J8 -> 1209.09 | AP8: =AO8/I8 -> 0.27305556 | AQ8: =VLOOKUP(C8,[1]两年对比终版!$A:$W,6,0) -> 0 | AS8: 31 | AT8: =AS8+O8 -> 41 | AU8: =AT8/N8 -> 0.34166667 | AV8: =VLOOKUP(C8,[1]两年对比终版!$A:$N,14,0) -> 0 | AW8: =AT8-AV8 -> 41 | AX8: =(AT8-AV8)/AV8 -> #DIV/0! | AY8: 341.67 | AZ8: =AY8+T8 -> 444.07 | BA8: =AZ8/S8 -> 0.24670556 | BB8: =VLOOKUP(C8,[1]两年对比终版!$A:$W,17,0) -> 0 | BC8: =AZ8-BB8 -> 444.07 | BD8: =(AZ8-BB8)/BB8 -> #DIV/0! | BE8: 10 | BF8: =BE8+Y8 -> 20 | BG8: =BF8/X8 -> 0.16666667 | BH8: =VLOOKUP(C8,[1]两年对比终版!$A:$T,20,0) -> 0 | BI8: =(BF8-BH8)/BH8 -> #DIV/0! | BJ8: 142 | BK8: =BJ8+AD8 -> 244.4 | BL8: =BK8/AC8 -> 0.13577778 | BM8: =VLOOKUP(C8,[1]两年对比终版!$A:$W,23,0) -> 0 | BN8: =(BK8-BM8)/BM8 -> #DIV/0!
A9: 5 | B9: A | C9: 哈巴 | D9: 270 | E9: 89 | F9: 0.32962963 | G9: 0 | H9: 1 | I9: 4428 | J9: 946.586 | K9: 0.21377281 | L9: 0 | M9: 1 | N9: 120 | O9: 43 | P9: 0.35833333 | Q9: 0 | R9: 1 | S9: 1800 | T9: 456.926 | U9: 0.25384778 | V9: 0 | W9: 1 | X9: 120 | Y9: 18 | Z9: 0.15 | AA9: 0 | AB9: 1 | AC9: 1800 | AD9: 183.536 | AE9: 0.10196444 | AF9: 0 | AG9: =(AD9-AF9)/AF9 -> #DIV/0! | AH9: 80 | AI9: =AH9+E9 -> 169 | AJ9: =AI9/D9 -> 0.62592593 | AK9: =VLOOKUP(C9,[1]两年对比终版!$A:$C,3,0) -> 0 | AL9: =AI9-AK9 -> 169 | AM9: =(AI9-AK9)/AK9 -> #DIV/0! | AN9: 960 | AO9: =AN9+J9 -> 1906.586 | AP9: =AO9/I9 -> 0.43057498 | AQ9: =VLOOKUP(C9,[1]两年对比终版!$A:$W,6,0) -> 0 | AS9: 50 | AT9: =AS9+O9 -> 93 | AU9: =AT9/N9 -> 0.775 | AV9: =VLOOKUP(C9,[1]两年对比终版!$A:$N,14,0) -> 0 | AW9: =AT9-AV9 -> 93 | AX9: =(AT9-AV9)/AV9 -> #DIV/0! | AY9: 474 | AZ9: =AY9+T9 -> 930.926 | BA9: =AZ9/S9 -> 0.51718111 | BB9: =VLOOKUP(C9,[1]两年对比终版!$A:$W,17,0) -> 0 | BC9: =AZ9-BB9 -> 930.926 | BD9: =(AZ9-BB9)/BB9 -> #DIV/0! | BE9: 42 | BF9: =BE9+Y9 -> 60 | BG9: =BF9/X9 -> 0.5 | BH9: =VLOOKUP(C9,[1]两年对比终版!$A:$T,20,0) -> 0 | BI9: =(BF9-BH9)/BH9 -> #DIV/0! | BJ9: 420 | BK9: =BJ9+AD9 -> 603.536 | BL9: =BK9/AC9 -> 0.33529778 | BM9: =VLOOKUP(C9,[1]两年对比终版!$A:$W,23,0) -> 0 | BN9: =(BK9-BM9)/BM9 -> #DIV/0!
A10: 6 | B10: B | C10: 俄罗斯（中南） | D10: 245 | E10: 15 | F10: 0.06122449 | G10: 69 | H10: -3.6 | I10: 4200 | J10: 145.87 | K10: 0.034730952 | L10: 885.396 | M10: -5.0697607 | N10: 100 | O10: 8 | P10: 0.08 | Q10: 28 | R10: -2.5 | S10: 1778 | T10: 78.11 | U10: 0.043931384 | V10: 469.932 | W10: -5.0162847 | X10: 100 | Y10: 9 | Z10: 0.09 | AA10: 28 | AB10: -2.1111111 | AC10: 1778 | AD10: 117.69 | AE10: 0.066192351 | AF10: 370.266 | AG10: =(AD10-AF10)/AF10 -> -0.68214743 | AH10: 71 | AI10: =AH10+E10 -> 86 | AJ10: =AI10/D10 -> 0.35102041 | AK10: =VLOOKUP(C10,[1]两年对比终版!$A:$C,3,0) -> 79 | AL10: =AI10-AK10 -> 7 | AM10: =(AI10-AK10)/AK10 -> 0.088607595 | AN10: 875 | AO10: =AN10+J10 -> 1020.87 | AP10: =AO10/I10 -> 0.24306429 | AQ10: =VLOOKUP(C10,[1]两年对比终版!$A:$W,6,0) -> 1044.926 | AR10: =(AO10-AQ10)/AQ10 -> -0.023021726 | AS10: 45 | AT10: =AS10+O10 -> 53 | AU10: =AT10/N10 -> 0.53 | AV10: =VLOOKUP(C10,[1]两年对比终版!$A:$N,14,0) -> 30 | AW10: =AT10-AV10 -> 23 | AX10: =(AT10-AV10)/AV10 -> 0.76666667 | AY10: 478 | AZ10: =AY10+T10 -> 556.11 | BA10: =AZ10/S10 -> 0.31277278 | BB10: =VLOOKUP(C10,[1]两年对比终版!$A:$W,17,0) -> 487.232 | BC10: =AZ10-BB10 -> 68.878 | BD10: =(AZ10-BB10)/BB10 -> 0.14136592 | BE10: 46 | BF10: =BE10+Y10 -> 55 | BG10: =BF10/X10 -> 0.55 | BH10: =VLOOKUP(C10,[1]两年对比终版!$A:$T,20,0) -> 36 | BI10: =(BF10-BH10)/BH10 -> 0.52777778 | BJ10: 471.3666 | BK10: =BJ10+AD10 -> 589.0566 | BL10: =BK10/AC10 -> 0.33130292 | BM10: =VLOOKUP(C10,[1]两年对比终版!$A:$W,23,0) -> 515.132 | BN10: =(BK10-BM10)/BM10 -> 0.14350613
A11: 7 | B11: B | C11: 俄罗斯（西南） | D11: 489 | E11: 54 | F11: 0.11042945 | G11: 324 | H11: -5 | I11: 7525.12 | J11: 1317.06 | K11: 0.17502179 | L11: 5818.925 | M11: -3.4181169 | N11: 210 | O11: 26 | P11: 0.12380952 | Q11: 133 | R11: -4.1153846 | S11: 2972 | T11: 294.803 | U11: 0.099193472 | V11: 2251.3625 | W11: -6.6368371 | X11: 210 | Y11: 24 | Z11: 0.11428571 | AA11: 28 | AB11: -0.16666667 | AC11: 2972 | AD11: 276.233 | AE11: 0.092945155 | AF11: 709.3345 | AG11: =(AD11-AF11)/AF11 -> -0.61057442 | AH11: 100 | AI11: =AH11+E11 -> 154 | AJ11: =AI11/D11 -> 0.31492843 | AK11: =VLOOKUP(C11,[1]两年对比终版!$A:$C,3,0) -> 415 | AL11: =AI11-AK11 -> -261 | AM11: =(AI11-AK11)/AK11 -> -0.62891566 | AN11: 1600 | AO11: =AN11+J11 -> 2917.06 | AP11: =AO11/I11 -> 0.38764299 | AQ11: =VLOOKUP(C11,[1]两年对比终版!$A:$W,6,0) -> 7818.733 | AR11: =(AO11-AQ11)/AQ11 -> -0.62691398 | AS11: 43 | AT11: =AS11+O11 -> 69 | AU11: =AT11/N11 -> 0.32857143 | AV11: =VLOOKUP(C11,[1]两年对比终版!$A:$N,14,0) -> 156 | AW11: =AT11-AV11 -> -87 | AX11: =(AT11-AV11)/AV11 -> -0.55769231 | AY11: 750 | AZ11: =AY11+T11 -> 1044.803 | BA11: =AZ11/S11 -> 0.35154879 | BB11: =VLOOKUP(C11,[1]两年对比终版!$A:$W,17,0) -> 2594.4505 | BC11: =AZ11-BB11 -> -1549.6475 | BD11: =(AZ11-BB11)/BB11 -> -0.59729315 | BE11: 24 | BF11: =BE11+Y11 -> 48 | BG11: =BF11/X11 -> 0.22857143 | BH11: =VLOOKUP(C11,[1]两年对比终版!$A:$T,20,0) -> 108 | BI11: =(BF11-BH11)/BH11 -> -0.55555556 | BJ11: 410 | BK11: =BJ11+AD11 -> 686.233 | BL11: =BK11/AC11 -> 0.23089939 | BM11: =VLOOKUP(C11,[1]两年对比终版!$A:$W,23,0) -> 1970.7395 | BN11: =(BK11-BM11)/BM11 -> -0.65178909
A12: 8 | B12: C | C12: 莫斯科 | D12: 72 | E12: 2 | F12: 0.027777778 | G12: 0 | H12: 1 | I12: 1085 | J12: 22.84 | K12: 0.021050691 | L12: 0 | M12: 1 | N12: 30 | O12: 2 | P12: 0.066666667 | Q12: 0 | R12: 1 | S12: 450 | T12: 22.84 | U12: 0.050755556 | V12: 0 | W12: 1 | X12: 30 | Y12: 2 | Z12: 0.066666667 | AA12: 0 | AB12: 1 | AC12: 450 | AD12: 22.84 | AE12: 0.050755556 | AF12: 0 | AG12: =(AD12-AF12)/AF12 -> #DIV/0! | AH12: 20 | AI12: =AH12+E12 -> 22 | AJ12: =AI12/D12 -> 0.30555556 | AK12: =VLOOKUP(C12,[1]两年对比终版!$A:$C,3,0) -> 0 | AL12: =AI12-AK12 -> 22 | AM12: =(AI12-AK12)/AK12 -> #DIV/0! | AN12: 156 | AO12: =AN12+J12 -> 178.84 | AP12: =AO12/I12 -> 0.16482949 | AQ12: =VLOOKUP(C12,[1]两年对比终版!$A:$W,6,0) -> 0 | AS12: 20 | AT12: =AS12+O12 -> 22 | AU12: =AT12/N12 -> 0.73333333 | AV12: =VLOOKUP(C12,[1]两年对比终版!$A:$N,14,0) -> 0 | AW12: =AT12-AV12 -> 22 | AX12: =(AT12-AV12)/AV12 -> #DIV/0! | AY12: 156 | AZ12: =AY12+T12 -> 178.84 | BA12: =AZ12/S12 -> 0.39742222 | BB12: =VLOOKUP(C12,[1]两年对比终版!$A:$W,17,0) -> 0 | BC12: =AZ12-BB12 -> 178.84 | BD12: =(AZ12-BB12)/BB12 -> #DIV/0! | BE12: 20 | BF12: =BE12+Y12 -> 22 | BG12: =BF12/X12 -> 0.73333333 | BH12: =VLOOKUP(C12,[1]两年对比终版!$A:$T,20,0) -> 0 | BI12: =(BF12-BH12)/BH12 -> #DIV/0! | BJ12: 156 | BK12: =BJ12+AD12 -> 178.84 | BL12: =BK12/AC12 -> 0.39742222 | BM12: =VLOOKUP(C12,[1]两年对比终版!$A:$W,23,0) -> 0 | BN12: =(BK12-BM12)/BM12 -> #DIV/0!
A13: 9 | B13: C | C13: 叶卡 | D13: 72 | E13: 0 | F13: 0 | G13: 0 | H13: #DIV/0! | I13: 1085 | J13: 0 | K13: 0 | L13: 0 | M13: #DIV/0! | N13: 30 | O13: 0 | P13: 0 | Q13: 0 | R13: #DIV/0! | S13: 450 | T13: 0 | U13: 0 | V13: 0 | W13: #DIV/0! | X13: 30 | Y13: 0 | Z13: 0 | AA13: 0 | AB13: #DIV/0! | AC13: 450 | AD13: 0 | AE13: 0 | AF13: 0 | AG13: =(AD13-AF13)/AF13 -> #DIV/0! | AH13: 0 | AI13: =AH13+E13 -> 0 | AJ13: =AI13/D13 -> 0 | AK13: =VLOOKUP(C13,[1]两年对比终版!$A:$C,3,0) -> 0 | AL13: =AI13-AK13 -> 0 | AM13: =(AI13-AK13)/AK13 -> #DIV/0! | AN13: 0 | AO13: =AN13+J13 -> 0 | AP13: =AO13/I13 -> 0 | AQ13: =VLOOKUP(C13,[1]两年对比终版!$A:$W,6,0) -> 0 | AS13: 0 | AT13: =AS13+O13 -> 0 | AU13: =AT13/N13 -> 0 | AV13: =VLOOKUP(C13,[1]两年对比终版!$A:$N,14,0) -> 0 | AW13: =AT13-AV13 -> 0 | AX13: =(AT13-AV13)/AV13 -> #DIV/0! | AY13: 0 | AZ13: =AY13+T13 -> 0 | BA13: =AZ13/S13 -> 0 | BB13: =VLOOKUP(C13,[1]两年对比终版!$A:$W,17,0) -> 0 | BC13: =AZ13-BB13 -> 0 | BD13: =(AZ13-BB13)/BB13 -> #DIV/0! | BE13: 0 | BF13: =BE13+Y13 -> 0 | BG13: =BF13/X13 -> 0 | BH13: =VLOOKUP(C13,[1]两年对比终版!$A:$T,20,0) -> 0 | BI13: =(BF13-BH13)/BH13 -> #DIV/0! | BJ13: 0 | BK13: =BJ13+AD13 -> 0 | BL13: =BK13/AC13 -> 0 | BM13: =VLOOKUP(C13,[1]两年对比终版!$A:$W,23,0) -> 0 | BN13: =(BK13-BM13)/BM13 -> #DIV/0!
A14: 10 | B14: C | C14: 新西 | D14: 72 | E14: 0 | F14: 0 | G14: 0 | H14: #DIV/0! | I14: 1085 | J14: 0 | K14: 0 | L14: 0 | M14: #DIV/0! | N14: 30 | O14: 0 | P14: 0 | Q14: 0 | R14: #DIV/0! | S14: 450 | T14: 0 | U14: 0 | V14: 0 | W14: #DIV/0! | X14: 30 | Y14: 0 | Z14: 0 | AA14: 0 | AB14: #DIV/0! | AC14: 450 | AD14: 0 | AE14: 0 | AF14: 0 | AG14: =(AD14-AF14)/AF14 -> #DIV/0! | AH14: 0 | AI14: =AH14+E14 -> 0 | AJ14: =AI14/D14 -> 0 | AK14: =VLOOKUP(C14,[1]两年对比终版!$A:$C,3,0) -> 0 | AL14: =AI14-AK14 -> 0 | AM14: =(AI14-AK14)/AK14 -> #DIV/0! | AN14: 0 | AO14: =AN14+J14 -> 0 | AP14: =AO14/I14 -> 0 | AQ14: =VLOOKUP(C14,[1]两年对比终版!$A:$W,6,0) -> 0 | AS14: 0 | AT14: =AS14+O14 -> 0 | AU14: =AT14/N14 -> 0 | AV14: =VLOOKUP(C14,[1]两年对比终版!$A:$N,14,0) -> 0 | AW14: =AT14-AV14 -> 0 | AX14: =(AT14-AV14)/AV14 -> #DIV/0! | AY14: 0 | AZ14: =AY14+T14 -> 0 | BA14: =AZ14/S14 -> 0 | BB14: =VLOOKUP(C14,[1]两年对比终版!$A:$W,17,0) -> 0 | BC14: =AZ14-BB14 -> 0 | BD14: =(AZ14-BB14)/BB14 -> #DIV/0! | BE14: 0 | BF14: =BE14+Y14 -> 0 | BG14: =BF14/X14 -> 0 | BH14: =VLOOKUP(C14,[1]两年对比终版!$A:$T,20,0) -> 0 | BI14: =(BF14-BH14)/BH14 -> #DIV/0! | BJ14: 0 | BK14: =BJ14+AD14 -> 0 | BL14: =BK14/AC14 -> 0 | BM14: =VLOOKUP(C14,[1]两年对比终版!$A:$W,23,0) -> 0 | BN14: =(BK14-BM14)/BM14 -> #DIV/0!
A15: 俄罗斯合计 | D15: 5256 | E15: 1110 | F15: 0.21118721 | G15: 1328 | H15: -0.1963964 | I15: 101740.12 | J15: 22497.926 | K15: 0.22113131 | L15: 23737.365 | M15: -0.055091238 | N15: 2300 | O15: 634 | P15: 0.27565217 | Q15: 559 | R15: 0.11829653 | S15: 41357 | T15: 10310.719 | U15: 0.24931013 | V15: 10378.782 | W15: -0.0066012176 | X15: 2300 | Y15: 453 | Z15: 0.19695652 | AA15: 291 | AB15: 0.35761589 | AC15: 41357 | AD15: 8142.419 | AE15: 0.19688128 | AF15: 5367.3683 | AG15: =(AD15-AF15)/AF15 -> 0.5170226 | AH15: =SUM(AH5:AH14) -> 932 | AI15: =AH15+E15 -> 2042 | AJ15: =AI15/D15 -> 0.38850837 | AK15: =SUM(AK5:AK14) -> 2154 | AL15: =AI15-AK15 -> -112 | AM15: =(AI15-AK15)/AK15 -> -0.051996286 | AN15: =SUM(AN5:AN14) -> 14902.8 | AO15: =AN15+J15 -> 37400.726 | AP15: =AO15/I15 -> 0.3676104 | AQ15: =SUM(AQ5:AQ14) -> 37366.251 | AR15: =(AO15-AQ15)/AQ15 -> 0.00092261864 | AS15: =SUM(AS5:AS14) -> 368 | AT15: =AS15+O15 -> 1002 | AU15: =AT15/N15 -> 0.43565217 | AV15: =SUM(AV5:AV14) -> 890 | AW15: =AT15-AV15 -> 112 | AX15: =(AT15-AV15)/AV15 -> 0.1258427 | AY15: =SUM(AY5:AY14) -> 4200.8 | AZ15: =AY15+T15 -> 14511.519 | BA15: =AZ15/S15 -> 0.35088423 | BB15: =SUM(BB5:BB14) -> 15906.592 | BC15: =AZ15-BB15 -> -1395.0734 | BD15: =(AZ15-BB15)/BB15 -> -0.0877041 | BE15: =SUM(BE5:BE14) -> 373 | BF15: =BE15+Y15 -> 826 | BG15: =BF15/X15 -> 0.35913043 | BH15: =SUM(BH5:BH14) -> 613 | BI15: =(BF15-BH15)/BH15 -> 0.34747145 | BJ15: =SUM(BJ5:BJ14) -> 6384.9266 | BK15: =BJ15+AD15 -> 14527.346 | BL15: =BK15/AC15 -> 0.35126691 | BM15: =SUM(BM5:BM14) -> 11385.117 | BN15: =(BK15-BM15)/BM15 -> 0.27599439
A16: 11 | B16: D | C16: 朝鲜-韩国 | D16: 54 | E16: 34 | F16: 0.62962963 | G16: 15 | H16: 0.55882353 | I16: 540 | J16: 294.161 | K16: 0.54474259 | L16: 152.22 | M16: 0.48252828 | N16: 32 | O16: 4 | P16: 0.125 | Q16: 1 | R16: 0.75 | S16: 264.163 | T16: 36.861 | U16: 0.13953885 | V16: 7.6 | W16: 0.79382003 | X16: 32 | Y16: 6 | Z16: 0.1875 | AA16: 1 | AB16: 0.83333333 | AC16: 264.163 | AD16: 55.4871 | AE16: 0.21004872 | AF16: 7.6 | AG16: =(AD16-AF16)/AF16 -> 6.3009342 | AH16: =VLOOKUP(C16,'[2]5月汇总'!$C:$AE,24,0) -> 13 | AI16: =AH16+E16 -> 47 | AJ16: =AI16/D16 -> 0.87037037 | AK16: =VLOOKUP(C16,[1]两年对比终版!$A:$C,3,0) -> 35 | AL16: =AI16-AK16 -> 12 | AM16: =(AI16-AK16)/AK16 -> 0.34285714 | AN16: =VLOOKUP(C16,'[2]5月汇总'!$C:$AA,25,0) -> 130 | AO16: =AN16+J16 -> 424.161 | AP16: =AO16/I16 -> 0.78548333 | AQ16: =VLOOKUP(C16,[1]两年对比终版!$A:$W,6,0) -> 287.19 | AR16: =(AO16-AQ16)/AQ16 -> 0.47693513 | AS16: =VLOOKUP(C16,'[2]5月汇总'!$C:$AE,26,0) -> 10 | AT16: =AS16+O16 -> 14 | AU16: =AT16/N16 -> 0.4375 | AV16: =VLOOKUP(C16,[1]两年对比终版!$A:$N,14,0) -> 1 | AW16: =AT16-AV16 -> 13 | AX16: =(AT16-AV16)/AV16 -> 13 | AY16: =VLOOKUP(C16,'[2]5月汇总'!$C:$AE,27,0) -> 100 | AZ16: =AY16+T16 -> 136.861 | BA16: =AZ16/S16 -> 0.518093 | BB16: =VLOOKUP(C16,[1]两年对比终版!$A:$W,17,0) -> 7.6 | BC16: =AZ16-BB16 -> 129.261 | BD16: =(AZ16-BB16)/BB16 -> 17.008026 | BE16: =VLOOKUP(C16,'[2]5月汇总'!$C:$AE,28,0) -> 10 | BF16: =BE16+Y16 -> 16 | BG16: =BF16/X16 -> 0.5 | BH16: =VLOOKUP(C16,[1]两年对比终版!$A:$T,20,0) -> 1 | BI16: =(BF16-BH16)/BH16 -> 15 | BJ16: =VLOOKUP(C16,'[2]5月汇总'!$C:$AE,29,0) -> 77.82 | BK16: =BJ16+AD16 -> 133.3071 | BL16: =BK16/AC16 -> 0.50463956 | BM16: =VLOOKUP(C16,[1]两年对比终版!$A:$W,23,0) -> 7.6 | BN16: =(BK16-BM16)/BM16 -> 16.540408
A17: 12 | B17: A | C17: 新加坡市政会 | D17: 277 | E17: 67 | F17: 0.24187726 | G17: 111 | H17: -0.65671642 | I17: 6100 | J17: 1640.06 | K17: 0.2688623 | L17: 2182.0143 | M17: -0.33044787 | N17: 101 | O17: 4 | P17: 0.03960396 | Q17: 42 | R17: -9.5 | S17: 2153 | T17: 74.2762 | U17: 0.034498932 | V17: 1068.6719 | W17: -13.38781 | X17: 101 | Y17: 21 | Z17: 0.20792079 | AA17: 21 | AB17: 0 | AC17: 2153 | AD17: 398.035 | AE17: 0.18487459 | AF17: 522.63907 | AG17: =(AD17-AF17)/AF17 -> -0.23841324 | AH17: =VLOOKUP(C17,'[2]5月汇总'!$C:$AE,24,0) -> 50 | AI17: =AH17+E17 -> 117 | AJ17: =AI17/D17 -> 0.42238267 | AK17: =VLOOKUP(C17,[1]两年对比终版!$A:$C,3,0) -> 196 | AL17: =AI17-AK17 -> -79 | AM17: =(AI17-AK17)/AK17 -> -0.40306122 | AN17: =VLOOKUP(C17,'[2]5月汇总'!$C:$AA,25,0) -> 1000 | AO17: =AN17+J17 -> 2640.06 | AP17: =AO17/I17 -> 0.43279672 | AQ17: =VLOOKUP(C17,[1]两年对比终版!$A:$W,6,0) -> 4135.4805 | AR17: =(AO17-AQ17)/AQ17 -> -0.36160743 | AS17: =VLOOKUP(C17,'[2]5月汇总'!$C:$AE,26,0) -> 0 | AT17: =AS17+O17 -> 4 | AU17: =AT17/N17 -> 0.03960396 | AV17: =VLOOKUP(C17,[1]两年对比终版!$A:$N,14,0) -> 77 | AW17: =AT17-AV17 -> -73 | AX17: =(AT17-AV17)/AV17 -> -0.94805195 | AY17: =VLOOKUP(C17,'[2]5月汇总'!$C:$AE,27,0) -> 0 | AZ17: =AY17+T17 -> 74.2762 | BA17: =AZ17/S17 -> 0.034498932 | BB17: =VLOOKUP(C17,[1]两年对比终版!$A:$W,17,0) -> 1734.6186 | BC17: =AZ17-BB17 -> -1660.3424 | BD17: =(AZ17-BB17)/BB17 -> -0.9571801 | BE17: =VLOOKUP(C17,'[2]5月汇总'!$C:$AE,28,0) -> 11 | BF17: =BE17+Y17 -> 32 | BG17: =BF17/X17 -> 0.31683168 | BH17: =VLOOKUP(C17,[1]两年对比终版!$A:$T,20,0) -> 25 | BI17: =(BF17-BH17)/BH17 -> 0.28 | BJ17: =VLOOKUP(C17,'[2]5月汇总'!$C:$AE,29,0) -> 220 | BK17: =BJ17+AD17 -> 618.035 | BL17: =BK17/AC17 -> 0.28705759 | BM17: =VLOOKUP(C17,[1]两年对比终版!$A:$W,23,0) -> 619.60194 | BN17: =(BK17-BM17)/BM17 -> -0.0025289479
A18: 13 | B18: A | C18: 新加坡HDB | D18: 566 | E18: 189 | F18: 0.33392226 | G18: 87 | H18: 0.53968254 | I18: 20400 | J18: 4595.47 | K18: 0.22526814 | L18: 1832.6242 | M18: 0.60121071 | N18: 260 | O18: 121 | P18: 0.46538462 | Q18: 33 | R18: 0.72727273 | S18: 8500 | T18: 5373.9 | U18: 0.63222353 | V18: 1324.4482 | W18: 0.7535406 | X18: 260 | Y18: 122 | Z18: 0.46923077 | AA18: 1 | AB18: 0.99180328 | AC18: 8500 | AD18: 5274.41 | AE18: 0.62051882 | AF18: 13.34 | AG18: =(AD18-AF18)/AF18 -> 394.38306 | AH18: =VLOOKUP(C18,'[2]5月汇总'!$C:$AE,24,0) -> 75 | AI18: =AH18+E18 -> 264 | AJ18: =AI18/D18 -> 0.4664311 | AK18: =VLOOKUP(C18,[1]两年对比终版!$A:$C,3,0) -> 260 | AL18: =AI18-AK18 -> 4 | AM18: =(AI18-AK18)/AK18 -> 0.015384615 | AN18: =VLOOKUP(C18,'[2]5月汇总'!$C:$AA,25,0) -> 2500 | AO18: =AN18+J18 -> 7095.47 | AP18: =AO18/I18 -> 0.34781716 | AQ18: =VLOOKUP(C18,[1]两年对比终版!$A:$W,6,0) -> 5925.604 | AR18: =(AO18-AQ18)/AQ18 -> 0.19742561 | AS18: =VLOOKUP(C18,'[2]5月汇总'!$C:$AE,26,0) -> 35 | AT18: =AS18+O18 -> 156 | AU18: =AT18/N18 -> 0.6 | AV18: =VLOOKUP(C18,[1]两年对比终版!$A:$N,14,0) -> 106 | AW18: =AT18-AV18 -> 50 | AX18: =(AT18-AV18)/AV18 -> 0.47169811 | AY18: =VLOOKUP(C18,'[2]5月汇总'!$C:$AE,27,0) -> 1260 | AZ18: =AY18+T18 -> 6633.9 | BA18: =AZ18/S18 -> 0.78045882 | BB18: =VLOOKUP(C18,[1]两年对比终版!$A:$W,17,0) -> 3962.6091 | BC18: =AZ18-BB18 -> 2671.2909 | BD18: =(AZ18-BB18)/BB18 -> 0.67412425 | BE18: =VLOOKUP(C18,'[2]5月汇总'!$C:$AE,28,0) -> 36 | BF18: =BE18+Y18 -> 158 | BG18: =BF18/X18 -> 0.60769231 | BH18: =VLOOKUP(C18,[1]两年对比终版!$A:$T,20,0) -> 10 | BI18: =(BF18-BH18)/BH18 -> 14.8 | BJ18: =VLOOKUP(C18,'[2]5月汇总'!$C:$AE,29,0) -> 1298 | BK18: =BJ18+AD18 -> 6572.41 | BL18: =BK18/AC18 -> 0.77322471 | BM18: =VLOOKUP(C18,[1]两年对比终版!$A:$W,23,0) -> 374.14793 | BN18: =(BK18-BM18)/BM18 -> 16.566341
A19: 14 | B19: D | C19: 泰国 | D19: 90 | E19: 20 | F19: 0.22222222 | G19: 37 | H19: -0.85 | I19: 840 | J19: 264.232 | K19: 0.3145619 | L19: 361.6613 | M19: -0.36872634 | N19: 25 | O19: 4 | P19: 0.16 | Q19: 15 | R19: -2.75 | S19: 200 | T19: 47.118 | U19: 0.23559 | V19: 142.7175 | W19: -2.028938 | X19: 25 | Y19: 3 | Z19: 0.12 | AA19: 18 | AB19: -5 | AC19: 200 | AD19: 32.8201 | AE19: 0.1641005 | AF19: 174.47638 | AG19: =(AD19-AF19)/AF19 -> -0.81189373 | AH19: =VLOOKUP(C19,'[2]5月汇总'!$C:$AE,24,0) -> 20 | AI19: =AH19+E19 -> 40 | AJ19: =AI19/D19 -> 0.44444444 | AK19: =VLOOKUP(C19,[1]两年对比终版!$A:$C,3,0) -> 52 | AL19: =AI19-AK19 -> -12 | AM19: =(AI19-AK19)/AK19 -> -0.23076923 | AN19: =VLOOKUP(C19,'[2]5月汇总'!$C:$AA,25,0) -> 152.8 | AO19: =AN19+J19 -> 417.032 | AP19: =AO19/I19 -> 0.49646667 | AQ19: =VLOOKUP(C19,[1]两年对比终版!$A:$W,6,0) -> 517.46812 | AR19: =(AO19-AQ19)/AQ19 -> -0.19409142 | AS19: =VLOOKUP(C19,'[2]5月汇总'!$C:$AE,26,0) -> 2 | AT19: =AS19+O19 -> 6 | AU19: =AT19/N19 -> 0.24 | AV19: =VLOOKUP(C19,[1]两年对比终版!$A:$N,14,0) -> 26 | AW19: =AT19-AV19 -> -20 | AX19: =(AT19-AV19)/AV19 -> -0.76923077 | AY19: =VLOOKUP(C19,'[2]5月汇总'!$C:$AE,27,0) -> 20.08 | AZ19: =AY19+T19 -> 67.198 | BA19: =AZ19/S19 -> 0.33599 | BB19: =VLOOKUP(C19,[1]两年对比终版!$A:$W,17,0) -> 239.82783 | BC19: =AZ19-BB19 -> -172.62983 | BD19: =(AZ19-BB19)/BB19 -> -0.71980733 | BE19: =VLOOKUP(C19,'[2]5月汇总'!$C:$AE,28,0) -> 2 | BF19: =BE19+Y19 -> 5 | BG19: =BF19/X19 -> 0.2 | BH19: =VLOOKUP(C19,[1]两年对比终版!$A:$T,20,0) -> 25 | BI19: =(BF19-BH19)/BH19 -> -0.8 | BJ19: =VLOOKUP(C19,'[2]5月汇总'!$C:$AE,29,0) -> 20 | BK19: =BJ19+AD19 -> 52.8201 | BL19: =BK19/AC19 -> 0.2641005 | BM19: =VLOOKUP(C19,[1]两年对比终版!$A:$W,23,0) -> 233.58913 | BN19: =(BK19-BM19)/BM19 -> -0.77387604
A20: 15 | B20: D | C20: 泰国2 | D20: 136 | E20: 44 | F20: 0.32352941 | G20: 0 | H20: 1 | I20: 1200 | J20: 382.54 | K20: 0.31878333 | L20: 0 | M20: 1 | N20: 36 | O20: 9 | P20: 0.25 | Q20: 0 | R20: 1 | S20: 300 | T20: 74.13 | U20: 0.2471 | V20: 0 | W20: 1 | X20: 36 | Y20: 9 | Z20: 0.25 | AA20: 0 | AB20: 1 | AC20: 300 | AD20: 74.13 | AE20: 0.2471 | AF20: 0 | AG20: =(AD20-AF20)/AF20 -> #DIV/0! | AH20: =VLOOKUP(C20,'[2]5月汇总'!$C:$AE,24,0) -> 30 | AI20: =AH20+E20 -> 74 | AJ20: =AI20/D20 -> 0.54411765 | AK20: =VLOOKUP(C20,[1]两年对比终版!$A:$C,3,0) -> 0 | AL20: =AI20-AK20 -> 74 | AM20: =(AI20-AK20)/AK20 -> #DIV/0! | AN20: =VLOOKUP(C20,'[2]5月汇总'!$C:$AA,25,0) -> 240 | AO20: =AN20+J20 -> 622.54 | AP20: =AO20/I20 -> 0.51878333 | AQ20: =VLOOKUP(C20,[1]两年对比终版!$A:$W,6,0) -> 0 | AS20: =VLOOKUP(C20,'[2]5月汇总'!$C:$AE,26,0) -> 30 | AT20: =AS20+O20 -> 39 | AU20: =AT20/N20 -> 1.0833333 | AV20: =VLOOKUP(C20,[1]两年对比终版!$A:$N,14,0) -> 0 | AW20: =AT20-AV20 -> 39 | AX20: =(AT20-AV20)/AV20 -> #DIV/0! | AY20: =VLOOKUP(C20,'[2]5月汇总'!$C:$AE,27,0) -> 240 | AZ20: =AY20+T20 -> 314.13 | BA20: =AZ20/S20 -> 1.0471 | BB20: =VLOOKUP(C20,[1]两年对比终版!$A:$W,17,0) -> 0 | BC20: =AZ20-BB20 -> 314.13 | BD20: =(AZ20-BB20)/BB20 -> #DIV/0! | BE20: =VLOOKUP(C20,'[2]5月汇总'!$C:$AE,28,0) -> 20 | BF20: =BE20+Y20 -> 29 | BG20: =BF20/X20 -> 0.80555556 | BH20: =VLOOKUP(C20,[1]两年对比终版!$A:$T,20,0) -> 0 | BI20: =(BF20-BH20)/BH20 -> #DIV/0! | BJ20: =VLOOKUP(C20,'[2]5月汇总'!$C:$AE,29,0) -> 160 | BK20: =BJ20+AD20 -> 234.13 | BL20: =BK20/AC20 -> 0.78043333 | BM20: =VLOOKUP(C20,[1]两年对比终版!$A:$W,23,0) -> 0 | BN20: =(BK20-BM20)/BM20 -> #DIV/0!
A21: 16 | B21: D | C21: 金三角 | D21: 40 | E21: 5 | F21: 0.125 | G21: 40 | H21: -7 | I21: 200 | J21: 40.6814 | K21: 0.203407 | L21: 334.90668 | M21: -7.2324275 | N21: 36 | O21: 0 | P21: 0 | Q21: 0 | R21: #DIV/0! | S21: 200 | T21: 0 | U21: 0 | V21: 0 | W21: #DIV/0! | X21: 36 | Y21: 0 | Z21: 0 | AA21: 0 | AB21: #DIV/0! | AC21: 200 | AD21: 0 | AE21: 0 | AF21: 0 | AG21: =(AD21-AF21)/AF21 -> #DIV/0! | AH21: =VLOOKUP(C21,'[2]5月汇总'!$C:$AE,24,0) -> 20 | AI21: =AH21+E21 -> 25 | AJ21: =AI21/D21 -> 0.625 | AK21: =VLOOKUP(C21,[1]两年对比终版!$A:$C,3,0) -> 94 | AL21: =AI21-AK21 -> -69 | AM21: =(AI21-AK21)/AK21 -> -0.73404255 | AN21: =VLOOKUP(C21,'[2]5月汇总'!$C:$AA,25,0) -> 140 | AO21: =AN21+J21 -> 180.6814 | AP21: =AO21/I21 -> 0.903407 | AQ21: =VLOOKUP(C21,[1]两年对比终版!$A:$W,6,0) -> 1146.3367 | AR21: =(AO21-AQ21)/AQ21 -> -0.84238365 | AS21: =VLOOKUP(C21,'[2]5月汇总'!$C:$AE,26,0) -> 0 | AT21: =AS21+O21 -> 0 | AU21: =AT21/N21 -> 0 | AV21: =VLOOKUP(C21,[1]两年对比终版!$A:$N,14,0) -> 0 | AW21: =AT21-AV21 -> 0 | AX21: =(AT21-AV21)/AV21 -> #DIV/0! | AY21: =VLOOKUP(C21,'[2]5月汇总'!$C:$AE,27,0) -> 0 | AZ21: =AY21+T21 -> 0 | BA21: =AZ21/S21 -> 0 | BB21: =VLOOKUP(C21,[1]两年对比终版!$A:$W,17,0) -> 0 | BC21: =AZ21-BB21 -> 0 | BD21: =(AZ21-BB21)/BB21 -> #DIV/0! | BE21: =VLOOKUP(C21,'[2]5月汇总'!$C:$AE,28,0) -> 0 | BF21: =BE21+Y21 -> 0 | BG21: =BF21/X21 -> 0 | BH21: =VLOOKUP(C21,[1]两年对比终版!$A:$T,20,0) -> 0 | BI21: =(BF21-BH21)/BH21 -> #DIV/0! | BJ21: =VLOOKUP(C21,'[2]5月汇总'!$C:$AE,29,0) -> 0 | BK21: =BJ21+AD21 -> 0 | BL21: =BK21/AC21 -> 0 | BM21: =VLOOKUP(C21,[1]两年对比终版!$A:$W,23,0) -> 0 | BN21: =(BK21-BM21)/BM21 -> #DIV/0!
A22: 17 | B22: B | C22: 马来西亚 | D22: 109 | E22: 48 | F22: 0.44036697 | G22: 43 | H22: 0.10416667 | I22: 900 | J22: 794.926 | K22: 0.88325111 | L22: 919.84 | M22: -0.15713916 | N22: 61 | O22: 14 | P22: 0.2295082 | Q22: 12 | R22: 0.14285714 | S22: 521 | T22: 209.618 | U22: 0.40233781 | V22: 82.925 | W22: 0.60439943 | X22: 61 | Y22: 6 | Z22: 0.098360656 | AA22: 7 | AB22: -0.16666667 | AC22: 521 | AD22: 56.597 | AE22: 0.10863148 | AF22: 83.85 | AG22: =(AD22-AF22)/AF22 -> -0.32502087 | AH22: =VLOOKUP(C22,'[2]5月汇总'!$C:$AE,24,0) -> 112 | AI22: =AH22+E22 -> 160 | AJ22: =AI22/D22 -> 1.4678899 | AK22: =VLOOKUP(C22,[1]两年对比终版!$A:$C,3,0) -> 66 | AL22: =AI22-AK22 -> 94 | AM22: =(AI22-AK22)/AK22 -> 1.4242424 | AN22: =VLOOKUP(C22,'[2]5月汇总'!$C:$AA,25,0) -> 1109.12 | AO22: =AN22+J22 -> 1904.046 | AP22: =AO22/I22 -> 2.1156067 | AQ22: =VLOOKUP(C22,[1]两年对比终版!$A:$W,6,0) -> 1463.75 | AR22: =(AO22-AQ22)/AQ22 -> 0.3008 | AS22: =VLOOKUP(C22,'[2]5月汇总'!$C:$AE,26,0) -> 26 | AT22: =AS22+O22 -> 40 | AU22: =AT22/N22 -> 0.6557377 | AV22: =VLOOKUP(C22,[1]两年对比终版!$A:$N,14,0) -> 16 | AW22: =AT22-AV22 -> 24 | AX22: =(AT22-AV22)/AV22 -> 1.5 | AY22: =VLOOKUP(C22,'[2]5月汇总'!$C:$AE,27,0) -> 722.73 | AZ22: =AY22+T22 -> 932.348 | BA22: =AZ22/S22 -> 1.7895355 | BB22: =VLOOKUP(C22,[1]两年对比终版!$A:$W,17,0) -> 132.085 | BC22: =AZ22-BB22 -> 800.263 | BD22: =(AZ22-BB22)/BB22 -> 6.0586971 | BE22: =VLOOKUP(C22,'[2]5月汇总'!$C:$AE,28,0) -> 14 | BF22: =BE22+Y22 -> 20 | BG22: =BF22/X22 -> 0.32786885 | BH22: =VLOOKUP(C22,[1]两年对比终版!$A:$T,20,0) -> 17 | BI22: =(BF22-BH22)/BH22 -> 0.17647059 | BJ22: =VLOOKUP(C22,'[2]5月汇总'!$C:$AE,29,0) -> 463.24 | BK22: =BJ22+AD22 -> 519.837 | BL22: =BK22/AC22 -> 0.99776775 | BM22: =VLOOKUP(C22,[1]两年对比终版!$A:$W,23,0) -> 140.475 | BN22: =(BK22-BM22)/BM22 -> 2.7005659
A23: 18 | B23: D | C23: 马尔代夫 | D23: 36 | E23: 23 | F23: 0.63888889 | G23: 15 | H23: 0.34782609 | I23: 630 | J23: 266.22 | K23: 0.42257143 | L23: 194.69801 | M23: 0.26865746 | N23: 17 | O23: 2 | P23: 0.11764706 | Q23: 5 | R23: -1.5 | S23: 264.163 | T23: 20.3891 | U23: 0.077183784 | V23: 67.535637 | W23: -2.3123403 | X23: 17 | Y23: 2 | Z23: 0.11764706 | AA23: 7 | AB23: -2.5 | AC23: 264.163 | AD23: 22.29 | AE23: 0.08437972 | AF23: 79.339117 | AG23: =(AD23-AF23)/AF23 -> -0.7190541 | AH23: =VLOOKUP(C23,'[2]5月汇总'!$C:$AE,24,0) -> 8 | AI23: =AH23+E23 -> 31 | AJ23: =AI23/D23 -> 0.86111111 | AK23: =VLOOKUP(C23,[1]两年对比终版!$A:$C,3,0) -> 37 | AL23: =AI23-AK23 -> -6 | AM23: =(AI23-AK23)/AK23 -> -0.16216216 | AN23: =VLOOKUP(C23,'[2]5月汇总'!$C:$AA,25,0) -> 130 | AO23: =AN23+J23 -> 396.22 | AP23: =AO23/I23 -> 0.62892063 | AQ23: =VLOOKUP(C23,[1]两年对比终版!$A:$W,6,0) -> 543.86292 | AR23: =(AO23-AQ23)/AQ23 -> -0.27147084 | AS23: =VLOOKUP(C23,'[2]5月汇总'!$C:$AE,26,0) -> 7 | AT23: =AS23+O23 -> 9 | AU23: =AT23/N23 -> 0.52941176 | AV23: =VLOOKUP(C23,[1]两年对比终版!$A:$N,14,0) -> 7 | AW23: =AT23-AV23 -> 2 | AX23: =(AT23-AV23)/AV23 -> 0.28571429 | AY23: =VLOOKUP(C23,'[2]5月汇总'!$C:$AE,27,0) -> 80.5 | AZ23: =AY23+T23 -> 100.8891 | BA23: =AZ23/S23 -> 0.38191988 | BB23: =VLOOKUP(C23,[1]两年对比终版!$A:$W,17,0) -> 96.411317 | BC23: =AZ23-BB23 -> 4.477783 | BD23: =(AZ23-BB23)/BB23 -> 0.046444579 | BE23: =VLOOKUP(C23,'[2]5月汇总'!$C:$AE,28,0) -> 7 | BF23: =BE23+Y23 -> 9 | BG23: =BF23/X23 -> 0.52941176 | BH23: =VLOOKUP(C23,[1]两年对比终版!$A:$T,20,0) -> 16 | BI23: =(BF23-BH23)/BH23 -> -0.4375 | BJ23: =VLOOKUP(C23,'[2]5月汇总'!$C:$AE,29,0) -> 71.5 | BK23: =BJ23+AD23 -> 93.79 | BL23: =BK23/AC23 -> 0.35504594 | BM23: =VLOOKUP(C23,[1]两年对比终版!$A:$W,23,0) -> 3354.156 | BN23: =(BK23-BM23)/BM23 -> -0.97203767
A24: 19 | B24: D | C24: 香港-台湾 | D24: 20 | E24: 8 | F24: 0.4 | G24: 0 | H24: 1 | I24: 200 | J24: 50.38 | K24: 0.2519 | L24: 0 | M24: 1 | N24: 15 | O24: 0 | P24: 0 | Q24: 0 | R24: #DIV/0! | S24: 200 | T24: 0 | U24: 0 | V24: 0 | W24: #DIV/0! | X24: 15 | Y24: 0 | Z24: 0 | AA24: 0 | AB24: #DIV/0! | AC24: 200 | AD24: 0 | AE24: 0 | AF24: 0 | AG24: =(AD24-AF24)/AF24 -> #DIV/0! | AH24: =VLOOKUP(C24,'[2]5月汇总'!$C:$AE,24,0) -> 0 | AI24: =AH24+E24 -> 8 | AJ24: =AI24/D24 -> 0.4 | AK24: =VLOOKUP(C24,[1]两年对比终版!$A:$C,3,0) -> 0 | AL24: =AI24-AK24 -> 8 | AM24: =(AI24-AK24)/AK24 -> #DIV/0! | AN24: =VLOOKUP(C24,'[2]5月汇总'!$C:$AA,25,0) -> 0 | AO24: =AN24+J24 -> 50.38 | AP24: =AO24/I24 -> 0.2519 | AQ24: =VLOOKUP(C24,[1]两年对比终版!$A:$W,6,0) -> 0 | AS24: =VLOOKUP(C24,'[2]5月汇总'!$C:$AE,26,0) -> 0 | AT24: =AS24+O24 -> 0 | AU24: =AT24/N24 -> 0 | AV24: =VLOOKUP(C24,[1]两年对比终版!$A:$N,14,0) -> 0 | AW24: =AT24-AV24 -> 0 | AX24: =(AT24-AV24)/AV24 -> #DIV/0! | AY24: =VLOOKUP(C24,'[2]5月汇总'!$C:$AE,27,0) -> 0 | AZ24: =AY24+T24 -> 0 | BA24: =AZ24/S24 -> 0 | BB24: =VLOOKUP(C24,[1]两年对比终版!$A:$W,17,0) -> 0 | BC24: =AZ24-BB24 -> 0 | BD24: =(AZ24-BB24)/BB24 -> #DIV/0! | BE24: =VLOOKUP(C24,'[2]5月汇总'!$C:$AE,28,0) -> 0 | BF24: =BE24+Y24 -> 0 | BG24: =BF24/X24 -> 0 | BH24: =VLOOKUP(C24,[1]两年对比终版!$A:$T,20,0) -> 0 | BI24: =(BF24-BH24)/BH24 -> #DIV/0! | BJ24: =VLOOKUP(C24,'[2]5月汇总'!$C:$AE,29,0) -> 0 | BK24: =BJ24+AD24 -> 0 | BL24: =BK24/AC24 -> 0 | BM24: =VLOOKUP(C24,[1]两年对比终版!$A:$W,23,0) -> 0 | BN24: =(BK24-BM24)/BM24 -> #DIV/0!
A25: 亚洲1合计 | D25: 1328 | E25: 438 | F25: 0.32981928 | G25: 1676 | H25: -2.826484 | I25: 31010 | J25: 8328.6704 | K25: 0.26858015 | L25: 29715.329 | M25: -2.5678359 | N25: 583 | O25: 158 | P25: 0.27101201 | Q25: 667 | R25: -3.221519 | S25: 12602.326 | T25: 5836.2923 | U25: 0.46311231 | V25: 13072.68 | W25: -1.2398947 | X25: 583 | Y25: 169 | Z25: 0.28987993 | AA25: 346 | AB25: -1.0473373 | AC25: 12602.326 | AD25: 5913.7692 | AE25: 0.46926013 | AF25: 6248.6129 | AG25: =(AD25-AF25)/AF25 -> -0.05358688 | AH25: =SUM(AH16:AH24) -> 328 | AI25: =AH25+E25 -> 766 | AJ25: =AI25/D25 -> 0.57680723 | AK25: =SUM(AK16:AK24) -> 740 | AL25: =AI25-AK25 -> 26 | AM25: =(AI25-AK25)/AK25 -> 0.035135135 | AN25: =SUM(AN16:AN24) -> 5401.92 | AO25: =AN25+J25 -> 13730.59 | AP25: =AO25/I25 -> 0.44277944 | AQ25: =SUM(AQ16:AQ24) -> 14019.692 | AR25: =(AO25-AQ25)/AQ25 -> -0.020621124 | AS25: =SUM(AS16:AS24) -> 110 | AT25: =AS25+O25 -> 268 | AU25: =AT25/N25 -> 0.45969125 | AV25: =SUM(AV16:AV24) -> 233 | AW25: =AT25-AV25 -> 35 | AX25: =(AT25-AV25)/AV25 -> 0.15021459 | AY25: =SUM(AY16:AY24) -> 2423.31 | AZ25: =AY25+T25 -> 8259.6023 | BA25: =AZ25/S25 -> 0.655403 | BB25: =SUM(BB16:BB24) -> 6173.1519 | BC25: =AZ25-BB25 -> 2086.4504 | BD25: =(AZ25-BB25)/BB25 -> 0.33798786 | BE25: =SUM(BE16:BE24) -> 100 | BF25: =BE25+Y25 -> 269 | BG25: =BF25/X25 -> 0.46140652 | BH25: =SUM(BH16:BH24) -> 94 | BI25: =(BF25-BH25)/BH25 -> 1.8617021 | BJ25: =SUM(BJ16:BJ24) -> 2310.56 | BK25: =BJ25+AD25 -> 8224.3292 | BL25: =BK25/AC25 -> 0.65260407 | BM25: =SUM(BM16:BM24) -> 4729.57 | BN25: =(BK25-BM25)/BM25 -> 0.73891692
A26: 20 | B26: C | C26: 越南-2 | D26: 235 | E26: 64 | F26: 0.27234043 | G26: 42 | H26: 0.34375 | I26: 1673.35 | J26: 437.632 | K26: 0.26153046 | L26: 319.10661 | M26: 0.27083345 | N26: 63 | O26: 12 | P26: 0.19047619 | Q26: 14 | R26: -0.16666667 | S26: 683 | T26: 65.701 | U26: 0.096194729 | V26: 117.34529 | W26: -0.78605029 | X26: 63 | Y26: 10 | Z26: 0.15873016 | AA26: 24 | AB26: -1.4 | AC26: 683 | AD26: 55.8172 | AE26: 0.081723572 | AF26: 196.15974 | AG26: =(AD26-AF26)/AF26 -> -0.71545028 | AH26: =VLOOKUP(C26,'[2]5月汇总'!$C:$AE,24,0) -> 30 | AI26: =AH26+E26 -> 94 | AJ26: =AI26/D26 -> 0.4 | AK26: =VLOOKUP(C26,[1]两年对比终版!$A:$C,3,0) -> 52 | AL26: =AI26-AK26 -> 42 | AM26: =(AI26-AK26)/AK26 -> 0.80769231 | AN26: =VLOOKUP(C26,'[2]5月汇总'!$C:$AA,25,0) -> 150 | AO26: =AN26+J26 -> 587.632 | AP26: =AO26/I26 -> 0.351171 | AQ26: =VLOOKUP(C26,[1]两年对比终版!$A:$W,6,0) -> 393.58625 | AR26: =(AO26-AQ26)/AQ26 -> 0.49301964 | AS26: =VLOOKUP(C26,'[2]5月汇总'!$C:$AE,26,0) -> 16 | AT26: =AS26+O26 -> 28 | AU26: =AT26/N26 -> 0.44444444 | AV26: =VLOOKUP(C26,[1]两年对比终版!$A:$N,14,0) -> 22 | AW26: =AT26-AV26 -> 6 | AX26: =(AT26-AV26)/AV26 -> 0.27272727 | AY26: =VLOOKUP(C26,'[2]5月汇总'!$C:$AE,27,0) -> 80 | AZ26: =AY26+T26 -> 145.701 | BA26: =AZ26/S26 -> 0.21332504 | BB26: =VLOOKUP(C26,[1]两年对比终版!$A:$W,17,0) -> 178.45729 | BC26: =AZ26-BB26 -> -32.756292 | BD26: =(AZ26-BB26)/BB26 -> -0.18355256 | BE26: =VLOOKUP(C26,'[2]5月汇总'!$C:$AE,28,0) -> 8 | BF26: =BE26+Y26 -> 18 | BG26: =BF26/X26 -> 0.28571429 | BH26: =VLOOKUP(C26,[1]两年对比终版!$A:$T,20,0) -> 29 | BI26: =(BF26-BH26)/BH26 -> -0.37931034 | BJ26: =VLOOKUP(C26,'[2]5月汇总'!$C:$AE,29,0) -> 57.237 | BK26: =BJ26+AD26 -> 113.0542 | BL26: =BK26/AC26 -> 0.16552592 | BM26: =VLOOKUP(C26,[1]两年对比终版!$A:$W,23,0) -> 228.72333 | BN26: =(BK26-BM26)/BM26 -> -0.50571637
A27: 21 | B27: B | C27: 印度公建 | D27: 66 | E27: 13 | F27: 0.1969697 | G27: 13 | H27: 0 | I27: 930 | J27: 260.053 | K27: 0.27962688 | L27: 386.93599 | M27: -0.48791203 | N27: 27 | O27: 6 | P27: 0.22222222 | Q27: 1 | R27: 0.83333333 | S27: 396.245 | T27: 68.5136 | U27: 0.17290717 | V27: 19.06 | W27: 0.72180706 | X27: 27 | Y27: 5 | Z27: 0.18518519 | AA27: 0 | AB27: 1 | AC27: 396.245 | AD27: 78.4854 | AE27: 0.19807291 | AF27: 0 | AG27: =(AD27-AF27)/AF27 -> #DIV/0! | AH27: =VLOOKUP(C27,'[2]5月汇总'!$C:$AE,24,0) -> 17 | AI27: =AH27+E27 -> 30 | AJ27: =AI27/D27 -> 0.45454545 | AK27: =VLOOKUP(C27,[1]两年对比终版!$A:$C,3,0) -> 23 | AL27: =AI27-AK27 -> 7 | AM27: =(AI27-AK27)/AK27 -> 0.30434783 | AN27: =VLOOKUP(C27,'[2]5月汇总'!$C:$AA,25,0) -> 166.6 | AO27: =AN27+J27 -> 426.653 | AP27: =AO27/I27 -> 0.45876667 | AQ27: =VLOOKUP(C27,[1]两年对比终版!$A:$W,6,0) -> 773.87896 | AR27: =(AO27-AQ27)/AQ27 -> -0.44868252 | AS27: =VLOOKUP(C27,'[2]5月汇总'!$C:$AE,26,0) -> 7 | AT27: =AS27+O27 -> 13 | AU27: =AT27/N27 -> 0.48148148 | AV27: =VLOOKUP(C27,[1]两年对比终版!$A:$N,14,0) -> 3 | AW27: =AT27-AV27 -> 10 | AX27: =(AT27-AV27)/AV27 -> 3.3333333 | AY27: =VLOOKUP(C27,'[2]5月汇总'!$C:$AE,27,0) -> 118.436 | AZ27: =AY27+T27 -> 186.9496 | BA27: =AZ27/S27 -> 0.47180305 | BB27: =VLOOKUP(C27,[1]两年对比终版!$A:$W,17,0) -> 44.012007 | BC27: =AZ27-BB27 -> 142.93759 | BD27: =(AZ27-BB27)/BB27 -> 3.2476954 | BE27: =VLOOKUP(C27,'[2]5月汇总'!$C:$AE,28,0) -> 11 | BF27: =BE27+Y27 -> 16 | BG27: =BF27/X27 -> 0.59259259 | BH27: =VLOOKUP(C27,[1]两年对比终版!$A:$T,20,0) -> 0 | BI27: =(BF27-BH27)/BH27 -> #DIV/0! | BJ27: =VLOOKUP(C27,'[2]5月汇总'!$C:$AE,29,0) -> 343.68219 | BK27: =BJ27+AD27 -> 422.16759 | BL27: =BK27/AC27 -> 1.0654206 | BM27: =VLOOKUP(C27,[1]两年对比终版!$A:$W,23,0) -> 0 | BN27: =(BK27-BM27)/BM27 -> #DIV/0!
A28: 22 | B28: D | C28: 巴基斯坦 | D28: 87 | E28: 20 | F28: 0.22988506 | G28: 0 | H28: 1 | I28: 688 | J28: 154.487 | K28: 0.22454506 | L28: 0 | M28: 1 | N28: 32 | O28: 4 | P28: 0.125 | Q28: 0 | R28: 1 | S28: 265 | T28: 23.2504 | U28: 0.087737358 | V28: 0 | W28: 1 | X28: 32 | Y28: 5 | Z28: 0.15625 | AA28: 0 | AB28: 1 | AC28: 265 | AD28: 37.6112 | AE28: 0.14192906 | AF28: 0 | AG28: =(AD28-AF28)/AF28 -> #DIV/0! | AH28: =VLOOKUP(C28,'[2]5月汇总'!$C:$AE,24,0) -> 13 | AI28: =AH28+E28 -> 33 | AJ28: =AI28/D28 -> 0.37931034 | AK28: =VLOOKUP(C28,[1]两年对比终版!$A:$C,3,0) -> 8 | AL28: =AI28-AK28 -> 25 | AM28: =(AI28-AK28)/AK28 -> 3.125 | AN28: =VLOOKUP(C28,'[2]5月汇总'!$C:$AA,25,0) -> 78.42 | AO28: =AN28+J28 -> 232.907 | AP28: =AO28/I28 -> 0.33852762 | AQ28: =VLOOKUP(C28,[1]两年对比终版!$A:$W,6,0) -> 74.024224 | AR28: =(AO28-AQ28)/AQ28 -> 2.1463619 | AS28: =VLOOKUP(C28,'[2]5月汇总'!$C:$AE,26,0) -> 4 | AT28: =AS28+O28 -> 8 | AU28: =AT28/N28 -> 0.25 | AV28: =VLOOKUP(C28,[1]两年对比终版!$A:$N,14,0) -> 2 | AW28: =AT28-AV28 -> 6 | AX28: =(AT28-AV28)/AV28 -> 3 | AY28: =VLOOKUP(C28,'[2]5月汇总'!$C:$AE,27,0) -> 44 | AZ28: =AY28+T28 -> 67.2504 | BA28: =AZ28/S28 -> 0.25377509 | BB28: =VLOOKUP(C28,[1]两年对比终版!$A:$W,17,0) -> 6.912768 | BC28: =AZ28-BB28 -> 60.337632 | BD28: =(AZ28-BB28)/BB28 -> 8.728433 | BE28: =VLOOKUP(C28,'[2]5月汇总'!$C:$AE,28,0) -> 5 | BF28: =BE28+Y28 -> 10 | BG28: =BF28/X28 -> 0.3125 | BH28: =VLOOKUP(C28,[1]两年对比终版!$A:$T,20,0) -> 0 | BI28: =(BF28-BH28)/BH28 -> #DIV/0! | BJ28: =VLOOKUP(C28,'[2]5月汇总'!$C:$AE,29,0) -> 51.98 | BK28: =BJ28+AD28 -> 89.5912 | BL28: =BK28/AC28 -> 0.33808 | BM28: =VLOOKUP(C28,[1]两年对比终版!$A:$W,23,0) -> 0 | BN28: =(BK28-BM28)/BM28 -> #DIV/0!
A29: 23 | B29: B | C29: 孟加拉-1 | D29: 238 | E29: 41 | F29: 0.17226891 | G29: 84 | H29: -1.0487805 | I29: 1768.9 | J29: 430.345 | K29: 0.24328396 | L29: 732.27569 | M29: -0.70160148 | N29: 73 | O29: 15 | P29: 0.20547945 | Q29: 16 | R29: -0.066666667 | S29: 722 | T29: 122.238 | U29: 0.16930471 | V29: 135.72362 | W29: -0.11032267 | X29: 73 | Y29: 14 | Z29: 0.19178082 | AA29: 12 | AB29: 0.14285714 | AC29: 722 | AD29: 114.248 | AE29: 0.15823823 | AF29: 104.07321 | AG29: =(AD29-AF29)/AF29 -> 0.097765729 | AH29: =VLOOKUP(C29,'[2]5月汇总'!$C:$AE,24,0) -> 65 | AI29: =AH29+E29 -> 106 | AJ29: =AI29/D29 -> 0.44537815 | AK29: =VLOOKUP(C29,[1]两年对比终版!$A:$C,3,0) -> 128 | AL29: =AI29-AK29 -> -22 | AM29: =(AI29-AK29)/AK29 -> -0.171875 | AN29: =VLOOKUP(C29,'[2]5月汇总'!$C:$AA,25,0) -> 279 | AO29: =AN29+J29 -> 709.345 | AP29: =AO29/I29 -> 0.4010091 | AQ29: =VLOOKUP(C29,[1]两年对比终版!$A:$W,6,0) -> 1268.9125 | AR29: =(AO29-AQ29)/AQ29 -> -0.44098193 | AS29: =VLOOKUP(C29,'[2]5月汇总'!$C:$AE,26,0) -> 15 | AT29: =AS29+O29 -> 30 | AU29: =AT29/N29 -> 0.4109589 | AV29: =VLOOKUP(C29,[1]两年对比终版!$A:$N,14,0) -> 27 | AW29: =AT29-AV29 -> 3 | AX29: =(AT29-AV29)/AV29 -> 0.11111111 | AY29: =VLOOKUP(C29,'[2]5月汇总'!$C:$AE,27,0) -> 127.32 | AZ29: =AY29+T29 -> 249.558 | BA29: =AZ29/S29 -> 0.3456482 | BB29: =VLOOKUP(C29,[1]两年对比终版!$A:$W,17,0) -> 224.14553 | BC29: =AZ29-BB29 -> 25.412467 | BD29: =(AZ29-BB29)/BB29 -> 0.11337485 | BE29: =VLOOKUP(C29,'[2]5月汇总'!$C:$AE,28,0) -> 11 | BF29: =BE29+Y29 -> 25 | BG29: =BF29/X29 -> 0.34246575 | BH29: =VLOOKUP(C29,[1]两年对比终版!$A:$T,20,0) -> 20 | BI29: =(BF29-BH29)/BH29 -> 0.25 | BJ29: =VLOOKUP(C29,'[2]5月汇总'!$C:$AE,29,0) -> 93.87 | BK29: =BJ29+AD29 -> 208.118 | BL29: =BK29/AC29 -> 0.28825208 | BM29: =VLOOKUP(C29,[1]两年对比终版!$A:$W,23,0) -> 167.86765 | BN29: =(BK29-BM29)/BM29 -> 0.23977429
A30: 24 | B30: C | C30: 澳大利亚 | D30: 136 | E30: 23 | F30: 0.16911765 | G30: 38 | H30: -0.65217391 | I30: 964 | J30: 320.911 | K30: 0.33289523 | L30: 580.17456 | M30: -0.80789864 | N30: 32 | O30: 8 | P30: 0.25 | Q30: 2 | R30: 0.75 | S30: 380 | T30: 88.3023 | U30: 0.23237447 | V30: 29.534539 | W30: 0.66552922 | X30: 32 | Y30: 3 | Z30: 0.09375 | AA30: 8 | AB30: -1.6666667 | AC30: 380 | AD30: 53.7101 | AE30: 0.14134237 | AF30: 165.75891 | AG30: =(AD30-AF30)/AF30 -> -0.67597459 | AH30: =VLOOKUP(C30,'[2]5月汇总'!$C:$AE,24,0) -> 13 | AI30: =AH30+E30 -> 36 | AJ30: =AI30/D30 -> 0.26470588 | AK30: =VLOOKUP(C30,[1]两年对比终版!$A:$C,3,0) -> 39 | AL30: =AI30-AK30 -> -3 | AM30: =(AI30-AK30)/AK30 -> -0.076923077 | AN30: =VLOOKUP(C30,'[2]5月汇总'!$C:$AA,25,0) -> 180 | AO30: =AN30+J30 -> 500.911 | AP30: =AO30/I30 -> 0.51961722 | AQ30: =VLOOKUP(C30,[1]两年对比终版!$A:$W,6,0) -> 592.24855 | AR30: =(AO30-AQ30)/AQ30 -> -0.15422166 | AS30: =VLOOKUP(C30,'[2]5月汇总'!$C:$AE,26,0) -> 7 | AT30: =AS30+O30 -> 15 | AU30: =AT30/N30 -> 0.46875 | AV30: =VLOOKUP(C30,[1]两年对比终版!$A:$N,14,0) -> 2 | AW30: =AT30-AV30 -> 13 | AX30: =(AT30-AV30)/AV30 -> 6.5 | AY30: =VLOOKUP(C30,'[2]5月汇总'!$C:$AE,27,0) -> 70 | AZ30: =AY30+T30 -> 158.3023 | BA30: =AZ30/S30 -> 0.416585 | BB30: =VLOOKUP(C30,[1]两年对比终版!$A:$W,17,0) -> 29.534539 | BC30: =AZ30-BB30 -> 128.76776 | BD30: =(AZ30-BB30)/BB30 -> 4.3599042 | BE30: =VLOOKUP(C30,'[2]5月汇总'!$C:$AE,28,0) -> 8 | BF30: =BE30+Y30 -> 11 | BG30: =BF30/X30 -> 0.34375 | BH30: =VLOOKUP(C30,[1]两年对比终版!$A:$T,20,0) -> 9 | BI30: =(BF30-BH30)/BH30 -> 0.22222222 | BJ30: =VLOOKUP(C30,'[2]5月汇总'!$C:$AE,29,0) -> 64.4 | BK30: =BJ30+AD30 -> 118.1101 | BL30: =BK30/AC30 -> 0.31081605 | BM30: =VLOOKUP(C30,[1]两年对比终版!$A:$W,23,0) -> 179.53971 | BN30: =(BK30-BM30)/BM30 -> -0.34215055
A31: 25 | B31: C | C31: 菲律宾 | D31: 69 | E31: 26 | F31: 0.37681159 | G31: 0 | H31: 1 | I31: 710 | J31: 214.36 | K31: 0.30191549 | L31: 0 | M31: 1 | N31: 27 | O31: 0 | P31: 0 | Q31: 0 | R31: #DIV/0! | S31: 350 | T31: 0 | U31: 0 | V31: 0 | W31: #DIV/0! | X31: 27 | Y31: 0 | Z31: 0 | AA31: 0 | AB31: #DIV/0! | AC31: 350 | AD31: 0 | AE31: 0 | AF31: 0 | AG31: =(AD31-AF31)/AF31 -> #DIV/0! | AH31: =VLOOKUP(C31,'[2]5月汇总'!$C:$AE,24,0) -> 0 | AI31: =AH31+E31 -> 26 | AJ31: =AI31/D31 -> 0.37681159 | AK31: =VLOOKUP(C31,[1]两年对比终版!$A:$C,3,0) -> 0 | AL31: =AI31-AK31 -> 26 | AM31: =(AI31-AK31)/AK31 -> #DIV/0! | AN31: =VLOOKUP(C31,'[2]5月汇总'!$C:$AA,25,0) -> 0 | AO31: =AN31+J31 -> 214.36 | AP31: =AO31/I31 -> 0.30191549 | AQ31: =VLOOKUP(C31,[1]两年对比终版!$A:$W,6,0) -> 0 | AS31: =VLOOKUP(C31,'[2]5月汇总'!$C:$AE,26,0) -> 0 | AT31: =AS31+O31 -> 0 | AU31: =AT31/N31 -> 0 | AV31: =VLOOKUP(C31,[1]两年对比终版!$A:$N,14,0) -> 0 | AW31: =AT31-AV31 -> 0 | AY31: =VLOOKUP(C31,'[2]5月汇总'!$C:$AE,27,0) -> 30 | AZ31: =AY31+T31 -> 30 | BA31: =AZ31/S31 -> 0.085714286 | BB31: =VLOOKUP(C31,[1]两年对比终版!$A:$W,17,0) -> 0 | BC31: =AZ31-BB31 -> 30 | BE31: =VLOOKUP(C31,'[2]5月汇总'!$C:$AE,28,0) -> 0 | BF31: =BE31+Y31 -> 0 | BG31: =BF31/X31 -> 0 | BH31: =VLOOKUP(C31,[1]两年对比终版!$A:$T,20,0) -> 0 | BJ31: =VLOOKUP(C31,'[2]5月汇总'!$C:$AE,29,0) -> 15 | BK31: =BJ31+AD31 -> 15 | BL31: =BK31/AC31 -> 0.042857143 | BM31: =VLOOKUP(C31,[1]两年对比终版!$A:$W,23,0) -> 0
A32: 26 | B32: C | C32: 印尼-1 | D32: 263 | E32: 48 | F32: 0.18250951 | G32: 35 | H32: 0.27083333 | I32: 1640 | J32: 499.416 | K32: 0.30452195 | L32: 300.42334 | M32: 0.39845071 | N32: 42 | O32: 8 | P32: 0.19047619 | Q32: 1 | R32: 0.875 | S32: 400 | T32: 77.5997 | U32: 0.19399925 | V32: 7.43 | W32: 0.90425221 | X32: 42 | Y32: 8 | Z32: 0.19047619 | AA32: 1 | AB32: 0.875 | AC32: 400 | AD32: 77.5997 | AE32: 0.19399925 | AF32: 7.43 | AG32: =(AD32-AF32)/AF32 -> 9.444105 | AH32: =VLOOKUP(C32,'[2]5月汇总'!$C:$AE,24,0) -> 0 | AI32: =AH32+E32 -> 48 | AJ32: =AI32/D32 -> 0.18250951 | AK32: =VLOOKUP(C32,[1]两年对比终版!$A:$C,3,0) -> 97 | AL32: =AI32-AK32 -> -49 | AM32: =(AI32-AK32)/AK32 -> -0.50515464 | AN32: =VLOOKUP(C32,'[2]5月汇总'!$C:$AA,25,0) -> 0 | AO32: =AN32+J32 -> 499.416 | AP32: =AO32/I32 -> 0.30452195 | AQ32: =VLOOKUP(C32,[1]两年对比终版!$A:$W,6,0) -> 1049.8087 | AR32: =(AO32-AQ32)/AQ32 -> -0.52427902 | AS32: =VLOOKUP(C32,'[2]5月汇总'!$C:$AE,26,0) -> 0 | AT32: =AS32+O32 -> 8 | AU32: =AT32/N32 -> 0.19047619 | AV32: =VLOOKUP(C32,[1]两年对比终版!$A:$N,14,0) -> 1 | AW32: =AT32-AV32 -> 7 | AX32: =(AT32-AV32)/AV32 -> 7 | AY32: =VLOOKUP(C32,'[2]5月汇总'!$C:$AE,27,0) -> 100 | AZ32: =AY32+T32 -> 177.5997 | BA32: =AZ32/S32 -> 0.44399925 | BB32: =VLOOKUP(C32,[1]两年对比终版!$A:$W,17,0) -> 7.43 | BC32: =AZ32-BB32 -> 170.1697 | BD32: =(AZ32-BB32)/BB32 -> 22.903055 | BE32: =VLOOKUP(C32,'[2]5月汇总'!$C:$AE,28,0) -> 0 | BF32: =BE32+Y32 -> 8 | BG32: =BF32/X32 -> 0.19047619 | BH32: =VLOOKUP(C32,[1]两年对比终版!$A:$T,20,0) -> 1 | BI32: =(BF32-BH32)/BH32 -> 7 | BJ32: =VLOOKUP(C32,'[2]5月汇总'!$C:$AE,29,0) -> 0 | BK32: =BJ32+AD32 -> 77.5997 | BL32: =BK32/AC32 -> 0.19399925 | BM32: =VLOOKUP(C32,[1]两年对比终版!$A:$W,23,0) -> 7.43 | BN32: =(BK32-BM32)/BM32 -> 9.444105
A33: 27 | B33: B | C33: 越南-1（工厂） | D33: 148 | E33: 23 | F33: 0.15540541 | G33: 9 | H33: 0.60869565 | I33: 1470 | J33: 311.155 | K33: 0.21167007 | L33: 98.864647 | M33: 0.6822656 | N33: 55 | O33: 10 | P33: 0.18181818 | Q33: 0 | R33: 1 | S33: 600 | T33: 74.2168 | U33: 0.12369467 | V33: 0 | W33: 1 | X33: 55 | Y33: 4 | Z33: 0.072727273 | AA33: 0 | AB33: 1 | AC33: 600 | AD33: 24.6438 | AE33: 0.041073 | AF33: 0 | AG33: =(AD33-AF33)/AF33 -> #DIV/0! | AH33: =VLOOKUP(C33,'[2]5月汇总'!$C:$AE,24,0) -> 22 | AI33: =AH33+E33 -> 45 | AJ33: =AI33/D33 -> 0.30405405 | AK33: =VLOOKUP(C33,[1]两年对比终版!$A:$C,3,0) -> 10 | AL33: =AI33-AK33 -> 35 | AM33: =(AI33-AK33)/AK33 -> 3.5 | AN33: =VLOOKUP(C33,'[2]5月汇总'!$C:$AA,25,0) -> 250 | AO33: =AN33+J33 -> 561.155 | AP33: =AO33/I33 -> 0.3817381 | AQ33: =VLOOKUP(C33,[1]两年对比终版!$A:$W,6,0) -> 106.42549 | AR33: =(AO33-AQ33)/AQ33 -> 4.2727501 | AS33: =VLOOKUP(C33,'[2]5月汇总'!$C:$AE,26,0) -> 2 | AT33: =AS33+O33 -> 12 | AU33: =AT33/N33 -> 0.21818182 | AV33: =VLOOKUP(C33,[1]两年对比终版!$A:$N,14,0) -> 1 | AW33: =AT33-AV33 -> 11 | AX33: =(AT33-AV33)/AV33 -> 11 | AY33: =VLOOKUP(C33,'[2]5月汇总'!$C:$AE,27,0) -> 13.8 | AZ33: =AY33+T33 -> 88.0168 | BA33: =AZ33/S33 -> 0.14669467 | BB33: =VLOOKUP(C33,[1]两年对比终版!$A:$W,17,0) -> 7.56084 | BC33: =AZ33-BB33 -> 80.45596 | BD33: =(AZ33-BB33)/BB33 -> 10.64114 | BE33: =VLOOKUP(C33,'[2]5月汇总'!$C:$AE,28,0) -> 7 | BF33: =BE33+Y33 -> 11 | BG33: =BF33/X33 -> 0.2 | BH33: =VLOOKUP(C33,[1]两年对比终版!$A:$T,20,0) -> 0 | BI33: =(BF33-BH33)/BH33 -> #DIV/0! | BJ33: =VLOOKUP(C33,'[2]5月汇总'!$C:$AE,29,0) -> 49.5 | BK33: =BJ33+AD33 -> 74.1438 | BL33: =BK33/AC33 -> 0.123573 | BM33: =VLOOKUP(C33,[1]两年对比终版!$A:$W,23,0) -> 0 | BN33: =(BK33-BM33)/BM33 -> #DIV/0!
A34: 28 | B34: A | C34: 印度私营 | D34: 246 | E34: 63 | F34: 0.25609756 | G34: 36 | H34: 0.42857143 | I34: 2934 | J34: 788.161 | K34: 0.2686302 | L34: 555.16878 | M34: 0.29561501 | N34: 81 | O34: 23 | P34: 0.28395062 | Q34: 12 | R34: 0.47826087 | S34: 1600 | T34: 269.24 | U34: 0.168275 | V34: 275.38668 | W34: -0.022829743 | X34: 81 | Y34: 6 | Z34: 0.074074074 | AA34: 14 | AB34: -1.3333333 | AC34: 1600 | AD34: 78.962 | AE34: 0.04935125 | AF34: 254.07979 | AG34: =(AD34-AF34)/AF34 -> -0.6892236 | AH34: =VLOOKUP(C34,'[2]5月汇总'!$C:$AE,24,0) -> 38 | AI34: =AH34+E34 -> 101 | AJ34: =AI34/D34 -> 0.41056911 | AK34: =VLOOKUP(C34,[1]两年对比终版!$A:$C,3,0) -> 110 | AL34: =AI34-AK34 -> -9 | AM34: =(AI34-AK34)/AK34 -> -0.081818182 | AN34: =VLOOKUP(C34,'[2]5月汇总'!$C:$AA,25,0) -> 430 | AO34: =AN34+J34 -> 1218.161 | AP34: =AO34/I34 -> 0.4151878 | AQ34: =VLOOKUP(C34,[1]两年对比终版!$A:$W,6,0) -> 1592.6828 | AR34: =(AO34-AQ34)/AQ34 -> -0.23515152 | AS34: =VLOOKUP(C34,'[2]5月汇总'!$C:$AE,26,0) -> 26 | AT34: =AS34+O34 -> 49 | AU34: =AT34/N34 -> 0.60493827 | AV34: =VLOOKUP(C34,[1]两年对比终版!$A:$N,14,0) -> 30 | AW34: =AT34-AV34 -> 19 | AX34: =(AT34-AV34)/AV34 -> 0.63333333 | AY34: =VLOOKUP(C34,'[2]5月汇总'!$C:$AE,27,0) -> 276 | AZ34: =AY34+T34 -> 545.24 | BA34: =AZ34/S34 -> 0.340775 | BB34: =VLOOKUP(C34,[1]两年对比终版!$A:$W,17,0) -> 723.49246 | BC34: =AZ34-BB34 -> -178.25246 | BD34: =(AZ34-BB34)/BB34 -> -0.24637778 | BE34: =VLOOKUP(C34,'[2]5月汇总'!$C:$AE,28,0) -> 21 | BF34: =BE34+Y34 -> 27 | BG34: =BF34/X34 -> 0.33333333 | BH34: =VLOOKUP(C34,[1]两年对比终版!$A:$T,20,0) -> 19 | BI34: =(BF34-BH34)/BH34 -> 0.42105263 | BJ34: =VLOOKUP(C34,'[2]5月汇总'!$C:$AE,29,0) -> 205 | BK34: =BJ34+AD34 -> 283.962 | BL34: =BK34/AC34 -> 0.17747625 | BM34: =VLOOKUP(C34,[1]两年对比终版!$A:$W,23,0) -> 329.72867 | BN34: =(BK34-BM34)/BM34 -> -0.13880101
A35: 29 | B35: C | C35: 菲律宾-2 | D35: 85 | E35: 29 | F35: 0.34117647 | G35: 0 | H35: 1 | I35: 650 | J35: 214.149 | K35: 0.32946 | L35: 0 | M35: 1 | N35: 27 | O35: 0 | P35: 0 | Q35: 0 | R35: #DIV/0! | S35: 350 | T35: 0 | U35: 0 | V35: 0 | W35: #DIV/0! | X35: 27 | Y35: 0 | Z35: 0 | AA35: 0 | AB35: #DIV/0! | AC35: 350 | AD35: 0 | AE35: 0 | AF35: 0 | AG35: =(AD35-AF35)/AF35 -> #DIV/0! | AH35: =VLOOKUP(C35,'[2]5月汇总'!$C:$AE,24,0) -> 41 | AI35: =AH35+E35 -> 70 | AJ35: =AI35/D35 -> 0.82352941 | AK35: =VLOOKUP(C35,[1]两年对比终版!$A:$C,3,0) -> 0 | AL35: =AI35-AK35 -> 70 | AM35: =(AI35-AK35)/AK35 -> #DIV/0! | AN35: =VLOOKUP(C35,'[2]5月汇总'!$C:$AA,25,0) -> 235 | AO35: =AN35+J35 -> 449.149 | AP35: =AO35/I35 -> 0.69099846 | AQ35: =VLOOKUP(C35,[1]两年对比终版!$A:$W,6,0) -> 0 | AS35: =VLOOKUP(C35,'[2]5月汇总'!$C:$AE,26,0) -> 5 | AT35: =AS35+O35 -> 5 | AU35: =AT35/N35 -> 0.18518519 | AV35: =VLOOKUP(C35,[1]两年对比终版!$A:$N,14,0) -> 0 | AW35: =AT35-AV35 -> 5 | AY35: =VLOOKUP(C35,'[2]5月汇总'!$C:$AE,27,0) -> 50 | AZ35: =AY35+T35 -> 50 | BA35: =AZ35/S35 -> 0.14285714 | BB35: =VLOOKUP(C35,[1]两年对比终版!$A:$W,17,0) -> 0 | BC35: =AZ35-BB35 -> 50 | BE35: =VLOOKUP(C35,'[2]5月汇总'!$C:$AE,28,0) -> 11 | BF35: =BE35+Y35 -> 11 | BG35: =BF35/X35 -> 0.40740741 | BH35: =VLOOKUP(C35,[1]两年对比终版!$A:$T,20,0) -> 0 | BJ35: =VLOOKUP(C35,'[2]5月汇总'!$C:$AE,29,0) -> 60 | BK35: =BJ35+AD35 -> 60 | BL35: =BK35/AC35 -> 0.17142857 | BM35: =VLOOKUP(C35,[1]两年对比终版!$A:$W,23,0) -> 0
A36: 30 | B36: C | C36: 印尼-2 | D36: 250 | E36: 51 | F36: 0.204 | G36: 0 | H36: 1 | I36: 1700 | J36: 530.632 | K36: 0.31213647 | L36: 0 | M36: 1 | N36: 42 | O36: 0 | P36: 0 | Q36: 0 | R36: #DIV/0! | S36: 400 | T36: 0 | U36: 0 | V36: 0 | W36: #DIV/0! | X36: 42 | Y36: 0 | Z36: 0 | AA36: 0 | AB36: #DIV/0! | AC36: 400 | AD36: 0 | AE36: 0 | AF36: 0 | AG36: =(AD36-AF36)/AF36 -> #DIV/0! | AH36: =VLOOKUP(C36,'[2]5月汇总'!$C:$AE,24,0) -> 0 | AI36: =AH36+E36 -> 51 | AJ36: =AI36/D36 -> 0.204 | AK36: =VLOOKUP(C36,[1]两年对比终版!$A:$C,3,0) -> 0 | AL36: =AI36-AK36 -> 51 | AM36: =(AI36-AK36)/AK36 -> #DIV/0! | AN36: =VLOOKUP(C36,'[2]5月汇总'!$C:$AA,25,0) -> 0 | AO36: =AN36+J36 -> 530.632 | AP36: =AO36/I36 -> 0.31213647 | AQ36: =VLOOKUP(C36,[1]两年对比终版!$A:$W,6,0) -> 0 | AS36: =VLOOKUP(C36,'[2]5月汇总'!$C:$AE,26,0) -> 0 | AT36: =AS36+O36 -> 0 | AU36: =AT36/N36 -> 0 | AV36: =VLOOKUP(C36,[1]两年对比终版!$A:$N,14,0) -> 0 | AW36: =AT36-AV36 -> 0 | AY36: =VLOOKUP(C36,'[2]5月汇总'!$C:$AE,27,0) -> 0 | AZ36: =AY36+T36 -> 0 | BA36: =AZ36/S36 -> 0 | BB36: =VLOOKUP(C36,[1]两年对比终版!$A:$W,17,0) -> 0 | BC36: =AZ36-BB36 -> 0 | BE36: =VLOOKUP(C36,'[2]5月汇总'!$C:$AE,28,0) -> 0 | BF36: =BE36+Y36 -> 0 | BG36: =BF36/X36 -> 0 | BH36: =VLOOKUP(C36,[1]两年对比终版!$A:$T,20,0) -> 0 | BJ36: =VLOOKUP(C36,'[2]5月汇总'!$C:$AE,29,0) -> 170 | BK36: =BJ36+AD36 -> 170 | BL36: =BK36/AC36 -> 0.425 | BM36: =VLOOKUP(C36,[1]两年对比终版!$A:$W,23,0) -> 0
A37: 亚洲2合计 | D37: 1823 | E37: 401 | F37: 0.21996709 | G37: 257 | H37: 0.35910224 | I37: 15128.25 | J37: 4161.301 | K37: 0.27506823 | L37: 2972.9496 | M37: 0.28557208 | N37: 501 | O37: 86 | P37: 0.17165669 | Q37: 46 | R37: 0.46511628 | S37: 6146.245 | T37: 789.0618 | U37: 0.12838112 | V37: 584.48013 | W37: 0.25927205 | X37: 501 | Y37: 55 | Z37: 0.10978044 | AA37: 59 | AB37: -0.072727273 | AC37: 6146.245 | AD37: 521.0774 | AE37: 0.084779796 | AF37: 727.50165 | AG37: =(AD37-AF37)/AF37 -> -0.28374403 | AH37: =SUM(AH26:AH36) -> 239 | AI37: =AH37+E37 -> 640 | AJ37: =AI37/D37 -> 0.35106967 | AK37: =SUM(AK26:AK36) -> 467 | AL37: =AI37-AK37 -> 173 | AM37: =(AI37-AK37)/AK37 -> 0.37044968 | AN37: =SUM(AN26:AN36) -> 1769.02 | AO37: =AN37+J37 -> 5930.321 | AP37: =AO37/I37 -> 0.39200311 | AQ37: =SUM(AQ26:AQ36) -> 5851.5674 | AR37: =(AO37-AQ37)/AQ37 -> 0.013458551 | AS37: =SUM(AS26:AS36) -> 82 | AT37: =AS37+O37 -> 168 | AU37: =AT37/N37 -> 0.33532934 | AV37: =SUM(AV26:AV36) -> 88 | AW37: =AT37-AV37 -> 80 | AX37: =(AT37-AV37)/AV37 -> 0.90909091 | AY37: =SUM(AY26:AY36) -> 909.556 | AZ37: =AY37+T37 -> 1698.6178 | BA37: =AZ37/S37 -> 0.27636676 | BB37: =SUM(BB26:BB36) -> 1221.5454 | BC37: =AZ37-BB37 -> 477.07236 | BD37: =(AZ37-BB37)/BB37 -> 0.39054819 | BE37: =SUM(BE26:BE36) -> 82 | BF37: =BE37+Y37 -> 137 | BG37: =BF37/X37 -> 0.27345309 | BH37: =SUM(BH26:BH36) -> 78 | BI37: =(BF37-BH37)/BH37 -> 0.75641026 | BJ37: =SUM(BJ26:BJ36) -> 1110.6692 | BK37: =BJ37+AD37 -> 1631.7466 | BL37: =BK37/AC37 -> 0.26548675 | BM37: =SUM(BM26:BM36) -> 913.28937 | BN37: =(BK37-BM37)/BM37 -> 0.78666986
A38: 31 | B38: B | C38: 阿联酋-2 | D38: 63 | E38: 43 | F38: 0.68253968 | G38: 40 | H38: 0.069767442 | I38: 2450 | J38: 490.787 | K38: 0.20032122 | L38: 1027.7122 | M38: -1.0940087 | N38: 20 | O38: 5 | P38: 0.25 | Q38: 25 | R38: -4 | S38: 900 | T38: 55.9393 | U38: 0.062154778 | V38: 891.86092 | W38: -14.943369 | X38: 20 | Y38: 1 | Z38: 0.05 | AA38: 16 | AB38: -15 | AC38: 900 | AD38: 26.6761 | AE38: 0.029640111 | AF38: 539.00555 | AG38: =(AD38-AF38)/AF38 -> -0.95050867 | AH38: =VLOOKUP(C38,'[2]5月汇总'!$C:$AE,24,0) -> 100 | AI38: =AH38+E38 -> 143 | AJ38: =AI38/D38 -> 2.2698413 | AK38: =VLOOKUP(C38,[1]两年对比终版!$A:$C,3,0) -> 42 | AL38: =AI38-AK38 -> 101 | AM38: =(AI38-AK38)/AK38 -> 2.4047619 | AN38: =VLOOKUP(C38,'[2]5月汇总'!$C:$AE,25,0) -> 535 | AO38: =AN38+J38 -> 1025.787 | AP38: =AO38/I38 -> 0.41868857 | AQ38: =VLOOKUP(C38,[1]两年对比终版!$A:$W,6,0) -> 1049.7856 | AR38: =(AO38-AQ38)/AQ38 -> -0.022860447 | AS38: =VLOOKUP(C38,'[2]5月汇总'!$C:$AE,26,0) -> 30 | AT38: =AS38+O38 -> 35 | AU38: =AT38/N38 -> 1.75 | AV38: =VLOOKUP(C38,[1]两年对比终版!$A:$N,14,0) -> 27 | AW38: =AT38-AV38 -> 8 | AX38: =(AT38-AV38)/AV38 -> 0.2962963 | AY38: =VLOOKUP(C38,'[2]5月汇总'!$C:$AE,27,0) -> 315 | AZ38: =AY38+T38 -> 370.9393 | BB38: =VLOOKUP(C38,[1]两年对比终版!$A:$W,17,0) -> 913.93426 | BC38: =AZ38-BB38 -> -542.99496 | BD38: =(AZ38-BB38)/BB38 -> -0.59412912 | BE38: =VLOOKUP(C38,'[2]5月汇总'!$C:$AE,28,0) -> 30 | BF38: =BE38+Y38 -> 31 | BG38: =BF38/X38 -> 1.55 | BH38: =VLOOKUP(C38,[1]两年对比终版!$A:$T,20,0) -> 26 | BI38: =(BF38-BH38)/BH38 -> 0.19230769 | BJ38: =VLOOKUP(C38,'[2]5月汇总'!$C:$AE,29,0) -> 315 | BK38: =BJ38+AD38 -> 341.6761 | BL38: =BK38/AC38 -> 0.37964011 | BM38: =VLOOKUP(C38,[1]两年对比终版!$A:$W,23,0) -> 895.74992 | BN38: =(BK38-BM38)/BM38 -> -0.6185586
AS39: =AS47+AS38 -> 48 | AT39: =AT47+AT38 -> 53 | AV39: =AV47+AV38 -> 27 | AW39: =AW47+AW38 -> 26 | AX39: =(AT39-AV39)/AV39 -> 0.96296296 | AY39: =AY47+AY38 -> 585 | AZ39: =AZ47+AZ38 -> 640.9393 | BB39: =BB38+BB47 -> 913.93426 | BC39: =BC38+BC47 -> -272.99496 | BD39: =(AZ39-BB39)/BB39 -> -0.29870306 | BE39: =BE38+BE47 -> 48 | BF39: =BF38+BF47 -> 49 | BH39: =BH38+BH47 -> 26 | BJ39: =BJ38+BJ47 -> 585 | BK39: =BK38+BK47 -> 611.6761 | BM39: =BM38+BM47 -> 895.74992 | BN39: =(BK39-BM39)/BM39 -> -0.31713519
A40: 32 | B40: A | C40: 沙特工厂 | D40: 733 | E40: 213 | F40: 0.29058663 | G40: 288 | H40: -0.35211268 | I40: 6860 | J40: 1838.18 | K40: 0.26795627 | L40: 2858.819 | M40: -0.55524433 | N40: 200 | O40: 29 | P40: 0.145 | Q40: 56 | R40: -0.93103448 | S40: 2360 | T40: 257.589 | U40: 0.10914788 | V40: 513.03622 | W40: -0.99168527 | X40: 200 | Y40: 29 | Z40: 0.145 | AA40: 60 | AB40: -1.0689655 | AC40: 2360 | AD40: 257.589 | AE40: 0.10914788 | AF40: 501.76314 | AG40: =(AD40-AF40)/AF40 -> -0.48663228 | AH40: =VLOOKUP(C40,'[2]5月汇总'!$C:$AE,24,0) -> 129 | AI40: =AH40+E40 -> 342 | AJ40: =AI40/D40 -> 0.46657572 | AK40: =VLOOKUP(C40,[1]两年对比终版!$A:$W,3,0) -> 860 | AL40: =AI40-AK40 -> -518 | AM40: =(AI40-AK40)/AK40 -> -0.60232558 | AN40: =VLOOKUP(C40,'[2]5月汇总'!$C:$AE,25,0) -> 1030 | AO40: =AN40+J40 -> 2868.18 | AP40: =AO40/I40 -> 0.41810204 | AQ40: =VLOOKUP(C40,[1]两年对比终版!$A:$W,6,0) -> 7680.8761 | AR40: =(AO40-AQ40)/AQ40 -> -0.62658166 | AS40: =VLOOKUP(C40,'[2]5月汇总'!$C:$AE,26,0) -> 90 | AT40: =AS40+O40 -> 119 | AU40: =AT40/N40 -> 0.595 | AV40: =VLOOKUP(C40,[1]两年对比终版!$A:$N,14,0) -> 115 | AW40: =AT40-AV40 -> 4 | AX40: =(AT40-AV40)/AV40 -> 0.034782609 | AY40: =VLOOKUP(C40,'[2]5月汇总'!$C:$AE,27,0) -> 720 | AZ40: =AY40+T40 -> 977.589 | BA40: =AZ40/S40 -> 0.41423263 | BB40: =VLOOKUP(C40,[1]两年对比终版!$A:$W,17,0) -> 999.50571 | BC40: =AZ40-BB40 -> -21.916706 | BD40: =(AZ40-BB40)/BB40 -> -0.021927545 | BE40: =VLOOKUP(C40,'[2]5月汇总'!$C:$AE,28,0) -> 70 | BF40: =BE40+Y40 -> 99 | BG40: =BF40/X40 -> 0.495 | BH40: =VLOOKUP(C40,[1]两年对比终版!$A:$T,20,0) -> 132 | BI40: =(BF40-BH40)/BH40 -> -0.25 | BJ40: =VLOOKUP(C40,'[2]5月汇总'!$C:$AE,29,0) -> 480 | BK40: =BJ40+AD40 -> 737.589 | BL40: =BK40/AC40 -> 0.31253771 | BM40: =VLOOKUP(C40,[1]两年对比终版!$A:$W,23,0) -> 1132.2966 | BN40: =(BK40-BM40)/BM40 -> -0.34859028
...

Sheet 上半年单月明细
A1: 2026年国际市场运营系统上半年预计签排发数量
A2: 报表日期： | C2: 2026-04-28
A3: 序号 | B3: 模块类型 | C3: 模块 | D3: 1-4月新签梯量 | I3: 1-4月新签金额 | N3: 1-4月排产台 | S3: 1-4月排产额 | X3: 1-4月发货台 | AC3: 1-4月发货额 | AH3: 预计5月签单 | AR3: 预计5月排产 | BB3: 预计5月发货
D4: 指标 | E4: 完成 | F4: 完成比 | G4: 去年同期 | H4: 增长比 | I4: 指标 | J4: 完成 | K4: 完成比 | L4: 去年同期 | M4: 增长比 | N4: 指标 | O4: 完成 | P4: 完成比 | Q4: 去年同期 | R4: 增长比 | S4: 指标 | T4: 完成 | U4: 完成比 | V4: 去年同期 | W4: 增长比 | X4: 指标 | Y4: 完成 | Z4: 完成比 | AA4: 去年同期 | AB4: 增长比 | AC4: 指标 | AD4: 完成 | AE4: 完成比 | AF4: 去年同期 | AG4: 增长比 | AH4: 5月台数 | AI4: 1-5月台数合计 | AJ4: 完成比 | AK4: 去年同期 | AL4: 增长比 | AM4: 5月合同额 | AN4: 1-5月合同额合计 | AO4: 完成比 | AP4: 去年同期 | AQ4: 增长比 | AR4: 5月台数 | AS4: 1-5月台数合计 | AT4: 完成比 | AU4: 去年同期 | AV4: 增长比 | AW4: 5月合同额 | AX4: 1-5月排产额合计 | AY4: 完成比 | AZ4: 去年同期 | BA4: 增长比 | BB4: 5月台数 | BC4: 1-5月台数合计 | BD4: 完成比 | BE4: 去年同期 | BF4: 增长比 | BG4: 5月合同额 | BH4: 1-5月合同额合计 | BI4: 完成比 | BJ4: 去年同期 | BK4: 增长比
A5: 1 | B5: A | C5: 俄罗斯（中部） | D5: 1683 | E5: 429 | F5: 0.25490196 | G5: 448 | H5: =(E5-G5)/E5 -> -0.044289044 | I5: 35680 | J5: 8320.51 | K5: 0.23319815 | L5: 8425.6546 | M5: =(J5-L5)/J5 -> -0.012636798 | N5: 750 | O5: 291 | P5: 0.388 | Q5: 189 | R5: =(O5-Q5)/O5 -> 0.35051546 | S5: 14500 | T5: 5446.15 | U5: 0.37559655 | V5: 3547.1566 | W5: =(T5-V5)/T5 -> 0.34868548 | X5: 750 | Y5: 166 | Z5: 0.22133333 | AA5: 134 | AB5: =(Y5-AA5)/Y5 -> 0.19277108 | AC5: 14500 | AD5: 3443.34 | AE5: 0.23747172 | AF5: 2418.3666 | AG5: =(AD5-AF5)/AD5 -> 0.29766837 | AH5: 290 | AI5: =E5+AH5 -> 719 | AJ5: =AI5/D5 -> 0.42721331 | AK5: =VLOOKUP(C5,[1]两年对比终版!$A:$C,3,0) -> 714 | AL5: =(AI5-AK5)/AI5 -> 0.0069541029 | AM5: 5230 | AN5: =AM5+J5 -> 13550.51 | AO5: =AN5/I5 -> 0.37977887 | AP5: =VLOOKUP(C5,[1]两年对比终版!$A:$F,6,0) -> 12648.627 | AQ5: =(AN5-AP5)/AN5 -> 0.066557099 | AR5: 58 | AS5: =AR5+O5 -> 349 | AT5: =AS5/N5 -> 0.46533333 | AU5: =VLOOKUP(C5,[1]两年对比终版!$A:$W,14,0) -> 371 | AV5: =(AS5-AU5)/AS5 -> -0.063037249 | AW5: 1140 | AX5: =AW5+T5 -> 6586.15 | AY5: =AX5/S5 -> 0.45421724 | AZ5: =VLOOKUP(C5,[1]两年对比终版!$A:$W,17,0) -> 6707.2804 | BA5: =(AX5-AZ5)/AX5 -> -0.01839168 | BB5: 114 | BC5: =BB5+Y5 -> 280 | BD5: =BC5/X5 -> 0.37333333 | BE5: =VLOOKUP(C5,[1]两年对比终版!$A:$W,20,0) -> 223 | BF5: =(BC5-BE5)/BC5 -> 0.20357143 | BG5: 2627 | BH5: =BG5+AD5 -> 6070.34 | BI5: =BH5/AC5 -> 0.41864414 | BJ5: =VLOOKUP(C5,[1]两年对比终版!$A:$W,23,0) -> 4120.0566 | BK5: =(BH5-BJ5)/BH5 -> 0.32128075
