Workbook

Sheet 汇总
A1: 2026年国际市场运营系统合同预算情况表
AZ2: 金额单位：万元
A3: 序号 | B3: 模块类型 | C3: 模块 | D3: 新签梯量 | L3: 新签金额 | T3: 排产台 | AB3: 排产额 | AJ3: 发货台 | AR3: 发货额 | AZ3: 回款
D4: 指标 | E4: 完成 | F4: 5月 | G4: 6月 | H4: 半年累计 | I4: 去年同期 | J4: 同比增长 | K4: 完成比 | L4: 指标 | M4: 完成 | N4: 5月 | O4: 6月 | P4: 半年累计 | Q4: 去年同期 | R4: 同比增长 | S4: 完成比 | T4: 指标 | U4: 完成 | V4: 5月 | W4: 6月 | X4: 半年累计 | Y4: 去年同期 | Z4: 同比增长 | AA4: 完成比 | AB4: 指标 | AC4: 完成 | AD4: 5月 | AE4: 6月 | AF4: 半年累计 | AG4: 去年同期 | AH4: 同比增长 | AI4: 完成比 | AJ4: 指标 | AK4: 完成 | AL4: 5月 | AM4: 6月 | AN4: 半年累计 | AO4: 去年同期 | AP4: 同比增长 | AQ4: 完成比 | AR4: 指标 | AS4: 完成 | AT4: 5月 | AU4: 6月 | AV4: 半年累计 | AW4: 去年同期 | AX4: 同比增长 | AY4: 完成比 | AZ4: 指标 | BA4: 完成 | BB4: 5月 | BC4: 6月 | BD4: 累计 | BE4: 去年同期 | BF4: 完成比
A5: 1 | B5: A | C5: 俄罗斯（中部） | D5: 1683 | E5: 437 | F5: =VLOOKUP(C5,'[1]5月25-5月31日汇总'!$C:$D,2,0) -> 0 | G5: =VLOOKUP(C5,'[1]6月汇总'!$C:$D,2,0) -> 100 | H5: =SUM(E5:G5) -> 537 | I5: =VLOOKUP(C5,[2]两年对比终版!$A:$C,3,0) -> 714 | K5: =H5/D5 -> 0.31907308 | L5: 35680 | M5: 8416.64 | N5: =VLOOKUP(C5,'[1]5月25-5月31日汇总'!$C:$E,3,0) -> 0 | O5: =VLOOKUP(C5,'[1]6月汇总'!$C:$E,3,0) -> 1800 | P5: =SUM(M5:O5) -> 10216.64 | Q5: =VLOOKUP(C5,[2]两年对比终版!$A:$F,6,0) -> 12662.341 | S5: =P5/L5 -> 0.28634081 | T5: 750 | U5: 309 | V5: =VLOOKUP(C5,'[1]5月25-5月31日汇总'!$C:$F,4,0) -> 0 | W5: =VLOOKUP(C5,'[1]6月汇总'!$C:$F,4,0) -> 19 | X5: =SUM(U5:W5) -> 328 | Y5: =VLOOKUP(C5,[2]两年对比终版!$A:$N,14,0) -> 371 | AA5: =X5/T5 -> 0.43733333 | AB5: 14500 | AC5: 5700.21 | AD5: =VLOOKUP(C5,'[1]5月25-5月31日汇总'!$C:$G,5,0) -> 0 | AE5: =VLOOKUP(C5,'[1]6月汇总'!$C:$G,5,0) -> 350 | AF5: =SUM(AC5:AE5) -> 6050.21 | AG5: =VLOOKUP(C5,[2]两年对比终版!$A:$Q,17,0) -> 6707.2804 | AI5: =AF5/AB5 -> 0.41725586 | AJ5: 750 | AK5: 259 | AL5: =VLOOKUP(C5,'[1]5月25-5月31日汇总'!$C:$H,6,0) -> 0 | AM5: =VLOOKUP(C5,'[1]6月汇总'!$C:$I,6,0) -> 182 | AN5: =SUM(AK5:AM5) -> 441 | AO5: =VLOOKUP(C5,[2]两年对比终版!$A:$T,20,0) -> 223 | AQ5: =AN5/AJ5 -> 0.588 | AR5: 14500 | AS5: 5724.95 | AT5: =VLOOKUP(C5,'[1]5月25-5月31日汇总'!$C:$I,7,0) -> 0 | AU5: =VLOOKUP(C5,'[1]6月汇总'!$C:$I,7,0) -> 2937 | AV5: =SUM(AS5:AU5) -> 8661.95 | AW5: =VLOOKUP(C5,[2]两年对比终版!$A:$X,23,0) -> 4120.0566 | AY5: =AV5/AR5 -> 0.59737586 | AZ5: 13775 | BA5: 3848.89 | BD5: =SUM(BA5:BC5) -> 3848.89 | BE5: =VLOOKUP(C5,[2]两年对比终版!$A:$AD,30,0) -> 5003.1689 | BF5: =BD5/AZ5 -> 0.27941125
A6: 2 | B6: A | C6: 俄罗斯（西部） | D6: 1683 | E6: 433 | F6: =VLOOKUP(C6,'[1]5月25-5月31日汇总'!$C:$D,2,0) -> 0 | G6: =VLOOKUP(C6,'[1]6月汇总'!$C:$D,2,0) -> 25 | H6: =SUM(E6:G6) -> 458 | I6: =VLOOKUP(C6,[2]两年对比终版!$A:$C,3,0) -> 500 | K6: =H6/D6 -> 0.2721331 | L6: 35680 | M6: 9375.82 | N6: =VLOOKUP(C6,'[1]5月25-5月31日汇总'!$C:$E,3,0) -> 0 | O6: =VLOOKUP(C6,'[1]6月汇总'!$C:$E,3,0) -> 450 | P6: =SUM(M6:O6) -> 9825.82 | Q6: =VLOOKUP(C6,[2]两年对比终版!$A:$F,6,0) -> 9367.9865 | S6: =P6/L6 -> 0.27538733 | T6: 750 | U6: 304 | V6: =VLOOKUP(C6,'[1]5月25-5月31日汇总'!$C:$F,4,0) -> 44 | W6: =VLOOKUP(C6,'[1]6月汇总'!$C:$F,4,0) -> 36 | X6: =SUM(U6:W6) -> 384 | Y6: =VLOOKUP(C6,[2]两年对比终版!$A:$N,14,0) -> 207 | AA6: =X6/T6 -> 0.512 | AB6: 14500 | AC6: 4876.19 | AD6: =VLOOKUP(C6,'[1]5月25-5月31日汇总'!$C:$G,5,0) -> 660.1 | AE6: =VLOOKUP(C6,'[1]6月汇总'!$C:$G,5,0) -> 550 | AF6: =SUM(AC6:AE6) -> 6086.29 | AG6: =VLOOKUP(C6,[2]两年对比终版!$A:$Q,17,0) -> 4230.2512 | AI6: =AF6/AB6 -> 0.41974414 | AJ6: 750 | AK6: 183 | AL6: =VLOOKUP(C6,'[1]5月25-5月31日汇总'!$C:$H,6,0) -> 0 | AM6: =VLOOKUP(C6,'[1]6月汇总'!$C:$I,6,0) -> 0 | AN6: =SUM(AK6:AM6) -> 183 | AO6: =VLOOKUP(C6,[2]两年对比终版!$A:$T,20,0) -> 121 | AQ6: =AN6/AJ6 -> 0.244 | AR6: 14500 | AS6: 3464.95 | AT6: =VLOOKUP(C6,'[1]5月25-5月31日汇总'!$C:$I,7,0) -> 0 | AU6: =VLOOKUP(C6,'[1]6月汇总'!$C:$I,7,0) -> 0 | AV6: =SUM(AS6:AU6) -> 3464.95 | AW6: =VLOOKUP(C6,[2]两年对比终版!$A:$X,23,0) -> 2814.2512 | AY6: =AV6/AR6 -> 0.23896207 | AZ6: 13775 | BA6: 2098.04 | BD6: =SUM(BA6:BC6) -> 2098.04 | BE6: =VLOOKUP(C6,[2]两年对比终版!$A:$AD,30,0) -> 3283.8379 | BF6: =BD6/AZ6 -> 0.1523078
A7: 3 | B7: A | C7: 俄罗斯（东部） | D7: 400 | E7: 210 | F7: =VLOOKUP(C7,'[1]5月25-5月31日汇总'!$C:$D,2,0) -> 0 | G7: =VLOOKUP(C7,'[1]6月汇总'!$C:$D,2,0) -> 31 | H7: =SUM(E7:G7) -> 241 | I7: =VLOOKUP(C7,[2]两年对比终版!$A:$C,3,0) -> 446 | K7: =H7/D7 -> 0.6025 | L7: 6544 | M7: 3909.41 | N7: =VLOOKUP(C7,'[1]5月25-5月31日汇总'!$C:$E,3,0) -> 0 | O7: =VLOOKUP(C7,'[1]6月汇总'!$C:$E,3,0) -> 364 | P7: =SUM(M7:O7) -> 4273.41 | Q7: =VLOOKUP(C7,[2]两年对比终版!$A:$F,6,0) -> 6485.9783 | S7: =P7/L7 -> 0.6530272 | T7: 160 | U7: 98 | V7: =VLOOKUP(C7,'[1]5月25-5月31日汇总'!$C:$F,4,0) -> 0 | W7: =VLOOKUP(C7,'[1]6月汇总'!$C:$F,4,0) -> 10 | X7: =SUM(U7:W7) -> 108 | Y7: =VLOOKUP(C7,[2]两年对比终版!$A:$N,14,0) -> 126 | AA7: =X7/T7 -> 0.675 | AB7: 2657 | AC7: 1280.19 | AD7: =VLOOKUP(C7,'[1]5月25-5月31日汇总'!$C:$G,5,0) -> 0 | AE7: =VLOOKUP(C7,'[1]6月汇总'!$C:$G,5,0) -> 180 | AF7: =SUM(AC7:AE7) -> 1460.19 | AG7: =VLOOKUP(C7,[2]两年对比终版!$A:$Q,17,0) -> 1887.3783 | AI7: =AF7/AB7 -> 0.54956342 | AJ7: 160 | AK7: 58 | AL7: =VLOOKUP(C7,'[1]5月25-5月31日汇总'!$C:$H,6,0) -> 4 | AM7: =VLOOKUP(C7,'[1]6月汇总'!$C:$I,6,0) -> 27 | AN7: =SUM(AK7:AM7) -> 89 | AO7: =VLOOKUP(C7,[2]两年对比终版!$A:$T,20,0) -> 125 | AQ7: =AN7/AJ7 -> 0.55625 | AR7: 2657 | AS7: 712.73 | AT7: =VLOOKUP(C7,'[1]5月25-5月31日汇总'!$C:$I,7,0) -> 72 | AU7: =VLOOKUP(C7,'[1]6月汇总'!$C:$I,7,0) -> 374 | AV7: =SUM(AS7:AU7) -> 1158.73 | AW7: =VLOOKUP(C7,[2]两年对比终版!$A:$X,23,0) -> 1964.9378 | AY7: =AV7/AR7 -> 0.43610463 | AZ7: 2524 | BA7: 761.994 | BD7: =SUM(BA7:BC7) -> 761.994 | BE7: =VLOOKUP(C7,[2]两年对比终版!$A:$AD,30,0) -> 2215.7524 | BF7: =BD7/AZ7 -> 0.30189937
A8: 4 | B8: A | C8: 罗斯托夫 | D8: 270 | E8: 43 | F8: =VLOOKUP(C8,'[1]5月25-5月31日汇总'!$C:$D,2,0) -> 0 | G8: =VLOOKUP(C8,'[1]6月汇总'!$C:$D,2,0) -> 33 | H8: =SUM(E8:G8) -> 76 | I8: =VLOOKUP(C8,[2]两年对比终版!$A:$C,3,0) -> 0 | K8: =H8/D8 -> 0.28148148 | L8: 4428 | M8: 904.52 | N8: =VLOOKUP(C8,'[1]5月25-5月31日汇总'!$C:$E,3,0) -> 0 | O8: =VLOOKUP(C8,'[1]6月汇总'!$C:$E,3,0) -> 354 | P8: =SUM(M8:O8) -> 1258.52 | Q8: =VLOOKUP(C8,[2]两年对比终版!$A:$F,6,0) -> 0 | S8: =P8/L8 -> 0.28421861 | T8: 120 | U8: 14 | V8: =VLOOKUP(C8,'[1]5月25-5月31日汇总'!$C:$F,4,0) -> 1 | W8: =VLOOKUP(C8,'[1]6月汇总'!$C:$F,4,0) -> 13 | X8: =SUM(U8:W8) -> 28 | Y8: =VLOOKUP(C8,[2]两年对比终版!$A:$N,14,0) -> 0 | AA8: =X8/T8 -> 0.23333333 | AB8: 1800 | AC8: 139.5 | AD8: =VLOOKUP(C8,'[1]5月25-5月31日汇总'!$C:$G,5,0) -> 8 | AE8: =VLOOKUP(C8,'[1]6月汇总'!$C:$G,5,0) -> 176 | AF8: =SUM(AC8:AE8) -> 323.5 | AG8: =VLOOKUP(C8,[2]两年对比终版!$A:$Q,17,0) -> 0 | AI8: =AF8/AB8 -> 0.17972222 | AJ8: 120 | AK8: 10 | AL8: =VLOOKUP(C8,'[1]5月25-5月31日汇总'!$C:$H,6,0) -> 0 | AM8: =VLOOKUP(C8,'[1]6月汇总'!$C:$I,6,0) -> 4 | AN8: =SUM(AK8:AM8) -> 14 | AO8: =VLOOKUP(C8,[2]两年对比终版!$A:$T,20,0) -> 0 | AQ8: =AN8/AJ8 -> 0.11666667 | AR8: 1800 | AS8: 102.4 | AT8: =VLOOKUP(C8,'[1]5月25-5月31日汇总'!$C:$I,7,0) -> 0 | AU8: =VLOOKUP(C8,'[1]6月汇总'!$C:$I,7,0) -> 37 | AV8: =SUM(AS8:AU8) -> 139.4 | AW8: =VLOOKUP(C8,[2]两年对比终版!$A:$X,23,0) -> 0 | AY8: =AV8/AR8 -> 0.077444444 | AZ8: 1710 | BA8: 116.493 | BD8: =SUM(BA8:BC8) -> 116.493 | BE8: =VLOOKUP(C8,[2]两年对比终版!$A:$AD,30,0) -> 0 | BF8: =BD8/AZ8 -> 0.068124561
A9: 5 | B9: A | C9: 哈巴 | D9: 270 | E9: 181 | F9: =VLOOKUP(C9,'[1]5月25-5月31日汇总'!$C:$D,2,0) -> 13 | G9: =VLOOKUP(C9,'[1]6月汇总'!$C:$D,2,0) -> 12 | H9: =SUM(E9:G9) -> 206 | I9: =VLOOKUP(C9,[2]两年对比终版!$A:$C,3,0) -> 0 | K9: =H9/D9 -> 0.76296296 | L9: 4428 | M9: 2347.34 | N9: =VLOOKUP(C9,'[1]5月25-5月31日汇总'!$C:$E,3,0) -> 343.6 | O9: =VLOOKUP(C9,'[1]6月汇总'!$C:$E,3,0) -> 134.1 | P9: =SUM(M9:O9) -> 2825.04 | Q9: =VLOOKUP(C9,[2]两年对比终版!$A:$F,6,0) -> 0 | S9: =P9/L9 -> 0.63799458 | T9: 120 | U9: 47 | V9: =VLOOKUP(C9,'[1]5月25-5月31日汇总'!$C:$F,4,0) -> 4 | W9: =VLOOKUP(C9,'[1]6月汇总'!$C:$F,4,0) -> 20 | X9: =SUM(U9:W9) -> 71 | Y9: =VLOOKUP(C9,[2]两年对比终版!$A:$N,14,0) -> 0 | AA9: =X9/T9 -> 0.59166667 | AB9: 1800 | AC9: 500.366 | AD9: =VLOOKUP(C9,'[1]5月25-5月31日汇总'!$C:$G,5,0) -> 43.4 | AE9: =VLOOKUP(C9,'[1]6月汇总'!$C:$G,5,0) -> 169.3 | AF9: =SUM(AC9:AE9) -> 713.066 | AG9: =VLOOKUP(C9,[2]两年对比终版!$A:$Q,17,0) -> 0 | AI9: =AF9/AB9 -> 0.39614778 | AJ9: 120 | AK9: 43 | AL9: =VLOOKUP(C9,'[1]5月25-5月31日汇总'!$C:$H,6,0) -> 0 | AM9: =VLOOKUP(C9,'[1]6月汇总'!$C:$I,6,0) -> 4 | AN9: =SUM(AK9:AM9) -> 47 | AO9: =VLOOKUP(C9,[2]两年对比终版!$A:$T,20,0) -> 0 | AQ9: =AN9/AJ9 -> 0.39166667 | AR9: 1800 | AS9: 456.926 | AT9: =VLOOKUP(C9,'[1]5月25-5月31日汇总'!$C:$I,7,0) -> 0 | AU9: =VLOOKUP(C9,'[1]6月汇总'!$C:$I,7,0) -> 43.4 | AV9: =SUM(AS9:AU9) -> 500.326 | AW9: =VLOOKUP(C9,[2]两年对比终版!$A:$X,23,0) -> 0 | AY9: =AV9/AR9 -> 0.27795889 | AZ9: 1710 | BA9: 419.486 | BD9: =SUM(BA9:BC9) -> 419.486 | BE9: =VLOOKUP(C9,[2]两年对比终版!$A:$AD,30,0) -> 0 | BF9: =BD9/AZ9 -> 0.24531345
A10: 6 | B10: B | C10: 俄罗斯（中南） | D10: 245 | E10: 30 | F10: =VLOOKUP(C10,'[1]5月25-5月31日汇总'!$C:$D,2,0) -> 28 | G10: =VLOOKUP(C10,'[1]6月汇总'!$C:$D,2,0) -> 70 | H10: =SUM(E10:G10) -> 128 | I10: =VLOOKUP(C10,[2]两年对比终版!$A:$C,3,0) -> 79 | K10: =H10/D10 -> 0.52244898 | L10: 4200 | M10: 329.386 | N10: =VLOOKUP(C10,'[1]5月25-5月31日汇总'!$C:$E,3,0) -> 472.51 | O10: =VLOOKUP(C10,'[1]6月汇总'!$C:$E,3,0) -> 900 | P10: =SUM(M10:O10) -> 1701.896 | Q10: =VLOOKUP(C10,[2]两年对比终版!$A:$F,6,0) -> 1044.926 | S10: =P10/L10 -> 0.40521333 | T10: 100 | U10: 17 | V10: =VLOOKUP(C10,'[1]5月25-5月31日汇总'!$C:$F,4,0) -> 4 | W10: =VLOOKUP(C10,'[1]6月汇总'!$C:$F,4,0) -> 25 | X10: =SUM(U10:W10) -> 46 | Y10: =VLOOKUP(C10,[2]两年对比终版!$A:$N,14,0) -> 30 | AA10: =X10/T10 -> 0.46 | AB10: 1778 | AC10: 174.656 | AD10: =VLOOKUP(C10,'[1]5月25-5月31日汇总'!$C:$G,5,0) -> 74.6 | AE10: =VLOOKUP(C10,'[1]6月汇总'!$C:$G,5,0) -> 300 | AF10: =SUM(AC10:AE10) -> 549.256 | AG10: =VLOOKUP(C10,[2]两年对比终版!$A:$Q,17,0) -> 487.232 | AI10: =AF10/AB10 -> 0.30891789 | AJ10: 100 | AK10: 12 | AL10: =VLOOKUP(C10,'[1]5月25-5月31日汇总'!$C:$H,6,0) -> 3 | AM10: =VLOOKUP(C10,'[1]6月汇总'!$C:$I,6,0) -> 31 | AN10: =SUM(AK10:AM10) -> 46 | AO10: =VLOOKUP(C10,[2]两年对比终版!$A:$T,20,0) -> 36 | AQ10: =AN10/AJ10 -> 0.46 | AR10: 1778 | AS10: 148.86 | AT10: =VLOOKUP(C10,'[1]5月25-5月31日汇总'!$C:$I,7,0) -> 31.17 | AU10: =VLOOKUP(C10,'[1]6月汇总'!$C:$I,7,0) -> 292.7166 | AV10: =SUM(AS10:AU10) -> 472.7466 | AW10: =VLOOKUP(C10,[2]两年对比终版!$A:$X,23,0) -> 515.132 | AY10: =AV10/AR10 -> 0.26588673 | AZ10: 1689 | BA10: 145.87 | BD10: =SUM(BA10:BC10) -> 145.87 | BE10: =VLOOKUP(C10,[2]两年对比终版!$A:$AD,30,0) -> 545.38061 | BF10: =BD10/AZ10 -> 0.086364713
A11: 7 | B11: B | C11: 俄罗斯（西南） | D11: 489 | E11: 64 | F11: =VLOOKUP(C11,'[1]5月25-5月31日汇总'!$C:$D,2,0) -> 10 | G11: =VLOOKUP(C11,'[1]6月汇总'!$C:$D,2,0) -> 80 | H11: =SUM(E11:G11) -> 154 | I11: =VLOOKUP(C11,[2]两年对比终版!$A:$C,3,0) -> 415 | K11: =H11/D11 -> 0.31492843 | L11: 7525.12 | M11: 1474.22 | N11: =VLOOKUP(C11,'[1]5月25-5月31日汇总'!$C:$E,3,0) -> 130 | O11: =VLOOKUP(C11,'[1]6月汇总'!$C:$E,3,0) -> 1600 | P11: =SUM(M11:O11) -> 3204.22 | Q11: =VLOOKUP(C11,[2]两年对比终版!$A:$F,6,0) -> 7818.733 | S11: =P11/L11 -> 0.42580318 | T11: 210 | U11: 28 | V11: =VLOOKUP(C11,'[1]5月25-5月31日汇总'!$C:$F,4,0) -> 0 | W11: =VLOOKUP(C11,'[1]6月汇总'!$C:$F,4,0) -> 23 | X11: =SUM(U11:W11) -> 51 | Y11: =VLOOKUP(C11,[2]两年对比终版!$A:$N,14,0) -> 156 | AA11: =X11/T11 -> 0.24285714 | AB11: 2972 | AC11: 328.073 | AD11: =VLOOKUP(C11,'[1]5月25-5月31日汇总'!$C:$G,5,0) -> 0 | AE11: =VLOOKUP(C11,'[1]6月汇总'!$C:$G,5,0) -> 370 | AF11: =SUM(AC11:AE11) -> 698.073 | AG11: =VLOOKUP(C11,[2]两年对比终版!$A:$Q,17,0) -> 2594.4505 | AI11: =AF11/AB11 -> 0.23488324 | AJ11: 210 | AK11: 24 | AL11: =VLOOKUP(C11,'[1]5月25-5月31日汇总'!$C:$H,6,0) -> 0 | AM11: =VLOOKUP(C11,'[1]6月汇总'!$C:$I,6,0) -> 4 | AN11: =SUM(AK11:AM11) -> 28 | AO11: =VLOOKUP(C11,[2]两年对比终版!$A:$T,20,0) -> 108 | AQ11: =AN11/AJ11 -> 0.13333333 | AR11: 2972 | AS11: 276.233 | AT11: =VLOOKUP(C11,'[1]5月25-5月31日汇总'!$C:$I,7,0) -> 0 | AU11: =VLOOKUP(C11,'[1]6月汇总'!$C:$I,7,0) -> 53 | AV11: =SUM(AS11:AU11) -> 329.233 | AW11: =VLOOKUP(C11,[2]两年对比终版!$A:$X,23,0) -> 1970.7395 | AY11: =AV11/AR11 -> 0.11077826 | AZ11: 2822 | BA11: 16.713 | BD11: =SUM(BA11:BC11) -> 16.713 | BE11: =VLOOKUP(C11,[2]两年对比终版!$A:$AD,30,0) -> 2067.2919 | BF11: =BD11/AZ11 -> 0.0059223955
A12: 8 | B12: C | C12: 莫斯科 | D12: 72 | E12: 2 | F12: =VLOOKUP(C12,'[1]5月25-5月31日汇总'!$C:$D,2,0) -> 8 | G12: =VLOOKUP(C12,'[1]6月汇总'!$C:$D,2,0) -> 14 | H12: =SUM(E12:G12) -> 24 | I12: =VLOOKUP(C12,[2]两年对比终版!$A:$C,3,0) -> 0 | K12: =H12/D12 -> 0.33333333 | L12: 1085 | M12: 22.84 | N12: =VLOOKUP(C12,'[1]5月25-5月31日汇总'!$C:$E,3,0) -> 100 | O12: =VLOOKUP(C12,'[1]6月汇总'!$C:$E,3,0) -> 118 | P12: =SUM(M12:O12) -> 240.84 | Q12: =VLOOKUP(C12,[2]两年对比终版!$A:$F,6,0) -> 0 | S12: =P12/L12 -> 0.22197235 | T12: 30 | U12: 2 | V12: =VLOOKUP(C12,'[1]5月25-5月31日汇总'!$C:$F,4,0) -> 0 | W12: =VLOOKUP(C12,'[1]6月汇总'!$C:$F,4,0) -> 6 | X12: =SUM(U12:W12) -> 8 | Y12: =VLOOKUP(C12,[2]两年对比终版!$A:$N,14,0) -> 0 | AA12: =X12/T12 -> 0.26666667 | AB12: 450 | AC12: 22.84 | AD12: =VLOOKUP(C12,'[1]5月25-5月31日汇总'!$C:$G,5,0) -> 0 | AE12: =VLOOKUP(C12,'[1]6月汇总'!$C:$G,5,0) -> 49 | AF12: =SUM(AC12:AE12) -> 71.84 | AG12: =VLOOKUP(C12,[2]两年对比终版!$A:$Q,17,0) -> 0 | AI12: =AF12/AB12 -> 0.15964444 | AJ12: 30 | AK12: 2 | AL12: =VLOOKUP(C12,'[1]5月25-5月31日汇总'!$C:$H,6,0) -> 0 | AM12: =VLOOKUP(C12,'[1]6月汇总'!$C:$I,6,0) -> 6 | AN12: =SUM(AK12:AM12) -> 8 | AO12: =VLOOKUP(C12,[2]两年对比终版!$A:$T,20,0) -> 0 | AQ12: =AN12/AJ12 -> 0.26666667 | AR12: 450 | AS12: 22.84 | AT12: =VLOOKUP(C12,'[1]5月25-5月31日汇总'!$C:$I,7,0) -> 0 | AU12: =VLOOKUP(C12,'[1]6月汇总'!$C:$I,7,0) -> 49 | AV12: =SUM(AS12:AU12) -> 71.84 | AW12: =VLOOKUP(C12,[2]两年对比终版!$A:$X,23,0) -> 0 | AY12: =AV12/AR12 -> 0.15964444 | AZ12: 428 | BA12: 22.12 | BD12: =SUM(BA12:BC12) -> 22.12 | BE12: =VLOOKUP(C12,[2]两年对比终版!$A:$AD,30,0) -> 0 | BF12: =BD12/AZ12 -> 0.051682243
A13: 9 | B13: C | C13: 叶卡 | D13: 72 | E13: 0 | F13: =VLOOKUP(C13,'[1]5月25-5月31日汇总'!$C:$D,2,0) -> 0 | G13: =VLOOKUP(C13,'[1]6月汇总'!$C:$D,2,0) -> 0 | H13: =SUM(E13:G13) -> 0 | I13: =VLOOKUP(C13,[2]两年对比终版!$A:$C,3,0) -> 0 | K13: =H13/D13 -> 0 | L13: 1085 | M13: 0 | N13: =VLOOKUP(C13,'[1]5月25-5月31日汇总'!$C:$E,3,0) -> 0 | O13: =VLOOKUP(C13,'[1]6月汇总'!$C:$E,3,0) -> 0 | P13: =SUM(M13:O13) -> 0 | Q13: =VLOOKUP(C13,[2]两年对比终版!$A:$F,6,0) -> 0 | S13: =P13/L13 -> 0 | T13: 30 | U13: 0 | V13: =VLOOKUP(C13,'[1]5月25-5月31日汇总'!$C:$F,4,0) -> 0 | W13: =VLOOKUP(C13,'[1]6月汇总'!$C:$F,4,0) -> 0 | X13: =SUM(U13:W13) -> 0 | Y13: =VLOOKUP(C13,[2]两年对比终版!$A:$N,14,0) -> 0 | AA13: =X13/T13 -> 0 | AB13: 450 | AC13: 0 | AD13: =VLOOKUP(C13,'[1]5月25-5月31日汇总'!$C:$G,5,0) -> 0 | AE13: =VLOOKUP(C13,'[1]6月汇总'!$C:$G,5,0) -> 0 | AF13: =SUM(AC13:AE13) -> 0 | AG13: =VLOOKUP(C13,[2]两年对比终版!$A:$Q,17,0) -> 0 | AI13: =AF13/AB13 -> 0 | AJ13: 30 | AK13: 0 | AL13: =VLOOKUP(C13,'[1]5月25-5月31日汇总'!$C:$H,6,0) -> 0 | AM13: =VLOOKUP(C13,'[1]6月汇总'!$C:$I,6,0) -> 0 | AN13: =SUM(AK13:AM13) -> 0 | AO13: =VLOOKUP(C13,[2]两年对比终版!$A:$T,20,0) -> 0 | AQ13: =AN13/AJ13 -> 0 | AR13: 450 | AS13: 0 | AT13: =VLOOKUP(C13,'[1]5月25-5月31日汇总'!$C:$I,7,0) -> 0 | AU13: =VLOOKUP(C13,'[1]6月汇总'!$C:$I,7,0) -> 0 | AV13: =SUM(AS13:AU13) -> 0 | AW13: =VLOOKUP(C13,[2]两年对比终版!$A:$X,23,0) -> 0 | AY13: =AV13/AR13 -> 0 | AZ13: 428 | BA13: 0 | BD13: =SUM(BA13:BC13) -> 0 | BE13: =VLOOKUP(C13,[2]两年对比终版!$A:$AD,30,0) -> 0 | BF13: =BD13/AZ13 -> 0
A14: 10 | B14: C | C14: 新西 | D14: 72 | E14: 0 | F14: =VLOOKUP(C14,'[1]5月25-5月31日汇总'!$C:$D,2,0) -> 0 | G14: =VLOOKUP(C14,'[1]6月汇总'!$C:$D,2,0) -> 0 | H14: =SUM(E14:G14) -> 0 | I14: =VLOOKUP(C14,[2]两年对比终版!$A:$C,3,0) -> 0 | K14: =H14/D14 -> 0 | L14: 1085 | M14: 0 | N14: =VLOOKUP(C14,'[1]5月25-5月31日汇总'!$C:$E,3,0) -> 0 | O14: =VLOOKUP(C14,'[1]6月汇总'!$C:$E,3,0) -> 0 | P14: =SUM(M14:O14) -> 0 | Q14: =VLOOKUP(C14,[2]两年对比终版!$A:$F,6,0) -> 0 | S14: =P14/L14 -> 0 | T14: 30 | U14: 0 | V14: =VLOOKUP(C14,'[1]5月25-5月31日汇总'!$C:$F,4,0) -> 0 | W14: =VLOOKUP(C14,'[1]6月汇总'!$C:$F,4,0) -> 0 | X14: =SUM(U14:W14) -> 0 | Y14: =VLOOKUP(C14,[2]两年对比终版!$A:$N,14,0) -> 0 | AA14: =X14/T14 -> 0 | AB14: 450 | AC14: 0 | AD14: =VLOOKUP(C14,'[1]5月25-5月31日汇总'!$C:$G,5,0) -> 0 | AE14: =VLOOKUP(C14,'[1]6月汇总'!$C:$G,5,0) -> 0 | AF14: =SUM(AC14:AE14) -> 0 | AG14: =VLOOKUP(C14,[2]两年对比终版!$A:$Q,17,0) -> 0 | AI14: =AF14/AB14 -> 0 | AJ14: 30 | AK14: 0 | AL14: =VLOOKUP(C14,'[1]5月25-5月31日汇总'!$C:$H,6,0) -> 0 | AM14: =VLOOKUP(C14,'[1]6月汇总'!$C:$I,6,0) -> 0 | AN14: =SUM(AK14:AM14) -> 0 | AO14: =VLOOKUP(C14,[2]两年对比终版!$A:$T,20,0) -> 0 | AQ14: =AN14/AJ14 -> 0 | AR14: 450 | AS14: 0 | AT14: =VLOOKUP(C14,'[1]5月25-5月31日汇总'!$C:$I,7,0) -> 0 | AU14: =VLOOKUP(C14,'[1]6月汇总'!$C:$I,7,0) -> 0 | AV14: =SUM(AS14:AU14) -> 0 | AW14: =VLOOKUP(C14,[2]两年对比终版!$A:$X,23,0) -> 0 | AY14: =AV14/AR14 -> 0 | AZ14: 428 | BA14: 0 | BD14: =SUM(BA14:BC14) -> 0 | BE14: =VLOOKUP(C14,[2]两年对比终版!$A:$AD,30,0) -> 0 | BF14: =BD14/AZ14 -> 0
A15: 俄罗斯合计 | D15: =SUM(D5:D14) -> 5256 | E15: =SUM(E5:E14) -> 1400 | F15: =SUM(F5:F14) -> 59 | G15: =SUM(G5:G14) -> 365 | H15: =SUM(H5:H14) -> 1824 | I15: =SUM(I5:I14) -> 2154 | J15: =(H15-I15)/I15 -> -0.15320334 | K15: =H15/D15 -> 0.34703196 | L15: =SUM(L5:L14) -> 101740.12 | M15: =SUM(M5:M14) -> 26780.176 | N15: =SUM(N5:N14) -> 1046.11 | O15: =SUM(O5:O14) -> 5720.1 | P15: =SUM(P5:P14) -> 33546.386 | Q15: =SUM(Q5:Q14) -> 37379.965 | R15: =(P15-Q15)/Q15 -> -0.10255706 | S15: =P15/L15 -> 0.32972623 | T15: =SUM(T5:T14) -> 2300 | U15: =SUM(U5:U14) -> 819 | V15: =SUM(V5:V14) -> 53 | W15: =SUM(W5:W14) -> 152 | X15: =SUM(X5:X14) -> 1024 | Y15: =SUM(Y5:Y14) -> 890 | Z15: =(X15-Y15)/Y15 -> 0.1505618 | AA15: =X15/T15 -> 0.44521739 | AB15: =SUM(AB5:AB14) -> 41357 | AC15: =SUM(AC5:AC14) -> 13022.025 | AD15: =SUM(AD5:AD14) -> 786.1 | AE15: =SUM(AE5:AE14) -> 2144.3 | AF15: =SUM(AF5:AF14) -> 15952.425 | AG15: =SUM(AG5:AG14) -> 15906.592 | AH15: =(AF15-AG15)/AG15 -> 0.0028813613 | AI15: =AF15/AB15 -> 0.38572491 | AJ15: =SUM(AJ5:AJ14) -> 2300 | AK15: =SUM(AK5:AK14) -> 591 | AL15: =SUM(AL5:AL14) -> 7 | AM15: =SUM(AM5:AM14) -> 258 | AN15: =SUM(AN5:AN14) -> 856 | AO15: =SUM(AO5:AO14) -> 613 | AP15: =(AN15-AO15)/AO15 -> 0.39641109 | AQ15: =AN15/AJ15 -> 0.37217391 | AR15: =SUM(AR5:AR14) -> 41357 | AS15: =SUM(AS5:AS14) -> 10909.889 | AT15: =SUM(AT5:AT14) -> 103.17 | AU15: =SUM(AU5:AU14) -> 3786.1166 | AV15: =SUM(AV5:AV14) -> 14799.176 | AW15: =SUM(AW5:AW14) -> 11385.117 | AX15: =(AV15-AW15)/AW15 -> 0.2998703 | AY15: =AV15/AR15 -> 0.35783968 | AZ15: =SUM(AZ5:AZ14) -> 39289 | BA15: =SUM(BA5:BA14) -> 7429.606 | BB15: =SUM(BB5:BB14) -> 0 | BC15: =SUM(BC5:BC14) -> 0 | BD15: =SUM(BD5:BD14) -> 7429.606 | BE15: =SUM(BE5:BE14) -> 13115.432 | BF15: =BD15/AZ15 -> 0.18910143
A16: 11 | B16: D | C16: 朝鲜-韩国 | D16: 54 | E16: 34 | F16: =VLOOKUP(C16,'[1]5月25-5月31日汇总'!$C:$D,2,0) -> 0 | G16: =VLOOKUP(C16,'[1]6月汇总'!$C:$D,2,0) -> 10 | H16: =SUM(E16:G16) -> 44 | I16: =VLOOKUP(C16,[2]两年对比终版!$A:$C,3,0) -> 35 | K16: =H16/D16 -> 0.81481481 | L16: 540 | M16: 293.5 | N16: =VLOOKUP(C16,'[1]5月25-5月31日汇总'!$C:$E,3,0) -> 0 | O16: =VLOOKUP(C16,'[1]6月汇总'!$C:$E,3,0) -> 8 | P16: =SUM(M16:O16) -> 301.5 | Q16: =VLOOKUP(C16,[2]两年对比终版!$A:$F,6,0) -> 287.19 | S16: =P16/L16 -> 0.55833333 | T16: 32 | U16: 4 | V16: =VLOOKUP(C16,'[1]5月25-5月31日汇总'!$C:$F,4,0) -> 0 | W16: =VLOOKUP(C16,'[1]6月汇总'!$C:$F,4,0) -> 8 | X16: =SUM(U16:W16) -> 12 | Y16: =VLOOKUP(C16,[2]两年对比终版!$A:$N,14,0) -> 1 | AA16: =X16/T16 -> 0.375 | AB16: 264.163 | AC16: 36.2 | AD16: =VLOOKUP(C16,'[1]5月25-5月31日汇总'!$C:$G,5,0) -> 0 | AE16: =VLOOKUP(C16,'[1]6月汇总'!$C:$G,5,0) -> 48 | AF16: =SUM(AC16:AE16) -> 84.2 | AG16: =VLOOKUP(C16,[2]两年对比终版!$A:$Q,17,0) -> 7.6 | AI16: =AF16/AB16 -> 0.31874259 | AJ16: 32 | AK16: 6 | AL16: =VLOOKUP(C16,'[1]5月25-5月31日汇总'!$C:$H,6,0) -> 0 | AM16: =VLOOKUP(C16,'[1]6月汇总'!$C:$I,6,0) -> 6 | AN16: =SUM(AK16:AM16) -> 12 | AO16: =VLOOKUP(C16,[2]两年对比终版!$A:$T,20,0) -> 1 | AQ16: =AN16/AJ16 -> 0.375 | AR16: 264.163 | AS16: 55.4871 | AT16: =VLOOKUP(C16,'[1]5月25-5月31日汇总'!$C:$I,7,0) -> 0 | AU16: =VLOOKUP(C16,'[1]6月汇总'!$C:$I,7,0) -> 60 | AV16: =SUM(AS16:AU16) -> 115.4871 | AW16: =VLOOKUP(C16,[2]两年对比终版!$A:$X,23,0) -> 7.6 | AY16: =AV16/AR16 -> 0.43718121 | AZ16: 251 | BA16: 4.8 | BD16: =SUM(BA16:BC16) -> 4.8 | BE16: =VLOOKUP(C16,[2]两年对比终版!$A:$AD,30,0) -> 7.6 | BF16: =BD16/AZ16 -> 0.019123506
A17: 12 | B17: A | C17: 新加坡市政会 | D17: 277 | E17: 67 | F17: =VLOOKUP(C17,'[1]5月25-5月31日汇总'!$C:$D,2,0) -> 20 | G17: =VLOOKUP(C17,'[1]6月汇总'!$C:$D,2,0) -> 47 | H17: =SUM(E17:G17) -> 134 | I17: =VLOOKUP(C17,[2]两年对比终版!$A:$C,3,0) -> 196 | K17: =H17/D17 -> 0.48375451 | L17: 6100 | M17: 1640.06 | N17: =VLOOKUP(C17,'[1]5月25-5月31日汇总'!$C:$E,3,0) -> 1000 | O17: =VLOOKUP(C17,'[1]6月汇总'!$C:$E,3,0) -> 1000 | P17: =SUM(M17:O17) -> 3640.06 | Q17: =VLOOKUP(C17,[2]两年对比终版!$A:$F,6,0) -> 4135.4805 | S17: =P17/L17 -> 0.59673115 | T17: 101 | U17: 4 | V17: =VLOOKUP(C17,'[1]5月25-5月31日汇总'!$C:$F,4,0) -> 0 | W17: =VLOOKUP(C17,'[1]6月汇总'!$C:$F,4,0) -> 0 | X17: =SUM(U17:W17) -> 4 | Y17: =VLOOKUP(C17,[2]两年对比终版!$A:$N,14,0) -> 77 | AA17: =X17/T17 -> 0.03960396 | AB17: 2153 | AC17: 74.2762 | AD17: =VLOOKUP(C17,'[1]5月25-5月31日汇总'!$C:$G,5,0) -> 0 | AE17: =VLOOKUP(C17,'[1]6月汇总'!$C:$G,5,0) -> 0 | AF17: =SUM(AC17:AE17) -> 74.2762 | AG17: =VLOOKUP(C17,[2]两年对比终版!$A:$Q,17,0) -> 1734.6186 | AI17: =AF17/AB17 -> 0.034498932 | AJ17: 101 | AK17: 28 | AL17: =VLOOKUP(C17,'[1]5月25-5月31日汇总'!$C:$H,6,0) -> 4 | AM17: =VLOOKUP(C17,'[1]6月汇总'!$C:$I,6,0) -> 9 | AN17: =SUM(AK17:AM17) -> 41 | AO17: =VLOOKUP(C17,[2]两年对比终版!$A:$T,20,0) -> 25 | AQ17: =AN17/AJ17 -> 0.40594059 | AR17: 2153 | AS17: 530.438 | AT17: =VLOOKUP(C17,'[1]5月25-5月31日汇总'!$C:$I,7,0) -> 80 | AU17: =VLOOKUP(C17,'[1]6月汇总'!$C:$I,7,0) -> 180 | AV17: =SUM(AS17:AU17) -> 790.438 | AW17: =VLOOKUP(C17,[2]两年对比终版!$A:$X,23,0) -> 619.60194 | AY17: =AV17/AR17 -> 0.3671333 | AZ17: 2045 | BA17: 478.41 | BD17: =SUM(BA17:BC17) -> 478.41 | BE17: =VLOOKUP(C17,[2]两年对比终版!$A:$AD,30,0) -> 1226.4742 | BF17: =BD17/AZ17 -> 0.23394132
A18: 13 | B18: A | C18: 新加坡HDB | D18: 566 | E18: 243 | F18: =VLOOKUP(C18,'[1]5月25-5月31日汇总'!$C:$D,2,0) -> 75 | G18: =VLOOKUP(C18,'[1]6月汇总'!$C:$D,2,0) -> 49 | H18: =SUM(E18:G18) -> 367 | I18: =VLOOKUP(C18,[2]两年对比终版!$A:$C,3,0) -> 260 | K18: =H18/D18 -> 0.64840989 | L18: 20400 | M18: 5502.59 | N18: =VLOOKUP(C18,'[1]5月25-5月31日汇总'!$C:$E,3,0) -> 2600 | O18: =VLOOKUP(C18,'[1]6月汇总'!$C:$E,3,0) -> 1010 | P18: =SUM(M18:O18) -> 9112.59 | Q18: =VLOOKUP(C18,[2]两年对比终版!$A:$F,6,0) -> 5925.604 | S18: =P18/L18 -> 0.44669559 | T18: 260 | U18: 140 | V18: =VLOOKUP(C18,'[1]5月25-5月31日汇总'!$C:$F,4,0) -> 0 | W18: =VLOOKUP(C18,'[1]6月汇总'!$C:$F,4,0) -> 10 | X18: =SUM(U18:W18) -> 150 | Y18: =VLOOKUP(C18,[2]两年对比终版!$A:$N,14,0) -> 106 | AA18: =X18/T18 -> 0.57692308 | AB18: 8500 | AC18: 6203.39 | AD18: =VLOOKUP(C18,'[1]5月25-5月31日汇总'!$C:$G,5,0) -> 0 | AE18: =VLOOKUP(C18,'[1]6月汇总'!$C:$G,5,0) -> 400 | AF18: =SUM(AC18:AE18) -> 6603.39 | AG18: =VLOOKUP(C18,[2]两年对比终版!$A:$Q,17,0) -> 3966.0716 | AI18: =AF18/AB18 -> 0.77686941 | AJ18: 260 | AK18: 155 | AL18: =VLOOKUP(C18,'[1]5月25-5月31日汇总'!$C:$H,6,0) -> 3 | AM18: =VLOOKUP(C18,'[1]6月汇总'!$C:$I,6,0) -> 13 | AN18: =SUM(AK18:AM18) -> 171 | AO18: =VLOOKUP(C18,[2]两年对比终版!$A:$T,20,0) -> 10 | AQ18: =AN18/AJ18 -> 0.65769231 | AR18: 8500 | AS18: 6707.44 | AT18: =VLOOKUP(C18,'[1]5月25-5月31日汇总'!$C:$I,7,0) -> 100 | AU18: =VLOOKUP(C18,'[1]6月汇总'!$C:$I,7,0) -> 470 | AV18: =SUM(AS18:AU18) -> 7277.44 | AW18: =VLOOKUP(C18,[2]两年对比终版!$A:$X,23,0) -> 374.14793 | AY18: =AV18/AR18 -> 0.85616941 | AZ18: 8075 | BA18: 23.4226 | BD18: =SUM(BA18:BC18) -> 23.4226 | BE18: =VLOOKUP(C18,[2]两年对比终版!$A:$AD,30,0) -> 15.197813 | BF18: =BD18/AZ18 -> 0.0029006316
A19: 14 | B19: D | C19: 泰国 | D19: 90 | E19: 25 | F19: =VLOOKUP(C19,'[1]5月25-5月31日汇总'!$C:$D,2,0) -> 3 | G19: =VLOOKUP(C19,'[1]6月汇总'!$C:$D,2,0) -> 10 | H19: =SUM(E19:G19) -> 38 | I19: =VLOOKUP(C19,[2]两年对比终版!$A:$C,3,0) -> 52 | K19: =H19/D19 -> 0.42222222 | L19: 840 | M19: 336.439 | N19: =VLOOKUP(C19,'[1]5月25-5月31日汇总'!$C:$E,3,0) -> 24 | O19: =VLOOKUP(C19,'[1]6月汇总'!$C:$E,3,0) -> 80 | P19: =SUM(M19:O19) -> 440.439 | Q19: =VLOOKUP(C19,[2]两年对比终版!$A:$F,6,0) -> 517.46812 | S19: =P19/L19 -> 0.52433214 | T19: 25 | U19: 5 | V19: =VLOOKUP(C19,'[1]5月25-5月31日汇总'!$C:$F,4,0) -> 1 | W19: =VLOOKUP(C19,'[1]6月汇总'!$C:$F,4,0) -> 2 | X19: =SUM(U19:W19) -> 8 | Y19: =VLOOKUP(C19,[2]两年对比终版!$A:$N,14,0) -> 26 | AA19: =X19/T19 -> 0.32 | AB19: 200 | AC19: 58.9903 | AD19: =VLOOKUP(C19,'[1]5月25-5月31日汇总'!$C:$G,5,0) -> 15.54 | AE19: =VLOOKUP(C19,'[1]6月汇总'!$C:$G,5,0) -> 18.34 | AF19: =SUM(AC19:AE19) -> 92.8703 | AG19: =VLOOKUP(C19,[2]两年对比终版!$A:$Q,17,0) -> 239.82783 | AI19: =AF19/AB19 -> 0.4643515 | AJ19: 25 | AK19: 5 | AL19: =VLOOKUP(C19,'[1]5月25-5月31日汇总'!$C:$H,6,0) -> 0 | AM19: =VLOOKUP(C19,'[1]6月汇总'!$C:$I,6,0) -> 3 | AN19: =SUM(AK19:AM19) -> 8 | AO19: =VLOOKUP(C19,[2]两年对比终版!$A:$T,20,0) -> 25 | AQ19: =AN19/AJ19 -> 0.32 | AR19: 200 | AS19: 56.3121 | AT19: =VLOOKUP(C19,'[1]5月25-5月31日汇总'!$C:$I,7,0) -> 0 | AU19: =VLOOKUP(C19,'[1]6月汇总'!$C:$I,7,0) -> 37.73 | AV19: =SUM(AS19:AU19) -> 94.0421 | AW19: =VLOOKUP(C19,[2]两年对比终版!$A:$X,23,0) -> 233.58913 | AY19: =AV19/AR19 -> 0.4702105 | AZ19: 190 | BA19: 22.5315 | BD19: =SUM(BA19:BC19) -> 22.5315 | BE19: =VLOOKUP(C19,[2]两年对比终版!$A:$AD,30,0) -> 283.50055 | BF19: =BD19/AZ19 -> 0.11858684
A20: 15 | B20: D | C20: 泰国2 | D20: 136 | E20: 49 | F20: =VLOOKUP(C20,'[1]5月25-5月31日汇总'!$C:$D,2,0) -> 2 | G20: =VLOOKUP(C20,'[1]6月汇总'!$C:$D,2,0) -> 20 | H20: =SUM(E20:G20) -> 71 | I20: =VLOOKUP(C20,[2]两年对比终版!$A:$C,3,0) -> 0 | K20: =H20/D20 -> 0.52205882 | L20: 1200 | M20: 429.24 | N20: =VLOOKUP(C20,'[1]5月25-5月31日汇总'!$C:$E,3,0) -> 13 | O20: =VLOOKUP(C20,'[1]6月汇总'!$C:$E,3,0) -> 160 | P20: =SUM(M20:O20) -> 602.24 | Q20: =VLOOKUP(C20,[2]两年对比终版!$A:$F,6,0) -> 0 | S20: =P20/L20 -> 0.50186667 | T20: 36 | U20: 12 | V20: =VLOOKUP(C20,'[1]5月25-5月31日汇总'!$C:$F,4,0) -> 0 | W20: =VLOOKUP(C20,'[1]6月汇总'!$C:$F,4,0) -> 10 | X20: =SUM(U20:W20) -> 22 | Y20: =VLOOKUP(C20,[2]两年对比终版!$A:$N,14,0) -> 0 | AA20: =X20/T20 -> 0.61111111 | AB20: 300 | AC20: 100.68 | AD20: =VLOOKUP(C20,'[1]5月25-5月31日汇总'!$C:$G,5,0) -> 0 | AE20: =VLOOKUP(C20,'[1]6月汇总'!$C:$G,5,0) -> 100 | AF20: =SUM(AC20:AE20) -> 200.68 | AG20: =VLOOKUP(C20,[2]两年对比终版!$A:$Q,17,0) -> 0 | AI20: =AF20/AB20 -> 0.66893333 | AJ20: 36 | AK20: 9 | AL20: =VLOOKUP(C20,'[1]5月25-5月31日汇总'!$C:$H,6,0) -> 0 | AM20: =VLOOKUP(C20,'[1]6月汇总'!$C:$I,6,0) -> 5 | AN20: =SUM(AK20:AM20) -> 14 | AO20: =VLOOKUP(C20,[2]两年对比终版!$A:$T,20,0) -> 0 | AQ20: =AN20/AJ20 -> 0.38888889 | AR20: 300 | AS20: 74.13 | AT20: =VLOOKUP(C20,'[1]5月25-5月31日汇总'!$C:$I,7,0) -> 0 | AU20: =VLOOKUP(C20,'[1]6月汇总'!$C:$I,7,0) -> 40 | AV20: =SUM(AS20:AU20) -> 114.13 | AW20: =VLOOKUP(C20,[2]两年对比终版!$A:$X,23,0) -> 0 | AY20: =AV20/AR20 -> 0.38043333 | AZ20: 285 | BA20: 106.129 | BD20: =SUM(BA20:BC20) -> 106.129 | BE20: =VLOOKUP(C20,[2]两年对比终版!$A:$AD,30,0) -> 0 | BF20: =BD20/AZ20 -> 0.37238246
A21: 16 | B21: D | C21: 金三角 | D21: 40 | E21: 5 | F21: =VLOOKUP(C21,'[1]5月25-5月31日汇总'!$C:$D,2,0) -> 0 | G21: =VLOOKUP(C21,'[1]6月汇总'!$C:$D,2,0) -> 6 | H21: =SUM(E21:G21) -> 11 | I21: =VLOOKUP(C21,[2]两年对比终版!$A:$C,3,0) -> 94 | K21: =H21/D21 -> 0.275 | L21: 200 | M21: 40.6814 | N21: =VLOOKUP(C21,'[1]5月25-5月31日汇总'!$C:$E,3,0) -> 0 | O21: =VLOOKUP(C21,'[1]6月汇总'!$C:$E,3,0) -> 30 | P21: =SUM(M21:O21) -> 70.6814 | Q21: =VLOOKUP(C21,[2]两年对比终版!$A:$F,6,0) -> 1146.3367 | S21: =P21/L21 -> 0.353407 | T21: 36 | U21: 0 | V21: =VLOOKUP(C21,'[1]5月25-5月31日汇总'!$C:$F,4,0) -> 0 | W21: =VLOOKUP(C21,'[1]6月汇总'!$C:$F,4,0) -> 0 | X21: =SUM(U21:W21) -> 0 | Y21: =VLOOKUP(C21,[2]两年对比终版!$A:$N,14,0) -> 0 | AA21: =X21/T21 -> 0 | AB21: 200 | AC21: 0 | AD21: =VLOOKUP(C21,'[1]5月25-5月31日汇总'!$C:$G,5,0) -> 0 | AE21: =VLOOKUP(C21,'[1]6月汇总'!$C:$G,5,0) -> 0 | AF21: =SUM(AC21:AE21) -> 0 | AG21: =VLOOKUP(C21,[2]两年对比终版!$A:$Q,17,0) -> 0 | AI21: =AF21/AB21 -> 0 | AJ21: 36 | AK21: 0 | AL21: =VLOOKUP(C21,'[1]5月25-5月31日汇总'!$C:$H,6,0) -> 0 | AM21: =VLOOKUP(C21,'[1]6月汇总'!$C:$I,6,0) -> 0 | AN21: =SUM(AK21:AM21) -> 0 | AO21: =VLOOKUP(C21,[2]两年对比终版!$A:$T,20,0) -> 0 | AQ21: =AN21/AJ21 -> 0 | AR21: 200 | AS21: 0 | AT21: =VLOOKUP(C21,'[1]5月25-5月31日汇总'!$C:$I,7,0) -> 0 | AU21: =VLOOKUP(C21,'[1]6月汇总'!$C:$I,7,0) -> 0 | AV21: =SUM(AS21:AU21) -> 0 | AW21: =VLOOKUP(C21,[2]两年对比终版!$A:$X,23,0) -> 0 | AY21: =AV21/AR21 -> 0 | AZ21: 190 | BA21: 0 | BD21: =SUM(BA21:BC21) -> 0 | BE21: =VLOOKUP(C21,[2]两年对比终版!$A:$AD,30,0) -> 0 | BF21: =BD21/AZ21 -> 0
A22: 17 | B22: B | C22: 马来西亚 | D22: 109 | E22: 48 | F22: =VLOOKUP(C22,'[1]5月25-5月31日汇总'!$C:$D,2,0) -> 0 | G22: =VLOOKUP(C22,'[1]6月汇总'!$C:$D,2,0) -> 2 | H22: =SUM(E22:G22) -> 50 | I22: =VLOOKUP(C22,[2]两年对比终版!$A:$C,3,0) -> 66 | K22: =H22/D22 -> 0.4587156 | L22: 900 | M22: 788.548 | N22: =VLOOKUP(C22,'[1]5月25-5月31日汇总'!$C:$E,3,0) -> 0 | O22: =VLOOKUP(C22,'[1]6月汇总'!$C:$E,3,0) -> 47 | P22: =SUM(M22:O22) -> 835.548 | Q22: =VLOOKUP(C22,[2]两年对比终版!$A:$F,6,0) -> 1463.75 | S22: =P22/L22 -> 0.92838667 | T22: 61 | U22: 19 | V22: =VLOOKUP(C22,'[1]5月25-5月31日汇总'!$C:$F,4,0) -> 0 | W22: =VLOOKUP(C22,'[1]6月汇总'!$C:$F,4,0) -> 9 | X22: =SUM(U22:W22) -> 28 | Y22: =VLOOKUP(C22,[2]两年对比终版!$A:$N,14,0) -> 16 | AA22: =X22/T22 -> 0.45901639 | AB22: 521 | AC22: 403.57 | AD22: =VLOOKUP(C22,'[1]5月25-5月31日汇总'!$C:$G,5,0) -> 0 | AE22: =VLOOKUP(C22,'[1]6月汇总'!$C:$G,5,0) -> 200 | AF22: =SUM(AC22:AE22) -> 603.57 | AG22: =VLOOKUP(C22,[2]两年对比终版!$A:$Q,17,0) -> 132.085 | AI22: =AF22/AB22 -> 1.1584837 | AJ22: 61 | AK22: 16 | AL22: =VLOOKUP(C22,'[1]5月25-5月31日汇总'!$C:$H,6,0) -> 0 | AM22: =VLOOKUP(C22,'[1]6月汇总'!$C:$I,6,0) -> 12 | AN22: =SUM(AK22:AM22) -> 28 | AO22: =VLOOKUP(C22,[2]两年对比终版!$A:$T,20,0) -> 17 | AQ22: =AN22/AJ22 -> 0.45901639 | AR22: 521 | AS22: 246.33 | AT22: =VLOOKUP(C22,'[1]5月25-5月31日汇总'!$C:$I,7,0) -> 0 | AU22: =VLOOKUP(C22,'[1]6月汇总'!$C:$I,7,0) -> 260 | AV22: =SUM(AS22:AU22) -> 506.33 | AW22: =VLOOKUP(C22,[2]两年对比终版!$A:$X,23,0) -> 140.475 | AY22: =AV22/AR22 -> 0.97184261 | AZ22: 495 | BA22: 71.5871 | BD22: =SUM(BA22:BC22) -> 71.5871 | BE22: =VLOOKUP(C22,[2]两年对比终版!$A:$AD,30,0) -> 225.57303 | BF22: =BD22/AZ22 -> 0.1446204
A23: 18 | B23: D | C23: 马尔代夫 | D23: 36 | E23: 29 | F23: =VLOOKUP(C23,'[1]5月25-5月31日汇总'!$C:$D,2,0) -> 0 | G23: =VLOOKUP(C23,'[1]6月汇总'!$C:$D,2,0) -> 4 | H23: =SUM(E23:G23) -> 33 | I23: =VLOOKUP(C23,[2]两年对比终版!$A:$C,3,0) -> 37 | K23: =H23/D23 -> 0.91666667 | L23: 630 | M23: 334.054 | N23: =VLOOKUP(C23,'[1]5月25-5月31日汇总'!$C:$E,3,0) -> 0 | O23: =VLOOKUP(C23,'[1]6月汇总'!$C:$E,3,0) -> 40 | P23: =SUM(M23:O23) -> 374.054 | Q23: =VLOOKUP(C23,[2]两年对比终版!$A:$F,6,0) -> 543.86292 | S23: =P23/L23 -> 0.59373651 | T23: 17 | U23: 6 | V23: =VLOOKUP(C23,'[1]5月25-5月31日汇总'!$C:$F,4,0) -> 0 | W23: =VLOOKUP(C23,'[1]6月汇总'!$C:$F,4,0) -> 2 | X23: =SUM(U23:W23) -> 8 | Y23: =VLOOKUP(C23,[2]两年对比终版!$A:$N,14,0) -> 7 | AA23: =X23/T23 -> 0.47058824 | AB23: 264.163 | AC23: 61.2354 | AD23: =VLOOKUP(C23,'[1]5月25-5月31日汇总'!$C:$G,5,0) -> 0 | AE23: =VLOOKUP(C23,'[1]6月汇总'!$C:$G,5,0) -> 20 | AF23: =SUM(AC23:AE23) -> 81.2354 | AG23: =VLOOKUP(C23,[2]两年对比终版!$A:$Q,17,0) -> 96.411317 | AI23: =AF23/AB23 -> 0.30751998 | AJ23: 17 | AK23: 3 | AL23: =VLOOKUP(C23,'[1]5月25-5月31日汇总'!$C:$H,6,0) -> 1 | AM23: =VLOOKUP(C23,'[1]6月汇总'!$C:$I,6,0) -> 4 | AN23: =SUM(AK23:AM23) -> 8 | AO23: =VLOOKUP(C23,[2]两年对比终版!$A:$T,20,0) -> 16 | AQ23: =AN23/AJ23 -> 0.47058824 | AR23: 264.163 | AS23: 30.5291 | AT23: =VLOOKUP(C23,'[1]5月25-5月31日汇总'!$C:$I,7,0) -> 12 | AU23: =VLOOKUP(C23,'[1]6月汇总'!$C:$I,7,0) -> 30 | AV23: =SUM(AS23:AU23) -> 72.5291 | AW23: =VLOOKUP(C23,[2]两年对比终版!$A:$X,23,0) -> 3354.156 | AY23: =AV23/AR23 -> 0.27456192 | AZ23: 251 | BA23: 38.246 | BD23: =SUM(BA23:BC23) -> 38.246 | BE23: =VLOOKUP(C23,[2]两年对比终版!$A:$AD,30,0) -> 3983.1595 | BF23: =BD23/AZ23 -> 0.1523745
A24: 19 | B24: D | C24: 香港-台湾 | D24: 20 | E24: 8 | F24: =VLOOKUP(C24,'[1]5月25-5月31日汇总'!$C:$D,2,0) -> 0 | G24: =VLOOKUP(C24,'[1]6月汇总'!$C:$D,2,0) -> 10 | H24: =SUM(E24:G24) -> 18 | I24: =VLOOKUP(C24,[2]两年对比终版!$A:$C,3,0) -> 0 | K24: =H24/D24 -> 0.9 | L24: 200 | M24: 50.38 | N24: =VLOOKUP(C24,'[1]5月25-5月31日汇总'!$C:$E,3,0) -> 0 | O24: =VLOOKUP(C24,'[1]6月汇总'!$C:$E,3,0) -> 50 | P24: =SUM(M24:O24) -> 100.38 | Q24: =VLOOKUP(C24,[2]两年对比终版!$A:$F,6,0) -> 0 | S24: =P24/L24 -> 0.5019 | T24: 15 | U24: 0 | V24: =VLOOKUP(C24,'[1]5月25-5月31日汇总'!$C:$F,4,0) -> 0 | W24: =VLOOKUP(C24,'[1]6月汇总'!$C:$F,4,0) -> 0 | X24: =SUM(U24:W24) -> 0 | Y24: =VLOOKUP(C24,[2]两年对比终版!$A:$N,14,0) -> 0 | AA24: =X24/T24 -> 0 | AB24: 200 | AC24: 0 | AD24: =VLOOKUP(C24,'[1]5月25-5月31日汇总'!$C:$G,5,0) -> 0 | AE24: =VLOOKUP(C24,'[1]6月汇总'!$C:$G,5,0) -> 0 | AF24: =SUM(AC24:AE24) -> 0 | AG24: =VLOOKUP(C24,[2]两年对比终版!$A:$Q,17,0) -> 0 | AI24: =AF24/AB24 -> 0 | AJ24: 15 | AK24: 0 | AL24: =VLOOKUP(C24,'[1]5月25-5月31日汇总'!$C:$H,6,0) -> 0 | AM24: =VLOOKUP(C24,'[1]6月汇总'!$C:$I,6,0) -> 0 | AN24: =SUM(AK24:AM24) -> 0 | AO24: =VLOOKUP(C24,[2]两年对比终版!$A:$T,20,0) -> 0 | AQ24: =AN24/AJ24 -> 0 | AR24: 200 | AS24: 0 | AT24: =VLOOKUP(C24,'[1]5月25-5月31日汇总'!$C:$I,7,0) -> 0 | AU24: =VLOOKUP(C24,'[1]6月汇总'!$C:$I,7,0) -> 0 | AV24: =SUM(AS24:AU24) -> 0 | AW24: =VLOOKUP(C24,[2]两年对比终版!$A:$X,23,0) -> 0 | AY24: =AV24/AR24 -> 0 | AZ24: 190 | BA24: 0 | BD24: =SUM(BA24:BC24) -> 0 | BE24: =VLOOKUP(C24,[2]两年对比终版!$A:$AD,30,0) -> 0 | BF24: =BD24/AZ24 -> 0
A25: 亚洲1合计 | D25: =SUM(D16:D24) -> 1328 | E25: =SUM(E16:E24) -> 508 | F25: =SUM(F16:F24) -> 100 | G25: =SUM(G16:G24) -> 158 | H25: =SUM(H16:H24) -> 766 | I25: =SUM(I16:I24) -> 740 | J25: =(H25-I25)/I25 -> 0.035135135 | K25: =H25/D25 -> 0.57680723 | L25: =SUM(L16:L24) -> 31010 | M25: =SUM(M16:M24) -> 9415.4924 | N25: =SUM(N16:N24) -> 3637 | O25: =SUM(O16:O24) -> 2425 | P25: =SUM(P16:P24) -> 15477.492 | Q25: =SUM(Q16:Q24) -> 14019.692 | R25: =(P25-Q25)/Q25 -> 0.10398232 | S25: =P25/L25 -> 0.49911294 | T25: =SUM(T16:T24) -> 583 | U25: =SUM(U16:U24) -> 190 | V25: =SUM(V16:V24) -> 1 | W25: =SUM(W16:W24) -> 41 | X25: =SUM(X16:X24) -> 232 | Y25: =SUM(Y16:Y24) -> 233 | Z25: =(X25-Y25)/Y25 -> -0.0042918455 | AA25: =X25/T25 -> 0.39794168 | AB25: =SUM(AB16:AB24) -> 12602.326 | AC25: =SUM(AC16:AC24) -> 6938.3419 | AD25: =SUM(AD16:AD24) -> 15.54 | AE25: =SUM(AE16:AE24) -> 786.34 | AF25: =SUM(AF16:AF24) -> 7740.2219 | AG25: =SUM(AG16:AG24) -> 6176.6144 | AH25: =(AF25-AG25)/AG25 -> 0.2531496 | AI25: =AF25/AB25 -> 0.61418994 | AJ25: =SUM(AJ16:AJ24) -> 583 | AK25: =SUM(AK16:AK24) -> 222 | AL25: =SUM(AL16:AL24) -> 8 | AM25: =SUM(AM16:AM24) -> 52 | AN25: =SUM(AN16:AN24) -> 282 | AO25: =SUM(AO16:AO24) -> 94 | AP25: =(AN25-AO25)/AO25 -> 2 | AQ25: =AN25/AJ25 -> 0.48370497 | AR25: =SUM(AR16:AR24) -> 12602.326 | AS25: =SUM(AS16:AS24) -> 7700.6663 | AT25: =SUM(AT16:AT24) -> 192 | AU25: =SUM(AU16:AU24) -> 1077.73 | AV25: =SUM(AV16:AV24) -> 8970.3963 | AW25: =SUM(AW16:AW24) -> 4729.57 | AX25: =(AV25-AW25)/AW25 -> 0.89666215 | AY25: =AV25/AR25 -> 0.71180481 | AZ25: =SUM(AZ16:AZ24) -> 11972 | BA25: =SUM(BA16:BA24) -> 745.1262 | BB25: =SUM(BB16:BB24) -> 0 | BC25: =SUM(BC16:BC24) -> 0 | BD25: =SUM(BD16:BD24) -> 745.1262 | BE25: =SUM(BE16:BE24) -> 5741.5051 | BF25: =BD25/AZ25 -> 0.062239075
A26: 20 | B26: C | C26: 越南-2 | D26: 235 | E26: 76 | F26: =VLOOKUP(C26,'[1]5月25-5月31日汇总'!$C:$D,2,0) -> 0 | G26: =VLOOKUP(C26,'[1]6月汇总'!$C:$D,2,0) -> 12 | H26: =SUM(E26:G26) -> 88 | I26: =VLOOKUP(C26,[2]两年对比终版!$A:$C,3,0) -> 52 | K26: =H26/D26 -> 0.37446809 | L26: 1673.35 | M26: 520.729 | N26: =VLOOKUP(C26,'[1]5月25-5月31日汇总'!$C:$E,3,0) -> 0 | O26: =VLOOKUP(C26,'[1]6月汇总'!$C:$E,3,0) -> 60 | P26: =SUM(M26:O26) -> 580.729 | Q26: =VLOOKUP(C26,[2]两年对比终版!$A:$F,6,0) -> 393.58625 | S26: =P26/L26 -> 0.34704575 | T26: 63 | U26: 12 | V26: =VLOOKUP(C26,'[1]5月25-5月31日汇总'!$C:$F,4,0) -> 0 | W26: =VLOOKUP(C26,'[1]6月汇总'!$C:$F,4,0) -> 6 | X26: =SUM(U26:W26) -> 18 | Y26: =VLOOKUP(C26,[2]两年对比终版!$A:$N,14,0) -> 22 | AA26: =X26/T26 -> 0.28571429 | AB26: 683 | AC26: 65.701 | AD26: =VLOOKUP(C26,'[1]5月25-5月31日汇总'!$C:$G,5,0) -> 0 | AE26: =VLOOKUP(C26,'[1]6月汇总'!$C:$G,5,0) -> 30 | AF26: =SUM(AC26:AE26) -> 95.701 | AG26: =VLOOKUP(C26,[2]两年对比终版!$A:$Q,17,0) -> 178.45729 | AI26: =AF26/AB26 -> 0.14011859 | AJ26: 63 | AK26: 14 | AL26: =VLOOKUP(C26,'[1]5月25-5月31日汇总'!$C:$H,6,0) -> 2 | AM26: =VLOOKUP(C26,'[1]6月汇总'!$C:$I,6,0) -> 2 | AN26: =SUM(AK26:AM26) -> 18 | AO26: =VLOOKUP(C26,[2]两年对比终版!$A:$T,20,0) -> 29 | AQ26: =AN26/AJ26 -> 0.28571429 | AR26: 683 | AS26: 90.6057 | AT26: =VLOOKUP(C26,'[1]5月25-5月31日汇总'!$C:$I,7,0) -> 12.24 | AU26: =VLOOKUP(C26,'[1]6月汇总'!$C:$I,7,0) -> 10 | AV26: =SUM(AS26:AU26) -> 112.8457 | AW26: =VLOOKUP(C26,[2]两年对比终版!$A:$X,23,0) -> 228.72333 | AY26: =AV26/AR26 -> 0.16522064 | AZ26: 649 | BA26: 53.013 | BD26: =SUM(BA26:BC26) -> 53.013 | BE26: =VLOOKUP(C26,[2]两年对比终版!$A:$AD,30,0) -> 218.19091 | BF26: =BD26/AZ26 -> 0.081684129
A27: 21 | B27: B | C27: 印度公建 | D27: 66 | E27: 14 | F27: =VLOOKUP(C27,'[1]5月25-5月31日汇总'!$C:$D,2,0) -> 2 | G27: =VLOOKUP(C27,'[1]6月汇总'!$C:$D,2,0) -> 3 | H27: =SUM(E27:G27) -> 19 | I27: =VLOOKUP(C27,[2]两年对比终版!$A:$C,3,0) -> 23 | K27: =H27/D27 -> 0.28787879 | L27: 930 | M27: 287.013 | N27: =VLOOKUP(C27,'[1]5月25-5月31日汇总'!$C:$E,3,0) -> 26.96 | O27: =VLOOKUP(C27,'[1]6月汇总'!$C:$E,3,0) -> 80.88 | P27: =SUM(M27:O27) -> 394.853 | Q27: =VLOOKUP(C27,[2]两年对比终版!$A:$F,6,0) -> 773.87896 | S27: =P27/L27 -> 0.42457312 | T27: 27 | U27: 6 | V27: =VLOOKUP(C27,'[1]5月25-5月31日汇总'!$C:$F,4,0) -> 1 | W27: =VLOOKUP(C27,'[1]6月汇总'!$C:$F,4,0) -> 2 | X27: =SUM(U27:W27) -> 9 | Y27: =VLOOKUP(C27,[2]两年对比终版!$A:$N,14,0) -> 3 | AA27: =X27/T27 -> 0.33333333 | AB27: 396.245 | AC27: 68.5136 | AD27: =VLOOKUP(C27,'[1]5月25-5月31日汇总'!$C:$G,5,0) -> 31.5 | AE27: =VLOOKUP(C27,'[1]6月汇总'!$C:$G,5,0) -> 26.86 | AF27: =SUM(AC27:AE27) -> 126.8736 | AG27: =VLOOKUP(C27,[2]两年对比终版!$A:$Q,17,0) -> 44.012007 | AI27: =AF27/AB27 -> 0.32018978 | AJ27: 27 | AK27: 5 | AL27: =VLOOKUP(C27,'[1]5月25-5月31日汇总'!$C:$H,6,0) -> 0 | AM27: =VLOOKUP(C27,'[1]6月汇总'!$C:$I,6,0) -> 5 | AN27: =SUM(AK27:AM27) -> 10 | AO27: =VLOOKUP(C27,[2]两年对比终版!$A:$T,20,0) -> 0 | AQ27: =AN27/AJ27 -> 0.37037037 | AR27: 396.245 | AS27: 78.4854 | AT27: =VLOOKUP(C27,'[1]5月25-5月31日汇总'!$C:$I,7,0) -> 0 | AU27: =VLOOKUP(C27,'[1]6月汇总'!$C:$I,7,0) -> 90.170706 | AV27: =SUM(AS27:AU27) -> 168.65611 | AW27: =VLOOKUP(C27,[2]两年对比终版!$A:$X,23,0) -> 0 | AY27: =AV27/AR27 -> 0.42563592 | AZ27: 376 | BA27: 6.95685 | BD27: =SUM(BA27:BC27) -> 6.95685 | BE27: =VLOOKUP(C27,[2]两年对比终版!$A:$AD,30,0) -> 1159.2175 | BF27: =BD27/AZ27 -> 0.018502261
A28: 22 | B28: D | C28: 巴基斯坦 | D28: 87 | E28: 32 | F28: =VLOOKUP(C28,'[1]5月25-5月31日汇总'!$C:$D,2,0) -> 0 | G28: =VLOOKUP(C28,'[1]6月汇总'!$C:$D,2,0) -> 6 | H28: =SUM(E28:G28) -> 38 | I28: =VLOOKUP(C28,[2]两年对比终版!$A:$C,3,0) -> 8 | K28: =H28/D28 -> 0.43678161 | L28: 688 | M28: 255.136 | N28: =VLOOKUP(C28,'[1]5月25-5月31日汇总'!$C:$E,3,0) -> 0 | O28: =VLOOKUP(C28,'[1]6月汇总'!$C:$E,3,0) -> 44.88 | P28: =SUM(M28:O28) -> 300.016 | Q28: =VLOOKUP(C28,[2]两年对比终版!$A:$F,6,0) -> 74.024224 | S28: =P28/L28 -> 0.43606977 | T28: 32 | U28: 4 | V28: =VLOOKUP(C28,'[1]5月25-5月31日汇总'!$C:$F,4,0) -> 0 | W28: =VLOOKUP(C28,'[1]6月汇总'!$C:$F,4,0) -> 2 | X28: =SUM(U28:W28) -> 6 | Y28: =VLOOKUP(C28,[2]两年对比终版!$A:$N,14,0) -> 2 | AA28: =X28/T28 -> 0.1875 | AB28: 265 | AC28: 23.2504 | AD28: =VLOOKUP(C28,'[1]5月25-5月31日汇总'!$C:$G,5,0) -> 0 | AE28: =VLOOKUP(C28,'[1]6月汇总'!$C:$G,5,0) -> 14.96 | AF28: =SUM(AC28:AE28) -> 38.2104 | AG28: =VLOOKUP(C28,[2]两年对比终版!$A:$Q,17,0) -> 6.912768 | AI28: =AF28/AB28 -> 0.14419019 | AJ28: 32 | AK28: 6 | AL28: =VLOOKUP(C28,'[1]5月25-5月31日汇总'!$C:$H,6,0) -> 1 | AM28: =VLOOKUP(C28,'[1]6月汇总'!$C:$I,6,0) -> 2 | AN28: =SUM(AK28:AM28) -> 9 | AO28: =VLOOKUP(C28,[2]两年对比终版!$A:$T,20,0) -> 0 | AQ28: =AN28/AJ28 -> 0.28125 | AR28: 265 | AS28: 45.7169 | AT28: =VLOOKUP(C28,'[1]5月25-5月31日汇总'!$C:$I,7,0) -> 7.75 | AU28: =VLOOKUP(C28,'[1]6月汇总'!$C:$I,7,0) -> 14.96 | AV28: =SUM(AS28:AU28) -> 68.4269 | AW28: =VLOOKUP(C28,[2]两年对比终版!$A:$X,23,0) -> 0 | AY28: =AV28/AR28 -> 0.25821472 | AZ28: 252 | BA28: 21.3624 | BD28: =SUM(BA28:BC28) -> 21.3624 | BE28: =VLOOKUP(C28,[2]两年对比终版!$A:$AD,30,0) -> 0 | BF28: =BD28/AZ28 -> 0.084771429
A29: 23 | B29: B | C29: 孟加拉-1 | D29: 238 | E29: 43 | F29: =VLOOKUP(C29,'[1]5月25-5月31日汇总'!$C:$D,2,0) -> 17 | G29: =VLOOKUP(C29,'[1]6月汇总'!$C:$D,2,0) -> 35 | H29: =SUM(E29:G29) -> 95 | I29: =VLOOKUP(C29,[2]两年对比终版!$A:$C,3,0) -> 128 | K29: =H29/D29 -> 0.39915966 | L29: 1768.9 | M29: 443.528 | N29: =VLOOKUP(C29,'[1]5月25-5月31日汇总'!$C:$E,3,0) -> 136.68 | O29: =VLOOKUP(C29,'[1]6月汇总'!$C:$E,3,0) -> 293.12 | P29: =SUM(M29:O29) -> 873.328 | Q29: =VLOOKUP(C29,[2]两年对比终版!$A:$F,6,0) -> 1268.9125 | S29: =P29/L29 -> 0.49371248 | T29: 73 | U29: 16 | V29: =VLOOKUP(C29,'[1]5月25-5月31日汇总'!$C:$F,4,0) -> 4 | W29: =VLOOKUP(C29,'[1]6月汇总'!$C:$F,4,0) -> 5 | X29: =SUM(U29:W29) -> 25 | Y29: =VLOOKUP(C29,[2]两年对比终版!$A:$N,14,0) -> 27 | AA29: =X29/T29 -> 0.34246575 | AB29: 722 | AC29: 129.646 | AD29: =VLOOKUP(C29,'[1]5月25-5月31日汇总'!$C:$G,5,0) -> 29.07 | AE29: =VLOOKUP(C29,'[1]6月汇总'!$C:$G,5,0) -> 36.85 | AF29: =SUM(AC29:AE29) -> 195.566 | AG29: =VLOOKUP(C29,[2]两年对比终版!$A:$Q,17,0) -> 224.14553 | AI29: =AF29/AB29 -> 0.27086704 | AJ29: 73 | AK29: 16 | AL29: =VLOOKUP(C29,'[1]5月25-5月31日汇总'!$C:$H,6,0) -> 1 | AM29: =VLOOKUP(C29,'[1]6月汇总'!$C:$I,6,0) -> 4 | AN29: =SUM(AK29:AM29) -> 21 | AO29: =VLOOKUP(C29,[2]两年对比终版!$A:$T,20,0) -> 20 | AQ29: =AN29/AJ29 -> 0.28767123 | AR29: 722 | AS29: 129.688 | AT29: =VLOOKUP(C29,'[1]5月25-5月31日汇总'!$C:$I,7,0) -> 7.16 | AU29: =VLOOKUP(C29,'[1]6月汇总'!$C:$I,7,0) -> 29.07 | AV29: =SUM(AS29:AU29) -> 165.918 | AW29: =VLOOKUP(C29,[2]两年对比终版!$A:$X,23,0) -> 167.86765 | AY29: =AV29/AR29 -> 0.22980332 | AZ29: 686 | BA29: 29.6454 | BD29: =SUM(BA29:BC29) -> 29.6454 | BE29: =VLOOKUP(C29,[2]两年对比终版!$A:$AD,30,0) -> 153.92602 | BF29: =BD29/AZ29 -> 0.043214869
A30: 24 | B30: C | C30: 澳大利亚 | D30: 136 | E30: 23 | F30: =VLOOKUP(C30,'[1]5月25-5月31日汇总'!$C:$D,2,0) -> 1 | G30: =VLOOKUP(C30,'[1]6月汇总'!$C:$D,2,0) -> 5 | H30: =SUM(E30:G30) -> 29 | I30: =VLOOKUP(C30,[2]两年对比终版!$A:$C,3,0) -> 39 | K30: =H30/D30 -> 0.21323529 | L30: 964 | M30: 320.911 | N30: =VLOOKUP(C30,'[1]5月25-5月31日汇总'!$C:$E,3,0) -> 11.42 | O30: =VLOOKUP(C30,'[1]6月汇总'!$C:$E,3,0) -> 80 | P30: =SUM(M30:O30) -> 412.331 | Q30: =VLOOKUP(C30,[2]两年对比终版!$A:$F,6,0) -> 592.24855 | S30: =P30/L30 -> 0.42772925 | T30: 32 | U30: 8 | V30: =VLOOKUP(C30,'[1]5月25-5月31日汇总'!$C:$F,4,0) -> 1 | W30: =VLOOKUP(C30,'[1]6月汇总'!$C:$F,4,0) -> 3 | X30: =SUM(U30:W30) -> 12 | Y30: =VLOOKUP(C30,[2]两年对比终版!$A:$N,14,0) -> 2 | AA30: =X30/T30 -> 0.375 | AB30: 380 | AC30: 88.3023 | AD30: =VLOOKUP(C30,'[1]5月25-5月31日汇总'!$C:$G,5,0) -> 11.42 | AE30: =VLOOKUP(C30,'[1]6月汇总'!$C:$G,5,0) -> 30 | AF30: =SUM(AC30:AE30) -> 129.7223 | AG30: =VLOOKUP(C30,[2]两年对比终版!$A:$Q,17,0) -> 29.534539 | AI30: =AF30/AB30 -> 0.34137447 | AJ30: 32 | AK30: 3 | AL30: =VLOOKUP(C30,'[1]5月25-5月31日汇总'!$C:$H,6,0) -> 4 | AM30: =VLOOKUP(C30,'[1]6月汇总'!$C:$I,6,0) -> 4 | AN30: =SUM(AK30:AM30) -> 11 | AO30: =VLOOKUP(C30,[2]两年对比终版!$A:$T,20,0) -> 9 | AQ30: =AN30/AJ30 -> 0.34375 | AR30: 380 | AS30: 53.7101 | AT30: =VLOOKUP(C30,'[1]5月25-5月31日汇总'!$C:$I,7,0) -> 24.43 | AU30: =VLOOKUP(C30,'[1]6月汇总'!$C:$I,7,0) -> 40 | AV30: =SUM(AS30:AU30) -> 118.1401 | AW30: =VLOOKUP(C30,[2]两年对比终版!$A:$X,23,0) -> 179.53971 | AY30: =AV30/AR30 -> 0.310895 | AZ30: 360 | BA30: 28.2947 | BD30: =SUM(BA30:BC30) -> 28.2947 | BE30: =VLOOKUP(C30,[2]两年对比终版!$A:$AD,30,0) -> 245.62006 | BF30: =BD30/AZ30 -> 0.078596389
A31: 25 | B31: C | C31: 菲律宾 | D31: 69 | E31: 26 | F31: =VLOOKUP(C31,'[1]5月25-5月31日汇总'!$C:$D,2,0) -> 0 | G31: =VLOOKUP(C31,'[1]6月汇总'!$C:$D,2,0) -> 9 | H31: =SUM(E31:G31) -> 35 | I31: =VLOOKUP(C31,[2]两年对比终版!$A:$C,3,0) -> 0 | K31: =H31/D31 -> 0.50724638 | L31: 710 | M31: 214.36 | N31: =VLOOKUP(C31,'[1]5月25-5月31日汇总'!$C:$E,3,0) -> 0 | O31: =VLOOKUP(C31,'[1]6月汇总'!$C:$E,3,0) -> 100 | P31: =SUM(M31:O31) -> 314.36 | Q31: =VLOOKUP(C31,[2]两年对比终版!$A:$F,6,0) -> 0 | S31: =P31/L31 -> 0.44276056 | T31: 27 | U31: 0 | V31: =VLOOKUP(C31,'[1]5月25-5月31日汇总'!$C:$F,4,0) -> 0 | W31: =VLOOKUP(C31,'[1]6月汇总'!$C:$F,4,0) -> 0 | X31: =SUM(U31:W31) -> 0 | Y31: =VLOOKUP(C31,[2]两年对比终版!$A:$N,14,0) -> 0 | AA31: =X31/T31 -> 0 | AB31: 350 | AC31: 0 | AD31: =VLOOKUP(C31,'[1]5月25-5月31日汇总'!$C:$G,5,0) -> 0 | AE31: =VLOOKUP(C31,'[1]6月汇总'!$C:$G,5,0) -> 0 | AF31: =SUM(AC31:AE31) -> 0 | AG31: =VLOOKUP(C31,[2]两年对比终版!$A:$Q,17,0) -> 0 | AI31: =AF31/AB31 -> 0 | AJ31: 27 | AK31: 0 | AL31: =VLOOKUP(C31,'[1]5月25-5月31日汇总'!$C:$H,6,0) -> 0 | AM31: =VLOOKUP(C31,'[1]6月汇总'!$C:$I,6,0) -> 0 | AN31: =SUM(AK31:AM31) -> 0 | AO31: =VLOOKUP(C31,[2]两年对比终版!$A:$T,20,0) -> 0 | AQ31: =AN31/AJ31 -> 0 | AR31: 350 | AS31: 0 | AT31: =VLOOKUP(C31,'[1]5月25-5月31日汇总'!$C:$I,7,0) -> 0 | AU31: =VLOOKUP(C31,'[1]6月汇总'!$C:$I,7,0) -> 0 | AV31: =SUM(AS31:AU31) -> 0 | AW31: =VLOOKUP(C31,[2]两年对比终版!$A:$X,23,0) -> 0 | AY31: =AV31/AR31 -> 0 | AZ31: 333 | BA31: 0 | BD31: =SUM(BA31:BC31) -> 0 | BE31: =VLOOKUP(C31,[2]两年对比终版!$A:$AD,30,0) -> 0 | BF31: =BD31/AZ31 -> 0
A32: 26 | B32: C | C32: 印尼-1 | D32: 263 | E32: 48 | F32: =VLOOKUP(C32,'[1]5月25-5月31日汇总'!$C:$D,2,0) -> 0 | G32: =VLOOKUP(C32,'[1]6月汇总'!$C:$D,2,0) -> 11 | H32: =SUM(E32:G32) -> 59 | I32: =VLOOKUP(C32,[2]两年对比终版!$A:$C,3,0) -> 97 | K32: =H32/D32 -> 0.2243346 | L32: 1640 | M32: 499.416 | N32: =VLOOKUP(C32,'[1]5月25-5月31日汇总'!$C:$E,3,0) -> 0 | O32: =VLOOKUP(C32,'[1]6月汇总'!$C:$E,3,0) -> 160 | P32: =SUM(M32:O32) -> 659.416 | Q32: =VLOOKUP(C32,[2]两年对比终版!$A:$F,6,0) -> 1049.8087 | S32: =P32/L32 -> 0.40208293 | T32: 42 | U32: 8 | V32: =VLOOKUP(C32,'[1]5月25-5月31日汇总'!$C:$F,4,0) -> 0 | W32: =VLOOKUP(C32,'[1]6月汇总'!$C:$F,4,0) -> 3 | X32: =SUM(U32:W32) -> 11 | Y32: =VLOOKUP(C32,[2]两年对比终版!$A:$N,14,0) -> 1 | AA32: =X32/T32 -> 0.26190476 | AB32: 400 | AC32: 77.5997 | AD32: =VLOOKUP(C32,'[1]5月25-5月31日汇总'!$C:$G,5,0) -> 0 | AE32: =VLOOKUP(C32,'[1]6月汇总'!$C:$G,5,0) -> 32 | AF32: =SUM(AC32:AE32) -> 109.5997 | AG32: =VLOOKUP(C32,[2]两年对比终版!$A:$Q,17,0) -> 7.43 | AI32: =AF32/AB32 -> 0.27399925 | AJ32: 42 | AK32: 8 | AL32: =VLOOKUP(C32,'[1]5月25-5月31日汇总'!$C:$H,6,0) -> 0 | AM32: =VLOOKUP(C32,'[1]6月汇总'!$C:$I,6,0) -> 3 | AN32: =SUM(AK32:AM32) -> 11 | AO32: =VLOOKUP(C32,[2]两年对比终版!$A:$T,20,0) -> 1 | AQ32: =AN32/AJ32 -> 0.26190476 | AR32: 400 | AS32: 77.5997 | AT32: =VLOOKUP(C32,'[1]5月25-5月31日汇总'!$C:$I,7,0) -> 0 | AU32: =VLOOKUP(C32,'[1]6月汇总'!$C:$I,7,0) -> 16 | AV32: =SUM(AS32:AU32) -> 93.5997 | AW32: =VLOOKUP(C32,[2]两年对比终版!$A:$X,23,0) -> 7.43 | AY32: =AV32/AR32 -> 0.23399925 | AZ32: 380 | BA32: 6.16148 | BD32: =SUM(BA32:BC32) -> 6.16148 | BE32: =VLOOKUP(C32,[2]两年对比终版!$A:$AD,30,0) -> 15.433404 | BF32: =BD32/AZ32 -> 0.016214421
A33: 27 | B33: B | C33: 越南-1（工厂） | D33: 148 | E33: 24 | F33: =VLOOKUP(C33,'[1]5月25-5月31日汇总'!$C:$D,2,0) -> 2 | G33: =VLOOKUP(C33,'[1]6月汇总'!$C:$D,2,0) -> 2 | H33: =SUM(E33:G33) -> 28 | I33: =VLOOKUP(C33,[2]两年对比终版!$A:$C,3,0) -> 10 | K33: =H33/D33 -> 0.18918919 | L33: 1470 | M33: 317.6 | N33: =VLOOKUP(C33,'[1]5月25-5月31日汇总'!$C:$E,3,0) -> 22.8 | O33: =VLOOKUP(C33,'[1]6月汇总'!$C:$E,3,0) -> 14 | P33: =SUM(M33:O33) -> 354.4 | Q33: =VLOOKUP(C33,[2]两年对比终版!$A:$F,6,0) -> 106.42549 | S33: =P33/L33 -> 0.24108844 | T33: 55 | U33: 11 | V33: =VLOOKUP(C33,'[1]5月25-5月31日汇总'!$C:$F,4,0) -> 2 | W33: =VLOOKUP(C33,'[1]6月汇总'!$C:$F,4,0) -> 2 | X33: =SUM(U33:W33) -> 15 | Y33: =VLOOKUP(C33,[2]两年对比终版!$A:$N,14,0) -> 1 | AA33: =X33/T33 -> 0.27272727 | AB33: 600 | AC33: 80.6616 | AD33: =VLOOKUP(C33,'[1]5月25-5月31日汇总'!$C:$G,5,0) -> 22.8 | AE33: =VLOOKUP(C33,'[1]6月汇总'!$C:$G,5,0) -> 14 | AF33: =SUM(AC33:AE33) -> 117.4616 | AG33: =VLOOKUP(C33,[2]两年对比终版!$A:$Q,17,0) -> 7.56084 | AI33: =AF33/AB33 -> 0.19576933 | AJ33: 55 | AK33: 10 | AL33: =VLOOKUP(C33,'[1]5月25-5月31日汇总'!$C:$H,6,0) -> 0 | AM33: =VLOOKUP(C33,'[1]6月汇总'!$C:$I,6,0) -> 1 | AN33: =SUM(AK33:AM33) -> 11 | AO33: =VLOOKUP(C33,[2]两年对比终版!$A:$T,20,0) -> 0 | AQ33: =AN33/AJ33 -> 0.2 | AR33: 600 | AS33: 74.2168 | AT33: =VLOOKUP(C33,'[1]5月25-5月31日汇总'!$C:$I,7,0) -> 0 | AU33: =VLOOKUP(C33,'[1]6月汇总'!$C:$I,7,0) -> 7.21 | AV33: =SUM(AS33:AU33) -> 81.4268 | AW33: =VLOOKUP(C33,[2]两年对比终版!$A:$X,23,0) -> 0 | AY33: =AV33/AR33 -> 0.13571133 | AZ33: 570 | BA33: 63.6724 | BD33: =SUM(BA33:BC33) -> 63.6724 | BE33: =VLOOKUP(C33,[2]两年对比终版!$A:$AD,30,0) -> 2.1891039 | BF33: =BD33/AZ33 -> 0.11170596
A34: 28 | B34: A | C34: 印度私营 | D34: 246 | E34: 88 | F34: =VLOOKUP(C34,'[1]5月25-5月31日汇总'!$C:$D,2,0) -> 3 | G34: =VLOOKUP(C34,'[1]6月汇总'!$C:$D,2,0) -> 16 | H34: =SUM(E34:G34) -> 107 | I34: =VLOOKUP(C34,[2]两年对比终版!$A:$C,3,0) -> 110 | K34: =H34/D34 -> 0.43495935 | L34: 2934 | M34: 1103.64 | N34: =VLOOKUP(C34,'[1]5月25-5月31日汇总'!$C:$E,3,0) -> 34 | O34: =VLOOKUP(C34,'[1]6月汇总'!$C:$E,3,0) -> 204.55 | P34: =SUM(M34:O34) -> 1342.19 | Q34: =VLOOKUP(C34,[2]两年对比终版!$A:$F,6,0) -> 1592.6828 | S34: =P34/L34 -> 0.4574608 | T34: 81 | U34: 24 | V34: =VLOOKUP(C34,'[1]5月25-5月31日汇总'!$C:$F,4,0) -> 1 | W34: =VLOOKUP(C34,'[1]6月汇总'!$C:$F,4,0) -> 16 | X34: =SUM(U34:W34) -> 41 | Y34: =VLOOKUP(C34,[2]两年对比终版!$A:$N,14,0) -> 30 | AA34: =X34/T34 -> 0.50617284 | AB34: 1600 | AC34: 274.693 | AD34: =VLOOKUP(C34,'[1]5月25-5月31日汇总'!$C:$G,5,0) -> 37.81 | AE34: =VLOOKUP(C34,'[1]6月汇总'!$C:$G,5,0) -> 204.55 | AF34: =SUM(AC34:AE34) -> 517.053 | AG34: =VLOOKUP(C34,[2]两年对比终版!$A:$Q,17,0) -> 723.49246 | AI34: =AF34/AB34 -> 0.32315813 | AJ34: 81 | AK34: 6 | AL34: =VLOOKUP(C34,'[1]5月25-5月31日汇总'!$C:$H,6,0) -> 4 | AM34: =VLOOKUP(C34,'[1]6月汇总'!$C:$I,6,0) -> 9 | AN34: =SUM(AK34:AM34) -> 19 | AO34: =VLOOKUP(C34,[2]两年对比终版!$A:$T,20,0) -> 19 | AQ34: =AN34/AJ34 -> 0.2345679 | AR34: 1600 | AS34: 78.962 | AT34: =VLOOKUP(C34,'[1]5月25-5月31日汇总'!$C:$I,7,0) -> 25.91 | AU34: =VLOOKUP(C34,'[1]6月汇总'!$C:$I,7,0) -> 82.28 | AV34: =SUM(AS34:AU34) -> 187.152 | AW34: =VLOOKUP(C34,[2]两年对比终版!$A:$X,23,0) -> 329.72867 | AY34: =AV34/AR34 -> 0.11697 | AZ34: 1520 | BA34: 11.9345 | BD34: =SUM(BA34:BC34) -> 11.9345 | BE34: =VLOOKUP(C34,[2]两年对比终版!$A:$AD,30,0) -> 534.08012 | BF34: =BD34/AZ34 -> 0.0078516447
A35: 29 | B35: C | C35: 菲律宾-2 | D35: 85 | E35: 29 | F35: =VLOOKUP(C35,'[1]5月25-5月31日汇总'!$C:$D,2,0) -> 0 | G35: =VLOOKUP(C35,'[1]6月汇总'!$C:$D,2,0) -> 8 | H35: =SUM(E35:G35) -> 37 | I35: =VLOOKUP(C35,[2]两年对比终版!$A:$C,3,0) -> 0 | K35: =H35/D35 -> 0.43529412 | L35: 650 | M35: 214.149 | N35: =VLOOKUP(C35,'[1]5月25-5月31日汇总'!$C:$E,3,0) -> 0 | O35: =VLOOKUP(C35,'[1]6月汇总'!$C:$E,3,0) -> 70 | P35: =SUM(M35:O35) -> 284.149 | Q35: =VLOOKUP(C35,[2]两年对比终版!$A:$F,6,0) -> 0 | S35: =P35/L35 -> 0.43715231 | T35: 27 | U35: 1 | V35: =VLOOKUP(C35,'[1]5月25-5月31日汇总'!$C:$F,4,0) -> 0 | W35: =VLOOKUP(C35,'[1]6月汇总'!$C:$F,4,0) -> 0 | X35: =SUM(U35:W35) -> 1 | Y35: =VLOOKUP(C35,[2]两年对比终版!$A:$N,14,0) -> 0 | AA35: =X35/T35 -> 0.037037037 | AB35: 350 | AC35: 15.5997 | AD35: =VLOOKUP(C35,'[1]5月25-5月31日汇总'!$C:$G,5,0) -> 0 | AE35: =VLOOKUP(C35,'[1]6月汇总'!$C:$G,5,0) -> 0 | AF35: =SUM(AC35:AE35) -> 15.5997 | AG35: =VLOOKUP(C35,[2]两年对比终版!$A:$Q,17,0) -> 0 | AI35: =AF35/AB35 -> 0.044570571 | AJ35: 27 | AK35: 0 | AL35: =VLOOKUP(C35,'[1]5月25-5月31日汇总'!$C:$H,6,0) -> 0 | AM35: =VLOOKUP(C35,'[1]6月汇总'!$C:$I,6,0) -> 0 | AN35: =SUM(AK35:AM35) -> 0 | AO35: =VLOOKUP(C35,[2]两年对比终版!$A:$T,20,0) -> 0 | AQ35: =AN35/AJ35 -> 0 | AR35: 350 | AS35: 0 | AT35: =VLOOKUP(C35,'[1]5月25-5月31日汇总'!$C:$I,7,0) -> 0 | AU35: =VLOOKUP(C35,'[1]6月汇总'!$C:$I,7,0) -> 0 | AV35: =SUM(AS35:AU35) -> 0 | AW35: =VLOOKUP(C35,[2]两年对比终版!$A:$X,23,0) -> 0 | AY35: =AV35/AR35 -> 0 | AZ35: 333 | BA35: 4.7464 | BD35: =SUM(BA35:BC35) -> 4.7464 | BE35: =VLOOKUP(C35,[2]两年对比终版!$A:$AD,30,0) -> 0 | BF35: =BD35/AZ35 -> 0.014253453
A36: 30 | B36: C | C36: 印尼-2 | D36: 250 | E36: 51 | F36: =VLOOKUP(C36,'[1]5月25-5月31日汇总'!$C:$D,2,0) -> 0 | G36: =VLOOKUP(C36,'[1]6月汇总'!$C:$D,2,0) -> 19 | H36: =SUM(E36:G36) -> 70 | I36: =VLOOKUP(C36,[2]两年对比终版!$A:$C,3,0) -> 0 | K36: =H36/D36 -> 0.28 | L36: 1700 | M36: 530.632 | N36: =VLOOKUP(C36,'[1]5月25-5月31日汇总'!$C:$E,3,0) -> 0 | O36: =VLOOKUP(C36,'[1]6月汇总'!$C:$E,3,0) -> 170 | P36: =SUM(M36:O36) -> 700.632 | Q36: =VLOOKUP(C36,[2]两年对比终版!$A:$F,6,0) -> 0 | S36: =P36/L36 -> 0.41213647 | T36: 42 | U36: 0 | V36: =VLOOKUP(C36,'[1]5月25-5月31日汇总'!$C:$F,4,0) -> 0 | W36: =VLOOKUP(C36,'[1]6月汇总'!$C:$F,4,0) -> 0 | X36: =SUM(U36:W36) -> 0 | Y36: =VLOOKUP(C36,[2]两年对比终版!$A:$N,14,0) -> 0 | AA36: =X36/T36 -> 0 | AB36: 400 | AC36: 0 | AD36: =VLOOKUP(C36,'[1]5月25-5月31日汇总'!$C:$G,5,0) -> 0 | AE36: =VLOOKUP(C36,'[1]6月汇总'!$C:$G,5,0) -> 0 | AF36: =SUM(AC36:AE36) -> 0 | AG36: =VLOOKUP(C36,[2]两年对比终版!$A:$Q,17,0) -> 0 | AI36: =AF36/AB36 -> 0 | AJ36: 42 | AK36: 0 | AL36: =VLOOKUP(C36,'[1]5月25-5月31日汇总'!$C:$H,6,0) -> 0 | AM36: =VLOOKUP(C36,'[1]6月汇总'!$C:$I,6,0) -> 0 | AN36: =SUM(AK36:AM36) -> 0 | AO36: =VLOOKUP(C36,[2]两年对比终版!$A:$T,20,0) -> 0 | AQ36: =AN36/AJ36 -> 0 | AR36: 400 | AS36: 0 | AT36: =VLOOKUP(C36,'[1]5月25-5月31日汇总'!$C:$I,7,0) -> 0 | AU36: =VLOOKUP(C36,'[1]6月汇总'!$C:$I,7,0) -> 0 | AV36: =SUM(AS36:AU36) -> 0 | AW36: =VLOOKUP(C36,[2]两年对比终版!$A:$X,23,0) -> 0 | AY36: =AV36/AR36 -> 0 | AZ36: 380 | BA36: 0 | BD36: =SUM(BA36:BC36) -> 0 | BE36: =VLOOKUP(C36,[2]两年对比终版!$A:$AD,30,0) -> 0 | BF36: =BD36/AZ36 -> 0
A37: 亚洲2合计 | D37: =SUM(D26:D36) -> 1823 | E37: =SUM(E26:E36) -> 454 | F37: =SUM(F26:F36) -> 25 | G37: =SUM(G26:G36) -> 126 | H37: =SUM(H26:H36) -> 605 | I37: =SUM(I26:I36) -> 467 | J37: =(H37-I37)/I37 -> 0.29550321 | K37: =H37/D37 -> 0.33187054 | L37: =SUM(L26:L36) -> 15128.25 | M37: =SUM(M26:M36) -> 4707.114 | N37: =SUM(N26:N36) -> 231.86 | O37: =SUM(O26:O36) -> 1277.43 | P37: =SUM(P26:P36) -> 6216.404 | Q37: =SUM(Q26:Q36) -> 5851.5674 | R37: =(P37-Q37)/Q37 -> 0.062348529 | S37: =P37/L37 -> 0.41091362 | T37: =SUM(T26:T36) -> 501 | U37: =SUM(U26:U36) -> 90 | V37: =SUM(V26:V36) -> 9 | W37: =SUM(W26:W36) -> 39 | X37: =SUM(X26:X36) -> 138 | Y37: =SUM(Y26:Y36) -> 88 | Z37: =(X37-Y37)/Y37 -> 0.56818182 | AA37: =X37/T37 -> 0.2754491 | AB37: =SUM(AB26:AB36) -> 6146.245 | AC37: =SUM(AC26:AC36) -> 823.9673 | AD37: =SUM(AD26:AD36) -> 132.6 | AE37: =SUM(AE26:AE36) -> 389.22 | AF37: =SUM(AF26:AF36) -> 1345.7873 | AG37: =SUM(AG26:AG36) -> 1221.5454 | AH37: =(AF37-AG37)/AG37 -> 0.10170875 | AI37: =AF37/AB37 -> 0.21896089 | AJ37: =SUM(AJ26:AJ36) -> 501 | AK37: =SUM(AK26:AK36) -> 68 | AL37: =SUM(AL26:AL36) -> 12 | AM37: =SUM(AM26:AM36) -> 30 | AN37: =SUM(AN26:AN36) -> 110 | AO37: =SUM(AO26:AO36) -> 78 | AP37: =(AN37-AO37)/AO37 -> 0.41025641 | AQ37: =AN37/AJ37 -> 0.21956088 | AR37: =SUM(AR26:AR36) -> 6146.245 | AS37: =SUM(AS26:AS36) -> 628.9846 | AT37: =SUM(AT26:AT36) -> 77.49 | AU37: =SUM(AU26:AU36) -> 289.69071 | AV37: =SUM(AV26:AV36) -> 996.16531 | AW37: =SUM(AW26:AW36) -> 913.28937 | AX37: =(AV37-AW37)/AW37 -> 0.090744444 | AY37: =AV37/AR37 -> 0.16207706 | AZ37: =SUM(AZ26:AZ36) -> 5839 | BA37: =SUM(BA26:BA36) -> 225.78713 | BB37: =SUM(BB26:BB36) -> 0 | BC37: =SUM(BC26:BC36) -> 0 | BD37: =SUM(BD26:BD36) -> 225.78713 | BE37: =SUM(BE26:BE36) -> 2328.6571 | BF37: =BD37/AZ37 -> 0.038668801
A38: 31 | B38: B | C38: 阿联酋-2 | D38: 122 | E38: 43 | F38: =VLOOKUP(C38,'[1]5月25-5月31日汇总'!$C:$D,2,0) -> 25 | G38: =VLOOKUP(C38,'[1]6月汇总'!$C:$D,2,0) -> 70 | H38: =SUM(E38:G38) -> 138 | I38: =VLOOKUP(C38,[2]两年对比终版!$A:$C,3,0) -> 42 | K38: =H38/D38 -> 1.1311475 | L38: 3360 | M38: 490.787 | N38: =VLOOKUP(C38,'[1]5月25-5月31日汇总'!$C:$E,3,0) -> 204.2426 | O38: =VLOOKUP(C38,'[1]6月汇总'!$C:$E,3,0) -> 816.9704 | P38: =SUM(M38:O38) -> 1512 | Q38: =VLOOKUP(C38,[2]两年对比终版!$A:$F,6,0) -> 1049.7856 | S38: =P38/L38 -> 0.45 | T38: 64 | U38: 5 | V38: =VLOOKUP(C38,'[1]5月25-5月31日汇总'!$C:$F,4,0) -> 0 | W38: =VLOOKUP(C38,'[1]6月汇总'!$C:$F,4,0) -> 10 | X38: =SUM(U38:W38) -> 15 | Y38: =VLOOKUP(C38,[2]两年对比终版!$A:$N,14,0) -> 27 | AA38: =X38/T38 -> 0.234375 | AB38: 1500 | AC38: 55.9393 | AD38: =VLOOKUP(C38,'[1]5月25-5月31日汇总'!$C:$G,5,0) -> 0 | AE38: =VLOOKUP(C38,'[1]6月汇总'!$C:$G,5,0) -> 155 | AF38: =SUM(AC38:AE38) -> 210.9393 | AG38: =VLOOKUP(C38,[2]两年对比终版!$A:$Q,17,0) -> 913.93426 | AI38: =AF38/AB38 -> 0.1406262 | AJ38: 64 | AK38: 1 | AL38: =VLOOKUP(C38,'[1]5月25-5月31日汇总'!$C:$H,6,0) -> 0 | AM38: =VLOOKUP(C38,'[1]6月汇总'!$C:$I,6,0) -> 10 | AN38: =SUM(AK38:AM38) -> 11 | AO38: =VLOOKUP(C38,[2]两年对比终版!$A:$T,20,0) -> 26 | AQ38: =AN38/AJ38 -> 0.171875 | AR38: 1500 | AS38: 26.6761 | AT38: =VLOOKUP(C38,'[1]5月25-5月31日汇总'!$C:$I,7,0) -> 0 | AU38: =VLOOKUP(C38,'[1]6月汇总'!$C:$I,7,0) -> 160 | AV38: =SUM(AS38:AU38) -> 186.6761 | AW38: =VLOOKUP(C38,[2]两年对比终版!$A:$X,23,0) -> 895.74992 | AY38: =AV38/AR38 -> 0.12445073 | AZ38: 1425 | BA38: 7.87278 | BD38: =SUM(BA38:BC38) -> 7.87278 | BE38: =VLOOKUP(C38,[2]两年对比终版!$A:$AD,30,0) -> 460.53615 | BF38: =BD38/AZ38 -> 0.0055247579
A39: 32 | B39: A | C39: 沙特工厂 | D39: 733 | E39: 215 | F39: =VLOOKUP(C39,'[1]5月25-5月31日汇总'!$C:$D,2,0) -> 25 | G39: =VLOOKUP(C39,'[1]6月汇总'!$C:$D,2,0) -> 92 | H39: =SUM(E39:G39) -> 332 | I39: =VLOOKUP(C39,[2]两年对比终版!$A:$C,3,0) -> 860 | K39: =H39/D39 -> 0.45293315 | L39: 6860 | M39: 1849.15 | N39: =VLOOKUP(C39,'[1]5月25-5月31日汇总'!$C:$E,3,0) -> 247.57 | O39: =VLOOKUP(C39,'[1]6月汇总'!$C:$E,3,0) -> 990.28 | P39: =SUM(M39:O39) -> 3087 | Q39: =VLOOKUP(C39,[2]两年对比终版!$A:$F,6,0) -> 7680.8761 | S39: =P39/L39 -> 0.45 | T39: 200 | U39: 31 | V39: =VLOOKUP(C39,'[1]5月25-5月31日汇总'!$C:$F,4,0) -> 2 | W39: =VLOOKUP(C39,'[1]6月汇总'!$C:$F,4,0) -> 10 | X39: =SUM(U39:W39) -> 43 | Y39: =VLOOKUP(C39,[2]两年对比终版!$A:$N,14,0) -> 115 | AA39: =X39/T39 -> 0.215 | AB39: 2360 | AC39: 268.559 | AD39: =VLOOKUP(C39,'[1]5月25-5月31日汇总'!$C:$G,5,0) -> 22 | AE39: =VLOOKUP(C39,'[1]6月汇总'!$C:$G,5,0) -> 105 | AF39: =SUM(AC39:AE39) -> 395.559 | AG39: =VLOOKUP(C39,[2]两年对比终版!$A:$Q,17,0) -> 999.50571 | AI39: =AF39/AB39 -> 0.16760975 | AJ39: 200 | AK39: 29 | AL39: =VLOOKUP(C39,'[1]5月25-5月31日汇总'!$C:$H,6,0) -> 1 | AM39: =VLOOKUP(C39,'[1]6月汇总'!$C:$I,6,0) -> 8 | AN39: =SUM(AK39:AM39) -> 38 | AO39: =VLOOKUP(C39,[2]两年对比终版!$A:$T,20,0) -> 132 | AQ39: =AN39/AJ39 -> 0.19 | AR39: 2360 | AS39: 257.589 | AT39: =VLOOKUP(C39,'[1]5月25-5月31日汇总'!$C:$I,7,0) -> 8 | AU39: =VLOOKUP(C39,'[1]6月汇总'!$C:$I,7,0) -> 70 | AV39: =SUM(AS39:AU39) -> 335.589 | AW39: =VLOOKUP(C39,[2]两年对比终版!$A:$X,23,0) -> 1132.2966 | AY39: =AV39/AR39 -> 0.14219873 | AZ39: 2242 | BA39: 676.018 | BD39: =SUM(BA39:BC39) -> 676.018 | BE39: =VLOOKUP(C39,[2]两年对比终版!$A:$AD,30,0) -> 831.13297 | BF39: =BD39/AZ39 -> 0.30152453
A40: 33 | B40: A | C40: 沙特-1 | D40: 299 | E40: 95 | F40: =VLOOKUP(C40,'[1]5月25-5月31日汇总'!$C:$D,2,0) -> 22 | G40: =VLOOKUP(C40,'[1]6月汇总'!$C:$D,2,0) -> 90 | H40: =SUM(E40:G40) -> 207 | I40: =VLOOKUP(C40,[2]两年对比终版!$A:$C,3,0) -> 380 | K40: =H40/D40 -> 0.69230769 | L40: 3710 | M40: 754.047 | N40: =VLOOKUP(C40,'[1]5月25-5月31日汇总'!$C:$E,3,0) -> 183.0906 | O40: =VLOOKUP(C40,'[1]6月汇总'!$C:$E,3,0) -> 732.3624 | P40: =SUM(M40:O40) -> 1669.5 | Q40: =VLOOKUP(C40,[2]两年对比终版!$A:$F,6,0) -> 2999.3153 | S40: =P40/L40 -> 0.45 | T40: 150 | U40: 13 | V40: =VLOOKUP(C40,'[1]5月25-5月31日汇总'!$C:$F,4,0) -> 8 | W40: =VLOOKUP(C40,'[1]6月汇总'!$C:$F,4,0) -> 15 | X40: =SUM(U40:W40) -> 36 | Y40: =VLOOKUP(C40,[2]两年对比终版!$A:$N,14,0) -> 18 | AA40: =X40/T40 -> 0.24 | AB40: 1500 | AC40: 108.787 | AD40: =VLOOKUP(C40,'[1]5月25-5月31日汇总'!$C:$G,5,0) -> 70 | AE40: =VLOOKUP(C40,'[1]6月汇总'!$C:$G,5,0) -> 180 | AF40: =SUM(AC40:AE40) -> 358.787 | AG40: =VLOOKUP(C40,[2]两年对比终版!$A:$Q,17,0) -> 244.92997 | AI40: =AF40/AB40 -> 0.23919133 | AJ40: 150 | AK40: 31 | AL40: =VLOOKUP(C40,'[1]5月25-5月31日汇总'!$C:$H,6,0) -> 0 | AM40: =VLOOKUP(C40,'[1]6月汇总'!$C:$I,6,0) -> 5 | AN40: =SUM(AK40:AM40) -> 36 | AO40: =VLOOKUP(C40,[2]两年对比终版!$A:$T,20,0) -> 22 | AQ40: =AN40/AJ40 -> 0.24 | AR40: 1500 | AS40: 307.471 | AT40: =VLOOKUP(C40,'[1]5月25-5月31日汇总'!$C:$I,7,0) -> 0 | AU40: =VLOOKUP(C40,'[1]6月汇总'!$C:$I,7,0) -> 45 | AV40: =SUM(AS40:AU40) -> 352.471 | AW40: =VLOOKUP(C40,[2]两年对比终版!$A:$X,23,0) -> 262.43406 | AY40: =AV40/AR40 -> 0.23498067 | AZ40: 1425 | BA40: 40.4176 | BD40: =SUM(BA40:BC40) -> 40.4176 | BE40: =VLOOKUP(C40,[2]两年对比终版!$A:$AD,30,0) -> 661.6902 | BF40: =BD40/AZ40 -> 0.028363228
...

Sheet 明细
A1: 2026年国际市场运营系统合同预算情况表
AT2: 金额单位：万元
A3: 序号 | B3: 模块类型 | C3: 模块 | D3: 新签梯量 | K3: 新签金额 | R3: 排产台 | Y3: 排产额 | AF3: 发货台 | AM3: 发货额 | AT3: 回款
D4: 指标 | E4: 完成 | F4: 5月 | G4: 6月 | H4: 累计 | I4: 去年同期 | J4: 完成比 | K4: 指标 | L4: 完成 | M4: 5月 | N4: 6月 | O4: 累计 | P4: 去年同期 | Q4: 完成比 | R4: 指标 | S4: 完成 | T4: 5月 | U4: 6月 | V4: 累计 | W4: 去年同期 | X4: 完成比 | Y4: 指标 | Z4: 完成 | AA4: 5月 | AB4: 6月 | AC4: 累计 | AD4: 去年同期 | AE4: 完成比 | AF4: 指标 | AG4: 完成 | AH4: 5月 | AI4: 6月 | AJ4: 累计 | AK4: 去年同期 | AL4: 完成比 | AM4: 指标 | AN4: 完成 | AO4: 5月 | AP4: 6月 | AQ4: 累计 | AR4: 去年同期 | AS4: 完成比 | AT4: 指标 | AU4: 完成 | AV4: 5月 | AW4: 6月 | AX4: 累计 | AY4: 去年同期 | AZ4: 完成比
