Workbook

Sheet 指标
A1: 2026年国际市场运营系统市场人员分配
A2: 大区 | B2: 模块 | E2: 模块经理 | F2: 国家 | G2: 业务助理
A3: 俄罗斯 | B3: 俄罗斯（中部） | C3: =#REF!/#REF! -> #REF! | E3: 丛峻
A4: 俄罗斯 | B4: 俄罗斯（西部） | C4: =#REF!/#REF! -> #REF! | E4: 单一
A5: 俄罗斯 | B5: 俄罗斯（东部） | C5: =#REF!/#REF! -> #REF! | E5: 宋艾亭
A6: 俄罗斯 | B6: 罗斯托夫 | C6: =#REF!/#REF! -> #REF! | E6: （空）
A7: 俄罗斯 | B7: 哈巴 | C7: =#REF!/#REF! -> #REF! | E7: （空）
A8: 俄罗斯 | B8: 俄罗斯（中南） | C8: =#REF!/#REF! -> #REF! | E8: 张沁媛
A9: 俄罗斯 | B9: 俄罗斯（西南） | C9: =#REF!/#REF! -> #REF! | E9: 刘景伟
A10: 俄罗斯 | B10: 莫斯科 | C10: =#REF!/#REF! -> #REF! | E10: 张东辉
A11: 俄罗斯 | B11: 叶卡 | C11: =#REF!/#REF! -> #REF! | E11: 孙继伟
A12: 俄罗斯 | B12: 新西 | C12: =#REF!/#REF! -> #REF! | E12: （空） | G12: 严晨 | H12: 李欣然 | I12: 李可心 | J12: 谈振清 | K12: 左冠日 | L12: 胡艳丽 | M12: 王萌萌
C13: =#REF!/#REF! -> #REF!
A14: 亚洲1 | B14: 朝鲜-韩国 | C14: =#REF!/#REF! -> #REF! | E14: 安鹏霖
A15: 亚洲1 | B15: 新加坡市政会 | C15: =#REF!/#REF! -> #REF! | E15: 祁阳
A16: 亚洲1 | B16: 新加坡HDB | C16: =#REF!/#REF! -> #REF! | E16: 王珊珊
A17: 亚洲1 | B17: 泰国 | C17: =#REF!/#REF! -> #REF! | E17: 张琬怡
A18: 亚洲1 | B18: 泰国2 | C18: =#REF!/#REF! -> #REF! | E18: 刘瑞
A19: 亚洲1 | B19: 金三角 | C19: =#REF!/#REF! -> #REF! | E19: （空）
A20: 亚洲1 | B20: 马来西亚 | C20: =#REF!/#REF! -> #REF! | E20: 鲁鸿飞
A21: 亚洲1 | B21: 马尔代夫 | C21: =#REF!/#REF! -> #REF! | E21: 叶哲铭
A22: 亚洲1 | B22: 香港-台湾 | C22: =#REF!/#REF! -> #REF! | E22: 刘瑞 | G22: 高强 | H22: 黄心阳 | I22: 王邦铭
C23: =#REF!/#REF! -> #REF!
A24: 亚洲2 | B24: 越南-2 | C24: =#REF!/#REF! -> #REF! | E24: 韩月华
A25: 亚洲2 | B25: 印度公建 | C25: =#REF!/#REF! -> #REF! | E25: 张鹏
A26: 亚洲2 | B26: 巴基斯坦 | C26: =#REF!/#REF! -> #REF! | E26: 耿建伟
A27: 亚洲2 | B27: 孟加拉-1 | C27: =#REF!/#REF! -> #REF! | E27: 刘晓虎
A28: 亚洲2 | B28: 澳大利亚 | C28: =#REF!/#REF! -> #REF! | E28: 董永生
A29: 亚洲2 | B29: 菲律宾 | C29: =#REF!/#REF! -> #REF! | E29: 吴旭东
A30: 亚洲2 | B30: 印尼-1 | C30: =#REF!/#REF! -> #REF! | E30: 张欢
A31: 亚洲2 | B31: 越南-1（工厂） | C31: =#REF!/#REF! -> #REF! | E31: 于春光
A32: 亚洲2 | B32: 印度私营 | C32: =#REF!/#REF! -> #REF! | E32: 高新尧
A33: 亚洲2 | B33: 菲律宾-2 | C33: =#REF!/#REF! -> #REF! | E33: 吴永顺
A34: 亚洲2 | B34: 印尼-2 | C34: =#REF!/#REF! -> #REF! | E34: 岳亮 | G34: 王浩甡 | H34: 王伟男
C35: =#REF!/#REF! -> #REF!
A36: 中东 | B36: 阿联酋-2 | C36: =#REF!/#REF! -> #REF! | E36: 任嘉庆
A37: 中东 | B37: 沙特工厂 | C37: =#REF!/#REF! -> #REF! | E37: 武永佳
A38: 中东 | B38: 沙特-1 | C38: =#REF!/#REF! -> #REF! | E38: 陈科锦
A39: 中东 | B39: 科威特 | C39: =#REF!/#REF! -> #REF! | E39: 赵俊峰
A40: 中东 | B40: 阿联酋-1 | C40: =#REF!/#REF! -> #REF! | E40: 张晓茜
...

Sheet 业务员-市场
A1: 国家 | B1: 模块 | C1: 大区 | D1: 模块经理 | E1: 业务助理
A2: 西俄罗斯 | B2: 俄罗斯（中部） | C2: 俄罗斯 | D2: =VLOOKUP(B2,'任命令模块-模主'!B:C,2,0) -> 丛峻
A3: 巴西1 | B3: 俄罗斯（中部） | C3: 俄罗斯 | D3: 丛峻
A4: 白俄罗斯1 | B4: 俄罗斯（西部） | C4: 俄罗斯 | D4: 单一
A5: 俄罗斯1 | B5: 俄罗斯（西部） | C5: 俄罗斯 | D5: 单一
A6: 东俄罗斯 | B6: 俄罗斯（东部） | C6: 俄罗斯 | D6: 宋艾亭
A7: 俄罗斯5 | B7: 罗斯托夫 | C7: 俄罗斯 | D7: 张执玮
A8: 俄罗斯6 | B8: 哈巴 | C8: 俄罗斯 | D8: 张小帆
A9: 俄罗斯3 | B9: 俄罗斯（中南） | C9: 俄罗斯 | D9: 张沁媛
A10: 俄罗斯2 | B10: 俄罗斯（西南） | C10: 俄罗斯 | D10: 刘景伟
A11: 孟加拉1 | B11: 俄罗斯（西南） | C11: 俄罗斯 | D11: 刘景伟
A12: 刚果2 | B12: 俄罗斯（西南） | C12: 俄罗斯 | D12: 刘景伟
A13: 塞内加尔3 | B13: 俄罗斯（西南） | C13: 俄罗斯 | D13: 刘景伟
A14: 坦桑尼亚1 | B14: 俄罗斯（西南） | C14: 俄罗斯 | D14: 刘景伟
... A16: 乌兹别克斯坦2 | B16: 莫斯科 | C16: 俄罗斯 | D16: 张东辉
A17: 俄罗斯8 | B17: 叶卡 | C17: 俄罗斯 | D17: （空） | E17: 原孙继伟
A18: 俄罗斯9 | B18: 新西 | C18: 俄罗斯 | D18: 张瑛琦 | E18: 严晨 | F18: 李欣然 | G18: 李可心 | H18: 谈振清 | I18: 左冠日 | J18: 胡艳丽 | K18: 王萌萌
A19: 朝鲜 | B19: 朝鲜-韩国 | C19: 亚洲1 | D19: 安鹏霖
A20: 中国1 | B20: 朝鲜-韩国 | C20: 亚洲1 | D20: 安鹏霖
A21: 韩国 | B21: 朝鲜-韩国 | C21: 亚洲1 | D21: 安鹏霖
A22: 日本 | B22: 朝鲜-韩国 | C22: 亚洲1 | D22: 安鹏霖
A23: 新加坡 | B23: 新加坡市政会 | C23: 亚洲1 | D23: 王珊珊
A24: 新加坡1 | B24: 新加坡HDB | C24: 亚洲1 | D24: 祁阳
A25: 印尼3 | B25: 新加坡市政会 | C25: 亚洲1 | D25: 王珊珊
A26: 泰国 | B26: 泰国 | C26: 亚洲1 | D26: 张琬怡
A27: 巴勒斯坦 | B27: 泰国 | C27: 亚洲1 | D27: 张琬怡
A28: 文莱 | B28: 泰国 | C28: 亚洲1 | D28: 张琬怡
A29: 也门 | B29: 泰国 | C29: 亚洲1 | D29: 张琬怡
A30: 伊拉克 | B30: 泰国 | C30: 亚洲1 | D30: 张琬怡
A31: 泰国2 | B31: 泰国2 | C31: 亚洲1 | D31: 刘瑞
A32: 老挝1 | B32: 金三角 | C32: 亚洲1 | D32: （空） | E32: 原张琬怡
A33: 柬埔寨 | B33: 金三角 | C33: 亚洲1 | D33: （空）
A34: 老挝 | B34: 金三角 | C34: 亚洲1 | D34: （空）
A35: 缅甸 | B35: 金三角 | C35: 亚洲1 | D35: （空）
A36: 孟加拉5 | B36: 金三角 | C36: 亚洲1 | D36: （空）
A37: 伊拉克3 | B37: 金三角 | C37: 亚洲1 | D37: （空）
A38: 亚美尼亚1 | B38: 金三角 | C38: 亚洲1 | D38: （空）
A39: 越南2 | B39: 金三角 | C39: 亚洲1 | D39: （空）
A40: 马来西亚 | B40: 马来西亚 | C40: 亚洲1 | D40: 鲁鸿飞
A41: 马尔代夫 | B41: 马尔代夫 | C41: 亚洲1 | D41: 叶哲铭
...

Sheet Sheet3
A1: 国家 | B1: 2025九大区模块 | C1: 2025九大区 | D1: 2026年对应模块 | E1: 2026九大区
A2: 巴哈马 | B2: 0 | C2: #N/A | D2: =VLOOKUP(A2,'业务员-市场'!A:B,2,0) -> #N/A | E2: =VLOOKUP(D2,'业务员-市场'!B:C,2,0) -> #N/A
A3: 巴西 | B3: 中美洲-2 | C3: 美洲 | D3: 巴西 | E3: 美洲
A4: 古巴 | B4: 0 | C4: #N/A | D4: =B4 -> 0 | E4: =VLOOKUP(D4,'业务员-市场'!B:C,2,0) -> #N/A
A5: 特立尼达和多巴哥 | B5: 0 | C5: #N/A | D5: =B5 -> 0 | E5: =VLOOKUP(D5,'业务员-市场'!B:C,2,0) -> #N/A
A6: 印尼1 | B6: 马来西亚 | C6: 亚洲1 | D6: =VLOOKUP(A6,'业务员-市场'!A:B,2,0) -> 马尔代夫 | E6: =VLOOKUP(D6,'业务员-市场'!B:C,2,0) -> 亚洲1
A7: 多米尼加1 | B7: 中美洲-2 | C7: 美洲 | D7: 加勒比海 | E7: 美洲
A8: 孟加拉1 | B8: 俄罗斯（西南） | C8: 俄罗斯 | D8: =VLOOKUP(A8,'业务员-市场'!A:B,2,0) -> 俄罗斯（西南） | E8: =VLOOKUP(D8,'业务员-市场'!B:C,2,0) -> 俄罗斯
A9: 沙特1 | B9: 沙特工厂 | C9: 中东 | D9: =VLOOKUP(A9,'业务员-市场'!A:B,2,0) -> 沙特工厂 | E9: =VLOOKUP(D9,'业务员-市场'!B:C,2,0) -> 中东
A10: 印度1 | B10: 印度私营 | C10: 亚洲2 | D10: =VLOOKUP(A10,'业务员-市场'!A:B,2,0) -> 印度私营 | E10: =VLOOKUP(D10,'业务员-市场'!B:C,2,0) -> 亚洲2
A11: 阿塞拜疆1 | B11: 阿塞拜疆 | C11: 中亚 | D11: =B11 -> 阿塞拜疆 | E11: =VLOOKUP(D11,'业务员-市场'!B:C,2,0) -> 中亚
A12: 埃及 | B12: 埃及 | C12: 非洲 | D12: 埃及-1 | E12: 非洲
A13: 巴林 | B13: 科威特 | C13: 中东 | D13: =VLOOKUP(A13,'业务员-市场'!A:B,2,0) -> 科威特 | E13: =VLOOKUP(D13,'业务员-市场'!B:C,2,0) -> 中东
A14: 卡塔尔 | B14: 卡塔尔 | C14: 中东 | D14: =VLOOKUP(A14,'业务员-市场'!A:B,2,0) -> 埃及-2 | E14: =VLOOKUP(D14,'业务员-市场'!B:C,2,0) -> 非洲
A15: 土耳其 | B15: 英国意大利 | C15: 欧洲 | D15: =VLOOKUP(A15,'业务员-市场'!A:B,2,0) -> 英国意大利 | E15: =VLOOKUP(D15,'业务员-市场'!B:C,2,0) -> 欧洲
A16: 以色列 | B16: 巴基斯坦 | C16: 亚洲2 | D16: =B16 -> 巴基斯坦 | E16: =VLOOKUP(D16,'业务员-市场'!B:C,2,0) -> 亚洲2
A17: 黎巴嫩 | B17: 埃及 | C17: 非洲 | D17: 埃及-1 | E17: 非洲
A18: 巴勒斯坦 | B18: 泰国 | C18: 亚洲1 | D18: =VLOOKUP(A18,'业务员-市场'!A:B,2,0) -> 泰国 | E18: =VLOOKUP(D18,'业务员-市场'!B:C,2,0) -> 亚洲1
A19: 科威特 | B19: 科威特 | C19: 中东 | D19: =VLOOKUP(A19,'业务员-市场'!A:B,2,0) -> 科威特 | E19: =VLOOKUP(D19,'业务员-市场'!B:C,2,0) -> 中东
A20: 沙特 | B20: 沙特-1 | C20: 中东 | D20: =VLOOKUP(A20,'业务员-市场'!A:B,2,0) -> 沙特-1 | E20: =VLOOKUP(D20,'业务员-市场'!B:C,2,0) -> 中东
A21: 也门 | B21: 泰国 | C21: 亚洲1 | D21: =VLOOKUP(A21,'业务员-市场'!A:B,2,0) -> 泰国 | E21: =VLOOKUP(D21,'业务员-市场'!B:C,2,0) -> 亚洲1
A22: 阿联酋 | B22: 阿联酋-1 | C22: 中东 | D22: =VLOOKUP(A22,'业务员-市场'!A:B,2,0) -> 阿联酋-1 | E22: =VLOOKUP(D22,'业务员-市场'!B:C,2,0) -> 中东
A23: 阿曼 | B23: 卡塔尔 | C23: 中东 | D23: =VLOOKUP(A23,'业务员-市场'!A:B,2,0) -> 卡塔尔 | E23: =VLOOKUP(D23,'业务员-市场'!B:C,2,0) -> 中东
A24: 伊拉克 | B24: 泰国 | C24: 亚洲1 | D24: =VLOOKUP(A24,'业务员-市场'!A:B,2,0) -> 泰国 | E24: =VLOOKUP(D24,'业务员-市场'!B:C,2,0) -> 亚洲1
A25: 伊朗 | B25: 泰国 | C25: 亚洲1 | D25: =VLOOKUP(A25,'业务员-市场'!A:B,2,0) -> 伊朗+阿曼 | E25: =VLOOKUP(D25,'业务员-市场'!B:C,2,0) -> 中东
A26: 阿富汗 | B26: 0 | C26: #N/A | D26: =B26 -> 0 | E26: =VLOOKUP(D26,'业务员-市场'!B:C,2,0) -> #N/A
A27: 阿富汗1 | B27: 0 | C27: #N/A | D27: =B27 -> 0 | E27: =VLOOKUP(D27,'业务员-市场'!B:C,2,0) -> #N/A
A28: 叙利亚 | B28: 0 | C28: #N/A | D28: =B28 -> 0 | E28: =VLOOKUP(D28,'业务员-市场'!B:C,2,0) -> #N/A
A29: 约旦1 | B29: 泰国 | C29: 亚洲1 | D29: =B29 -> 泰国 | E29: =VLOOKUP(D29,'业务员-市场'!B:C,2,0) -> 亚洲1
A30: 也门1 | B30: 泰国 | C30: 亚洲1 | D30: =B30 -> 泰国 | E30: =VLOOKUP(D30,'业务员-市场'!B:C,2,0) -> 亚洲1
A31: 老挝1 | B31: 金三角 | C31: 亚洲1 | D31: =VLOOKUP(A31,'业务员-市场'!A:B,2,0) -> 金三角 | E31: =VLOOKUP(D31,'业务员-市场'!B:C,2,0) -> 亚洲1
A32: 巴基斯坦 | B32: 巴基斯坦 | C32: 亚洲2 | D32: =VLOOKUP(A32,'业务员-市场'!A:B,2,0) -> 巴基斯坦 | E32: =VLOOKUP(D32,'业务员-市场'!B:C,2,0) -> 亚洲2
A33: 孟加拉 | B33: 孟加拉-1 | C33: 亚洲2 | D33: =VLOOKUP(A33,'业务员-市场'!A:B,2,0) -> 孟加拉-1 | E33: =VLOOKUP(D33,'业务员-市场'!B:C,2,0) -> 亚洲2
A34: 马尔代夫 | B34: 马尔代夫 | C34: 亚洲1 | D34: =VLOOKUP(A34,'业务员-市场'!A:B,2,0) -> 马尔代夫 | E34: =VLOOKUP(D34,'业务员-市场'!B:C,2,0) -> 亚洲1
A35: 阿根廷 | B35: 智利 | C35: 美洲 | D35: =VLOOKUP(A35,'业务员-市场'!A:B,2,0) -> 智利 | E35: =VLOOKUP(D35,'业务员-市场'!B:C,2,0) -> 美洲
A36: 厄瓜多尔 | B36: 智利 | C36: 美洲 | D36: =VLOOKUP(A36,'业务员-市场'!A:B,2,0) -> 智利 | E36: =VLOOKUP(D36,'业务员-市场'!B:C,2,0) -> 美洲
A37: 洪都拉斯 | B37: 加勒比海 | C37: 美洲 | D37: =VLOOKUP(A37,'业务员-市场'!A:B,2,0) -> 加勒比海 | E37: =VLOOKUP(D37,'业务员-市场'!B:C,2,0) -> 美洲
A38: 美国 | B38: 0 | C38: #N/A | D38: =B38 -> 0 | E38: =VLOOKUP(D38,'业务员-市场'!B:C,2,0) -> #N/A
A39: 秘鲁 | B39: 秘鲁 | C39: 美洲 | D39: =VLOOKUP(A39,'业务员-市场'!A:B,2,0) -> 秘鲁 | E39: =VLOOKUP(D39,'业务员-市场'!B:C,2,0) -> 美洲
A40: 委内瑞拉 | B40: 0 | C40: #N/A | D40: =B40 -> 0 | E40: =VLOOKUP(D40,'业务员-市场'!B:C,2,0) -> #N/A
...

Sheet 任命令模块-模主
A1: 大区 | B1: 模块 | C1: 模主
A2: 美洲 | B2: 哥伦比亚 | C2: 田媛媛
A3: 美洲 | B3: 加勒比海 | C3: 范皓铭
A4: 美洲 | B4: 智利 | C4: 翟文龙
A5: 美洲 | B5: 墨西哥－1 | C5: 尤健宇
A6: 美洲 | B6: 墨西哥－2 | C6: 肖宇晗
A7: 美洲 | B7: 秘鲁－1 | C7: 李知源
A8: 美洲 | B8: 秘鲁－2 | C8: 魏珍荣
A9: 美洲 | B9: 多米尼加 | C9: 梁国裕
A10: 美洲 | B10: 巴西 | C10: 杨春
A11: 亚洲－1 | B11: 新加坡HDB | C11: 祁阳
A12: 亚洲－1 | B12: 新加坡市政会 | C12: 王珊珊
... A67: 欧洲 | B67: 英国／意大利 | C67: 王俊豪

Sheet 模主+助理对应模块
A1: 三级组织 | B1: 岗位名称 | C1: 姓名 | D1: 模块
A2: 美洲大区 | B2: 国际美洲大区销售总经理 | C2: 吴迪 | D2: 墨西哥-1 | E2: =VLOOKUP(D2,'业务员-市场'!B:B,1,0) -> 墨西哥-1
A3: 中东大区 | B3: 国际中东大区销售总经理 | C3: 陈远一 | D3: 沙特工厂 | E3: =VLOOKUP(D3,'业务员-市场'!B:B,1,0) -> 沙特工厂
A4: 中亚大区 | B4: 国际中亚大区销售总经理 | C4: 齐文童 | D4: 俄罗斯（东部） | E4: =VLOOKUP(D4,'业务员-市场'!B:B,1,0) -> 俄罗斯（东部）
A5: 商贸配件大区 | B5: 国际商贸配件大区销售总经理 | C5: 周聖航 | D5: 新加坡HDB | E5: =VLOOKUP(D5,'业务员-市场'!B:B,1,0) -> 新加坡HDB
A6: 俄罗斯大区 | B6: 模主 | C6: 丛峻 | D6: 俄罗斯（中部） | E6: =VLOOKUP(D6,'业务员-市场'!B:B,1,0) -> 俄罗斯（中部）
B7: 模主 | C7: 单一 | D7: 俄罗斯（西部） | E7: =VLOOKUP(D7,'业务员-市场'!B:B,1,0) -> 俄罗斯（西部）
B8: 模主 | C8: 张沁媛 | D8: 俄罗斯（中南） | E8: =VLOOKUP(D8,'业务员-市场'!B:B,1,0) -> 俄罗斯（中南）
B9: 模主 | C9: 刘景伟 | D9: 俄罗斯（西南） | E9: =VLOOKUP(D9,'业务员-市场'!B:B,1,0) -> 俄罗斯（西南）
B10: 海外开发经理（外籍） | C10: 乌鲁格贝克·卡姆拉巴耶夫 | D10: 俄罗斯（西南） | E10: =VLOOKUP(D10,'业务员-市场'!B:B,1,0) -> 俄罗斯（西南）
B11: 模主 | C11: 宋艾亭 | D11: 俄罗斯（东部） | E11: =VLOOKUP(D11,'业务员-市场'!B:B,1,0) -> 俄罗斯（东部）
B12: 模主 | C12: 张东辉 | D12: 莫斯科 | E12: =VLOOKUP(D12,'业务员-市场'!B:B,1,0) -> 莫斯科
B13: 模主 | C13: 张执玮 | D13: 罗斯托夫 | E13: =VLOOKUP(D13,'业务员-市场'!B:B,1,0) -> 罗斯托夫
B14: 模主 | C14: 张小帆 | D14: 哈巴 | E14: =VLOOKUP(D14,'业务员-市场'!B:B,1,0) -> 哈巴
B15: 模主 | C15: 张瑛琦 | D15: 新西 | E15: =VLOOKUP(D15,'业务员-市场'!B:B,1,0) -> 新西
B16: 国际销售助理 | C16: 胡艳丽 | D16: 俄罗斯（东部） | E16: =VLOOKUP(D16,'业务员-市场'!B:B,1,0) -> 俄罗斯（东部）
B17: 国际销售助理 | C17: 左冠日 | D17: 俄罗斯（西部） | E17: =VLOOKUP(D17,'业务员-市场'!B:B,1,0) -> 俄罗斯（西部）
B18: 国际销售助理 | C18: 严晨 | D18: 俄罗斯（西部） | E18: =VLOOKUP(D18,'业务员-市场'!B:B,1,0) -> 俄罗斯（西部）
... B23: 已离职 | C23: 李欣然 | D23: 俄罗斯（中部） | E23: =VLOOKUP(D23,'业务员-市场'!B:B,1,0) -> 俄罗斯（中部）
A24: 非洲大区 | B24: 模主 | C24: 石云龙 | D24: 埃及-1 | E24: =VLOOKUP(D24,'业务员-市场'!B:B,1,0) -> 埃及-1
B25: 模主 | C25: 丁绎澎 | D25: 埃及-2 | E25: =VLOOKUP(D25,'业务员-市场'!B:B,1,0) -> 埃及-2
B26: 模主 | C26: 孙小婷 | D26: 非洲法语区 | E26: =VLOOKUP(D26,'业务员-市场'!B:B,1,0) -> 非洲法语区
B27: 模主 | C27: 史宇哲 | D27: 肯尼亚/坦桑尼亚 | E27: =VLOOKUP(D27,'业务员-市场'!B:B,1,0) -> 肯尼亚/坦桑尼亚
B28: 模主 | C28: 袁帅 | D28: 尼日利亚/埃塞俄比亚 | E28: =VLOOKUP(D28,'业务员-市场'!B:B,1,0) -> 尼日利亚/埃塞俄比亚
B29: 实习模主 | C29: 刘纪龙 | D29: 南非/安格拉 | E29: =VLOOKUP(D29,'业务员-市场'!B:B,1,0) -> 南非/安格拉
A30: 亚洲1大区 | B30: 模主 | C30: 祁阳 | D30: 新加坡HDB | E30: =VLOOKUP(D30,'业务员-市场'!B:B,1,0) -> 新加坡HDB
B31: 模主 | C31: 张琬怡 | D31: 泰国 | E31: =VLOOKUP(D31,'业务员-市场'!B:B,1,0) -> 泰国
B32: 模主 | C32: 王珊珊 | D32: 新加坡市政会 | E32: =VLOOKUP(D32,'业务员-市场'!B:B,1,0) -> 新加坡市政会
B33: 模主 | C33: 安鹏霖 | D33: 朝鲜-韩国 | E33: =VLOOKUP(D33,'业务员-市场'!B:B,1,0) -> 朝鲜-韩国
B34: 模主 | C34: 叶哲铭 | D34: 马尔代夫 | E34: =VLOOKUP(D34,'业务员-市场'!B:B,1,0) -> 马尔代夫
B35: 模主 | C35: 鲁鸿飞 | D35: 马来西亚 | E35: =VLOOKUP(D35,'业务员-市场'!B:B,1,0) -> 马来西亚
B36: 模主 | C36: 刘瑞 | D36: 泰国2 | E36: =VLOOKUP(D36,'业务员-市场'!B:B,1,0) -> 泰国2
B37: 模主 | C37: 王海娇 | D37: 香港-台湾 | E37: =VLOOKUP(D37,'业务员-市场'!B:B,1,0) -> 香港-台湾
B38: 国际业务经理 | C38: 高强 | D38: 新加坡HDB | E38: =VLOOKUP(D38,'业务员-市场'!B:B,1,0) -> 新加坡HDB
B39: 国际销售助理 | C39: 黄心阳 | D39: 朝鲜-韩国 | E39: =VLOOKUP(D39,'业务员-市场'!B:B,1,0) -> 朝鲜-韩国
B40: 国际销售助理 | C40: 王邦铭 | D40: 马尔代夫 | E40: =VLOOKUP(D40,'业务员-市场'!B:B,1,0) -> 马尔代夫
B41: 国际销售助理 | C41: 张金伟 | D41: 新加坡HDB | E41: =VLOOKUP(D41,'业务员-市场'!B:B,1,0) -> 新加坡HDB
B42: 国际销售助理 | C42: 张逸冰 | D42: 泰国2 | E42: =VLOOKUP(D42,'业务员-市场'!B:B,1,0) -> 泰国2
A43: 亚洲2大区 | B43: 模主 | C43: 刘晓虎 | D43: 孟加拉-1 | E43: =VLOOKUP(D43,'业务员-市场'!B:B,1,0) -> 孟加拉-1
B44: 模主 | C44: 张鹏 | D44: 印度公建 | E44: =VLOOKUP(D44,'业务员-市场'!B:B,1,0) -> 印度公建
...
